wss://ws.okx.com:8443/ws/v5/public <-> 1652459224.5300605
wss://ws.okx.com:8443/ws/v5/public <- 1652459225.2987883: {"op":"subscribe","args":[{"channel":"tickers","instId":"BTC-USD-220527"},{"channel":"tickers","instId":"UNI-USD-SWAP"},{"channel":"tickers","instId":"BTC-USDT"}]}
wss://ws.okx.com:8443/ws/v5/public <- 1652459225.2990754: {"op":"subscribe","args":[{"channel":"tickers","instId":"BTC-USD-220527"},{"channel":"tickers","instId":"UNI-USD-SWAP"},{"channel":"tickers","instId":"BTC-USDT"},{"channel":"trades","instId":"BTC-USD-220527"},{"channel":"trades","instId":"UNI-USD-SWAP"},{"channel":"trades","instId":"BTC-USDT"}]}
wss://ws.okx.com:8443/ws/v5/public <- 1652459225.2991893: {"op":"subscribe","args":[{"channel":"tickers","instId":"BTC-USD-220527"},{"channel":"tickers","instId":"UNI-USD-SWAP"},{"channel":"tickers","instId":"BTC-USDT"},{"channel":"trades","instId":"BTC-USD-220527"},{"channel":"trades","instId":"UNI-USD-SWAP"},{"channel":"trades","instId":"BTC-USDT"},{"channel":"books","instId":"BTC-USD-220527"},{"channel":"books","instId":"UNI-USD-SWAP"},{"channel":"books","instId":"BTC-USDT"}]}
1652459225.5037491: {"event":"subscribe","arg":{"channel":"tickers","instId":"BTC-USD-220527"}}
1652459225.5038502: {"event":"subscribe","arg":{"channel":"tickers","instId":"UNI-USD-SWAP"}}
1652459225.5038888: {"event":"subscribe","arg":{"channel":"tickers","instId":"BTC-USDT"}}
1652459225.5039184: {"event":"subscribe","arg":{"channel":"tickers","instId":"BTC-USD-220527"}}
1652459225.5041199: {"event":"subscribe","arg":{"channel":"tickers","instId":"UNI-USD-SWAP"}}
1652459225.5041583: {"event":"subscribe","arg":{"channel":"tickers","instId":"BTC-USDT"}}
1652459225.5041838: {"event":"subscribe","arg":{"channel":"trades","instId":"BTC-USD-220527"}}
1652459225.5042083: {"event":"subscribe","arg":{"channel":"trades","instId":"UNI-USD-SWAP"}}
1652459225.504232: {"event":"subscribe","arg":{"channel":"trades","instId":"BTC-USDT"}}
1652459225.5042565: {"event":"subscribe","arg":{"channel":"tickers","instId":"BTC-USD-220527"}}
1652459225.5042806: {"event":"subscribe","arg":{"channel":"tickers","instId":"UNI-USD-SWAP"}}
1652459225.5043046: {"event":"subscribe","arg":{"channel":"tickers","instId":"BTC-USDT"}}
1652459225.5043294: {"event":"subscribe","arg":{"channel":"trades","instId":"BTC-USD-220527"}}
1652459225.5043688: {"event":"subscribe","arg":{"channel":"trades","instId":"UNI-USD-SWAP"}}
1652459225.5043955: {"event":"subscribe","arg":{"channel":"trades","instId":"BTC-USDT"}}
1652459225.5044203: {"event":"subscribe","arg":{"channel":"books","instId":"BTC-USD-220527"}}
1652459225.5044448: {"event":"subscribe","arg":{"channel":"books","instId":"UNI-USD-SWAP"}}
1652459225.5044708: {"event":"subscribe","arg":{"channel":"books","instId":"BTC-USDT"}}
1652459225.5066085: {"arg":{"channel":"tickers","instId":"BTC-USD-220527"},"data":[{"instType":"FUTURES","instId":"BTC-USD-220527","last":"30218.8","lastSz":"1","askPx":"30220.1","askSz":"3","bidPx":"30210.4","bidSz":"4","open24h":"29571.4","high24h":"31003.3","low24h":"27930.8","sodUtc0":"28935.3","sodUtc8":"30320.5","volCcy24h":"2620.289","vol24h":"779573","ts":"1652459223003"}]}
1652459225.506837: {"arg":{"channel":"tickers","instId":"UNI-USD-SWAP"},"data":[{"instType":"SWAP","instId":"UNI-USD-SWAP","last":"5.123","lastSz":"100","askPx":"5.142","askSz":"25","bidPx":"5.134","bidSz":"96","open24h":"4.799","high24h":"5.458","low24h":"4.537","sodUtc0":"4.654","sodUtc8":"5.204","volCcy24h":"577730.7823","vol24h":"289425","ts":"1652459223143"}]}
1652459225.5069652: {"arg":{"channel":"tickers","instId":"BTC-USDT"},"data":[{"instType":"SPOT","instId":"BTC-USDT","last":"30236","lastSz":"0.0002","askPx":"30228.7","askSz":"1.55896972","bidPx":"30228.6","bidSz":"0.23393","open24h":"29700.4","high24h":"31073","low24h":"28020.3","sodUtc0":"29028.8","sodUtc8":"30337.7","volCcy24h":"525802090.62716611","vol24h":"17602.13085371","ts":"1652459224956"}]}
1652459225.5070758: {"arg":{"channel":"trades","instId":"BTC-USD-220527"},"data":[{"instId":"BTC-USD-220527","tradeId":"7849","px":"30218.8","sz":"1","side":"buy","ts":"1652459199958"}]}
1652459225.507172: {"arg":{"channel":"trades","instId":"UNI-USD-SWAP"},"data":[{"instId":"UNI-USD-SWAP","tradeId":"12883020","px":"5.123","sz":"100","side":"sell","ts":"1652459215150"}]}
1652459225.5072603: {"arg":{"channel":"trades","instId":"BTC-USDT"},"data":[{"instId":"BTC-USDT","tradeId":"338476307","px":"30236","sz":"0.0002","side":"buy","ts":"1652459224818"}]}
1652459225.5073643: {"arg":{"channel":"books","instId":"BTC-USD-220527"},"action":"snapshot","data":[{"asks":[["30238.8","2","0","1"],["30249.5","50","0","1"],["30249.6","29","0","1"],["30261.1","218","0","2"],["30261.5","215","0","1"],["30261.7","172","0","1"],["30264.5","11","0","1"],["30265.9","249","0","1"],["30268.4","40","0","1"],["30280.8","97","0","1"],["30280.9","217","0","1"],["30283.1","120","0","1"],["30291.1","442","0","1"],["30316","81","0","1"],["30316.1","1","0","1"],["30323.1","373","0","1"],["30325","17","0","1"],["30371.7","202","0","1"],["30371.8","10","0","1"],["30418.3","374","0","1"],["30426.3","508","0","1"],["30439.6","1539","0","1"],["30449.2","29","0","1"],["30464.9","202","0","1"],["30486.8","504","0","1"],["30536.9","926","0","1"],["30547.3","510","0","1"],["30551.3","1352","0","1"],["30551.5","602","0","1"],["30590.9","202","0","1"],["30599.4","839","0","1"],["30607.7","2007","0","1"],["30627.5","24","0","1"],["30698.4","2007","0","1"],["30704.2","6","0","1"],["30789.1","2001","0","1"],["30812.7","293","0","1"],["30852.7","6","0","1"],["30879.8","2008","0","1"],["30920","12","0","1"],["30953.5","959","0","1"],["30969.4","479","0","1"],["30970.5","2009","0","1"],["31151.6","5","0","1"],["31255.3","305","0","1"],["31430","50056","0","1"],["31560.1","299","0","1"],["31732.2","50044","0","1"],["31736.1","5036","0","1"],["31812.9","1","0","1"],["31891","300","0","1"],["31925.8","2399","0","1"],["32000","5","0","1"],["32034.4","50022","0","1"],["33214.2","1","0","1"],["34981.4","4399","0","1"],["34994.2","1","0","1"],["36535.7","1","0","1"],["38493.7","1","0","1"],["40189.3","1","0","1"],["42343.1","1","0","1"],["44208.3","1","0","1"],["46577.5","1","0","1"],["48629.2","1","0","1"]],"bids":[["30233.6","3","0","1"],["30219.4","104","0","2"],["30219.3","1520","0","1"],["30212.3","171","0","1"],["30209.8","5","0","1"],["30205.8","50","0","1"],["30204.1","1730","0","1"],["30202.1","30","0","1"],["30185.4","11","0","1"],["30184","1537","0","1"],["30181.3","18","0","1"],["30181.2","19","0","1"],["30180.7","249","0","1"],["30168.9","20","0","1"],["30165.8","3078","0","1"],["30145.8","4770","0","1"],["30145.3","120","0","1"],["30133.2","12","0","1"],["30130.3","1","0","1"],["30130.1","236","0","1"],["30129.9","442","0","1"],["30117.7","81","0","1"],["30117.6","369","0","1"],["30074.9","202","0","1"],["30074.6","373","0","1"],["30066.1","19","0","1"],["30050.6","1505","0","1"],["30047.1","509","0","1"],["30016.9","21","0","1"],["30016.8","839","0","1"],["30014.3","6","0","1"],["29986.7","505","0","1"],["29983.2","6","0","1"],["29975.1","919","0","1"],["29955.3","202","0","1"],["29940.7","1361","0","1"],["29926.2","506","0","1"],["29846","2008","0","1"],["29832.1","611","0","1"],["29823.9","959","0","1"],["29817.9","202","0","1"],["29776.9","34","0","1"],["29755.3","2007","0","1"],["29725.2","479","0","1"],["29722","3056","0","1"],["29664.7","2007","0","1"],["29574","2001","0","1"],["29571.5","302","0","1"],["29544.3","14","0","1"],["29483.4","2010","0","1"],["29469.2","5","0","1"],["29331.8","5","0","1"],["29292.4","300","0","1"],["29148.9","306","0","1"],["29061.3","50025","0","1"],["28837","299","0","1"],["28823.1","2399","0","1"],["28783.1","1","0","1"],["28758.5","50068","0","1"],["28716.3","5099","0","1"],["28494.6","8","0","1"],["28455.6","50073","0","1"],["27175.2","1","0","1"],["25904.7","1","0","1"],["25786.9","4399","0","1"],["24457.6","1","0","1"],["23314.2","1","0","1"],["22011.8","1","0","1"],["20982.7","1","0","1"],["19810.6","1","0","1"],["18884.4","1","0","1"],["17829.5","1","0","1"]],"ts":"1652459225393","checksum":1054815633}]}
1652459225.6963003: {"arg":{"channel":"books","instId":"UNI-USD-SWAP"},"action":"snapshot","data":[{"asks":[["5.148","60","0","1"],["5.149","192","0","1"],["5.151","48","0","1"],["5.152","25","0","2"],["5.153","491","0","3"],["5.154","1988","0","2"],["5.155","156","0","3"],["5.156","73","0","2"],["5.157","5","0","2"],["5.158","164","0","3"],["5.159","288","0","2"],["5.16","122","0","1"],["5.161","109","0","2"],["5.162","16","0","1"],["5.163","2613","0","1"],["5.166","11851","0","1"],["5.169","500","0","1"],["5.17","64","0","1"],["5.175","163","0","1"],["5.178","419","0","6"],["5.182","614","0","1"],["5.183","160","0","1"],["5.187","396","0","1"],["5.189","3686","0","1"],["5.19","3058","0","2"],["5.196","160","0","1"],["5.204","990","0","1"],["5.211","240","0","1"],["5.214","97","0","1"],["5.217","1188","0","1"],["5.224","13652","0","1"],["5.233","240","0","1"],["5.245","397","0","1"],["5.254","320","0","1"],["5.271","990","0","1"],["5.28","320","0","1"],["5.289","395","0","1"],["5.311","10","0","1"],["5.32","394","0","1"],["5.33","990","0","1"],["5.337","6","0","1"],["5.355","5","0","1"],["5.384","6","0","1"],["5.388","5","0","1"],["5.411","5","0","1"],["5.426","409","0","1"],["5.433","10","0","1"],["5.445","12","0","1"],["5.478","412","0","1"],["5.498","1","0","1"],["5.5","11","0","1"],["5.583","69","0","1"],["5.6","1","0","1"],["5.7","1","0","1"],["5.773","1","0","1"],["5.9","1","0","1"],["5.99","43","0","2"],["6","60","0","1"],["6.062","1","0","1"],["6.149","37","0","1"],["6.366","1","0","1"],["6.685","1","0","1"],["8","1","0","1"],["8.2","3","0","1"],["8.3","3","0","1"],["8.4","3","0","1"],["8.5","3","0","1"],["8.6","3","0","1"],["8.7","3","0","1"],["8.8","3","0","1"],["8.819","5","0","1"],["8.9","3","0","1"],["9","71","0","4"],["9.1","4","0","1"],["9.2","4","0","1"],["9.3","4","0","1"],["9.4","4","0","1"],["9.5","4","0","1"],["9.6","4","0","1"],["9.7","4","0","1"],["9.8","4","0","1"],["9.9","6","0","2"],["10","9","0","2"],["10.1","6","0","1"],["10.2","6","0","1"],["10.3","6","0","1"],["10.4","6","0","1"],["10.5","6","0","1"],["10.501","100","0","1"],["10.6","6","0","1"],["10.7","6","0","1"],["10.8","6","0","1"],["10.873","1","0","1"],["10.9","6","0","1"],["11","10","0","2"],["11.1","6","0","1"],["11.2","6","0","1"],["11.3","6","0","1"],["11.4","6","0","1"],["11.5","6","0","1"],["11.6","6","0","1"],["11.7","7","0","1"],["11.8","7","0","1"],["11.9","7","0","1"],["12","12","0","2"],["12.1","7","0","1"],["12.2","7","0","1"],["12.3","7","0","1"],["12.4","7","0","1"],["12.5","7","0","1"],["12.6","7","0","1"],["12.7","7","0","1"],["12.8","7","0","1"],["12.9","7","0","1"],["13","13","0","2"],["13.121","169","0","1"],["13.707","221","0","1"],["14","1","0","1"],["15.6","500","0","1"]],"bids":[["5.14","251","0","2"],["5.139","25","0","1"],["5.138","202","0","4"],["5.136","231","0","1"],["5.135","5","0","1"],["5.134","63","0","1"],["5.133","338","0","3"],["5.132","439","0","3"],["5.131","397","0","5"],["5.13","1729","0","1"],["5.128","738","0","3"],["5.126","16","0","1"],["5.124","12745","0","4"],["5.123","57","0","1"],["5.122","1785","0","2"],["5.121","412","0","3"],["5.12","115","0","2"],["5.119","1069","0","4"],["5.117","35","0","1"],["5.114","45","0","1"],["5.113","3485","0","1"],["5.106","75","0","2"],["5.105","3391","0","1"],["5.103","53","0","1"],["5.102","160","0","1"],["5.101","55","0","1"],["5.1","137","0","2"],["5.098","3498","0","1"],["5.097","160","0","1"],["5.094","396","0","1"],["5.09","2844","0","1"],["5.083","990","0","1"],["5.08","101","0","1"],["5.078","1233","0","1"],["5.072","337","0","1"],["5.07","12562","0","1"],["5.069","240","0","1"],["5.062","413","0","1"],["5.06","341","0","2"],["5.05","2","0","1"],["5.04","100","0","1"],["5.038","538","0","2"],["5.033","320","0","1"],["5.02","102","0","2"],["5.018","990","0","1"],["5.016","1","0","1"],["5.01","68","0","1"],["5.008","123","0","1"],["5.004","320","0","1"],["5","1507","0","5"],["4.98","408","0","1"],["4.974","1","0","1"],["4.962","401","0","1"],["4.95","990","0","1"],["4.928","402","0","1"],["4.9","245","0","1"],["4.8","240","0","1"],["4.75","10","0","1"],["4.725","1","0","1"],["4.7","235","0","1"],["4.67","10","0","1"],["4.6","230","0","1"],["4.574","5","0","1"],["4.5","249","0","3"],["4.488","1","0","1"],["4.46","20","0","1"],["4.45","4","0","1"],["4.438","6","0","1"],["4.4","220","0","1"],["4.39","5","0","1"],["4.36","2","0","1"],["4.3","21","0","1"],["4.263","1","0","1"],["4.26","20","0","1"],["4.258","228","0","1"],["4.236","12","0","1"],["4.19","5","0","1"],["4.167","2","0","1"],["4.16","3","0","1"],["4.06","20","0","1"],["4.049","1","0","1"],["4","353","0","3"],["3.947","34","0","1"],["3.9","6","0","1"],["3.86","20","0","1"],["3.8","38","0","1"],["3.795","75","0","1"],["3.66","20","0","1"],["3.65","73","0","1"],["3.64","17","0","1"],["3.63","59","0","1"],["3.58","38","0","2"],["3.52","1","0","1"],["3.5","3","0","1"],["3.492","43","0","2"],["3.41","3","0","1"],["3.38","25","0","1"],["3.34","34","0","1"],["3.33","21","0","1"],["3.3","33","0","1"],["3.188","37","0","2"],["3.116","3","0","1"],["3.1","337","0","2"],["3.088","61","0","1"],["3.036","130","0","3"],["3","42","0","1"],["2.9","29","0","1"],["2.88","115","0","2"],["2.8","280","0","1"],["2.6","2","0","1"],["2.45","1","0","1"],["2.4","5","0","1"],["2.18","62","0","1"],["2.1","5","0","1"],["1.95","1","0","1"],["1.922","13","0","1"],["1.9","6","0","2"],["1.8","16","0","1"],["1.5","150","0","1"],["1.3","1","0","1"],["1.23","42","0","1"]],"ts":"1652459225363","checksum":555605283}]}
1652459225.7021418: {"arg":{"channel":"books","instId":"BTC-USDT"},"action":"snapshot","data":[{"asks":[["30243.5","1.44679","0","6"],["30244","0.08","0","1"],["30246.1","0.05426064","0","1"],["30247.5","0.635","0","1"],["30248.1","0.0132","0","1"],["30249.1","0.09999997","0","1"],["30249.4","0.16562579","0","1"],["30249.7","0.06523858","0","1"],["30251.8","0.00047612","0","1"],["30251.9","0.1808","0","2"],["30252.3","0.27412546","0","1"],["30252.6","0.01648681","0","1"],["30252.9","0.19984","0","1"],["30254","0.05","0","1"],["30255","0.16","0","1"],["30255.2","0.04844827","0","1"],["30257","0.02484658","0","1"],["30257.1","0.93333757","0","2"],["30258.1","0.16","0","1"],["30259.5","0.00052769","0","1"],["30259.6","0.1","0","1"],["30260.3","0.04632884","0","1"],["30260.4","0.28027349","0","2"],["30260.5","0.74399463","0","1"],["30261","0.03","0","1"],["30261.1","0.06","0","1"],["30261.9","0.00662176","0","1"],["30262","0.85","0","1"],["30262.2","0.24845062","0","1"],["30262.7","0.33043978","0","1"],["30262.8","0.08249","0","1"],["30264.2","0.16","0","1"],["30265.6","0.883","0","1"],["30265.8","0.05","0","1"],["30266.4","0.09","0","1"],["30267.9","0.40056406","0","2"],["30268","0.55","0","3"],["30271.1","0.16","0","1"],["30274.2","0.28933546","0","2"],["30275.9","0.0094641","0","1"],["30276.9","0.00256247","0","1"],["30277.3","0.16","0","1"],["30277.5","0.0012","0","1"],["30279","0.037","0","1"],["30279.1","0.03103843","0","1"],["30280","0.053","0","2"],["30280.3","0.06","0","1"],["30280.4","0.16","0","1"],["30281.2","0.85","0","1"],["30282","0.82493","0","1"],["30283.2","0.00798335","0","1"],["30283.3","5.60195174","0","1"],["30283.5","0.0661682","0","1"],["30284.5","0.16","0","1"],["30284.7","3.018","0","1"],["30286.1","0.03163221","0","1"],["30287.2","2.44996","0","1"],["30287.6","0.8524","0","3"],["30287.7","0.1952","0","2"],["30289.6","0.08","0","1"],["30290.5","0.00008495","0","1"],["30290.8","1.01","0","2"],["30291","0.85004972","0","2"],["30291.1","0.00703238","0","1"],["30291.4","0.0000465","0","1"],["30293.9","0.16","0","1"],["30294","0.07083464","0","1"],["30296","2.45015","0","1"],["30296.4","0.0183","0","1"],["30297.8","2.45015","0","1"],["30298.5","0.02333343","0","1"],["30299.1","0.01171","0","1"],["30299.9","0.5","0","1"],["30300","0.88510977","0","6"],["30300.5","1","0","1"],["30301.3","0.00001013","0","1"],["30303","0.85099","0","2"],["30303.9","0.85","0","1"],["30304","0.016","0","1"],["30305.6","2.31208898","0","1"],["30307.6","0.0000131","0","1"],["30311.3","0.85","0","1"],["30313.3","0.00154236","0","1"],["30313.9","0.33137675","0","2"],["30314.4","0.0011218","0","1"],["30315","0.13232064","0","1"],["30316.2","2.45007","0","1"],["30316.4","0.08255","0","1"],["30319.8","0.85","0","1"],["30320","0.05301019","0","3"],["30320.6","0.00066159","0","1"],["30322.8","0.022276","0","1"],["30324","0.16539314","0","1"],["30326.1","1.67385185","0","1"],["30326.5","0.00046776","0","1"],["30327.2","0.4","0","1"],["30329.6","0.85","0","1"],["30330","0.033","0","1"],["30332.6","0.00017552","0","1"],["30333.3","0.04986236","0","3"],["30334","0.00453815","0","1"],["30336.3","0.00748258","0","2"],["30336.4","0.00005","0","1"],["30337","0.00086228","0","2"],["30339.2","0.00002071","0","1"],["30340","0.06633514","0","4"],["30340.2","0.00010958","0","1"],["30340.7","0.00066115","0","1"],["30345.5","4.62417796","0","1"],["30348","0.00340081","0","1"],["30348.4","0.0471802","0","1"],["30350","0.033","0","1"],["30353.3","1.67595385","0","2"],["30355","0.03769168","0","2"],["30359","0.00005185","0","1"],["30360","0.05304972","0","3"],["30360.8","0.00066072","0","1"],["30361.2","0.0113101","0","1"],["30365.7","0.0000465","0","1"],["30367.1","0.00073541","0","1"],["30370","0.066","0","2"],["30373.5","0.09529384","0","1"],["30375","0.00315533","0","5"],["30376.3","0.00655799","0","1"],["30376.9","0.0000131","0","1"],["30377.5","0.00319028","0","1"],["30377.7","0.00154236","0","1"],["30378.1","0.01375137","0","1"],["30379.9","0.00110782","0","1"],["30380","0.06606792","0","3"],["30380.5","1.67101924","0","1"],["30380.8","0.00066028","0","1"],["30382.1","0.00078128","0","1"],["30382.7","0.00647255","0","1"],["30383.5","0.00001013","0","1"],["30385.2","0.00126564","0","1"],["30386.7","0.02079628","0","1"],["30389.9","0.00026522","0","1"],["30390","0.066","0","2"],["30391","0.00166798","0","1"],["30391.9","0.00130052","0","1"],["30394","0.00166769","0","1"],["30395.3","0.00003044","0","1"],["30396.3","0.00576793","0","1"],["30399.9","0.00716335","0","5"],["30400","0.32567769","0","12"],["30400.1","0.0005","0","1"],["30400.9","0.00065984","0","1"],["30401","0.5","0","1"],["30404.8","0.00044899","0","1"],["30405.4","0.00165441","0","1"],["30407.1","0.00453815","0","1"],["30409.7","0.00012238","0","1"],["30410","0.06603514","0","3"],["30411","0.00102749","0","1"],["30411.4","0.00138697","0","2"],["30414","0.00087333","0","1"],["30416.6","0.00105875","0","1"],["30417","0.00008509","0","1"],["30417.2","0.000068","0","1"],["30417.4","0.00046546","0","1"],["30417.9","1.891","0","1"],["30418.7","0.00016537","0","1"],["30420","0.56194821","0","4"],["30420.9","0.00065941","0","1"],["30421.5","0.199187","0","1"],["30424.4","0.33134402","0","1"],["30424.5","0.00001067","0","1"],["30429","0.00004972","0","1"],["30430","0.033","0","1"],["30437.2","0.00002071","0","1"],["30438.3","0.00016431","0","1"],["30439","0.00005185","0","1"],["30439.9","0.0000465","0","1"],["30440","0.05337388","0","3"],["30441","0.00083449","0","3"],["30442.2","0.00154236","0","1"],["30442.6","0.00066612","0","1"],["30443","0.00261732","0","1"],["30443.1","0.00216282","0","1"],["30443.9","0.00010958","0","1"],["30444.1","0.00002403","0","2"],["30444.4","0.04844841","0","3"],["30445.7","0.00279434","0","1"],["30445.9","0.00011102","0","1"],["30446.1","0.0000131","0","1"],["30447.8","0.00155573","0","1"],["30449","0.005929","0","1"],["30449.5","0.00576925","0","2"],["30449.6","0.00084171","0","1"],["30449.9","0.00105931","0","1"],["30450","0.03662748","0","6"],["30454.6","0.0027406","0","1"],["30454.7","0.00021774","0","1"],["30455.1","0.3239921","0","1"],["30456.1","3.30021251","0","2"],["30459.4","0.10003288","0","2"],["30460","0.033","0","1"],["30460.2","0.04076","0","1"],["30461.1","0.00065854","0","2"],["30464.7","0.37768605","0","1"],["30465","0.85","0","1"],["30465.1","0.000074","0","1"],["30465.3","0.009747","0","1"],["30465.7","0.00001013","0","1"],["30466.4","0.00152554","0","1"],["30470","0.066","0","2"],["30470.7","0.0000077","0","1"],["30470.8","0.00266309","0","1"],["30472","0.0002498","0","1"],["30474","0.0002498","0","1"],["30475","0.02848655","0","1"],["30475.5","0.85","0","1"],["30476.7","0.00003044","0","1"],["30477.5","0.1386","0","1"],["30477.6","0.01353588","0","3"],["30477.9","0.00138737","0","1"],["30480","0.28391927","0","7"],["30480.4","0.00453815","0","1"],["30481.1","0.00065811","0","1"],["30484.3","0.00126564","0","1"],["30484.7","0.00127382","0","1"],["30485.3","0.00319028","0","1"],["30486.5","0.00073541","0","1"],["30488","0.0000181","0","1"],["30488.1","0.00002172","0","1"],["30488.5","0.00166798","0","1"],["30490","0.066","0","2"],["30490.5","0.00038909","0","1"],["30490.9","0.00023887","0","1"],["30491","0.00166769","0","1"],["30491.2","0.00232015","0","1"],["30492.5","0.00291576","0","1"],["30493.2","0.01061602","0","1"],["30493.3","0.00117611","0","2"],["30494.9","0.00057387","0","1"],["30495.9","0.00001067","0","1"],["30496.5","0.00655799","0","1"],["30498","0.00004972","0","1"],["30498.8","0.00031003","0","1"],["30499.9","0.06847522","0","7"],["30500","0.27471467","0","24"],["30501.2","0.00066897","0","2"],["30506","0.0001079","0","1"],["30506.7","0.00165441","0","1"],["30506.8","0.85","0","1"],["30506.9","0.00154236","0","1"],["30507.8","0.3475","0","1"],["30508.3","0.00138406","0","1"],["30510","0.099","0","3"],["30511","0.00001109","0","1"],["30512.7","0.00026215","0","2"],["30514.2","0.00008624","0","2"],["30515.1","0.001397","0","3"],["30515.3","0.0000131","0","1"],["30515.7","0.00138206","0","1"],["30517.2","0.00032326","0","1"],["30518.8","0.01375137","0","1"],["30519","0.00005185","0","1"],["30519.1","0.08842654","0","1"],["30520","0.1303285","0","8"],["30521.2","0.00065724","0","1"],["30521.8","0.00008099","0","1"],["30523.1","0.00003672","0","1"],["30523.6","0.007","0","1"],["30524","0.01919163","0","1"],["30524.5","0.00016295","0","1"],["30525","0.00016173","0","1"],["30525.4","0.00132971","0","1"],["30526.6","0.85004586","0","2"],["30529.5","0.00044899","0","1"],["30530","0.099","0","3"],["30530.4","0.00102749","0","1"],["30533.3","0.00794866","0","7"],["30535.2","0.00002071","0","1"],["30536","0.00005824","0","1"],["30536.1","0.000068","0","1"],["30538.3","0.00012238","0","1"],["30538.8","0.00138076","0","1"],["30539.5","0.00218649","0","1"],["30540","0.26375125","0","5"],["30541.3","0.00065681","0","1"],["30542.9","0.0003738","0","1"],["30545.2","0.09529384","0","1"],["30546.6","0.00005938","0","1"],["30547.4","0.00007709","0","1"],["30547.6","0.00011019","0","1"],["30547.7","0.00010958","0","1"],["30547.9","0.00001013","0","1"],["30549.3","5.584","0","1"],["30549.7","0.00017552","0","1"],["30550","0.11859288","0","6"],["30550.3","0.00008509","0","1"],["30551.2","0.00006222","0","1"],["30551.6","0.00005053","0","1"],["30553.4","0.00135672","0","1"],["30553.5","0.00087333","0","1"],["30553.8","0.00453815","0","1"],["30555","0.0009992","0","1"],["30555.5","0.0477443","0","1"],["30557.1","0.00018555","0","1"],["30558.1","0.00003044","0","1"],["30559.6","0.00873081","0","2"],["30560","0.12934028","0","7"],["30561.4","0.00065638","0","2"],["30562.8","0.00130052","0","1"],["30565.9","0.0006244","0","2"],["30566.6","0.00105931","0","1"],["30567","0.00004972","0","1"],["30567.4","0.00001067","0","1"],["30569.4","0.00138847","0","1"],["30570","0.099","0","3"],["30571.3","0.00009275","0","1"],["30571.4","0.00033671","0","1"],["30571.8","0.00154236","0","1"],["30574.3","0.00012182","0","1"],["30576.5","0.00004568","0","1"],["30576.7","0.00059496","0","1"],["30577.7","0.000031","0","1"],["30580","0.099","0","3"],["30580.9","0.00007685","0","1"],["30581.4","0.00065595","0","1"],["30583.3","0.00108158","0","2"],["30583.8","0.00126564","0","1"],["30584.6","0.0000131","0","1"],["30585.5","0.00018362","0","1"],["30586","0.00166798","0","1"],["30586.6","0.00015026","0","1"],["30587.8","0.0539246","0","1"],["30588","0.00166769","0","1"],["30588.5","0.0000465","0","1"],["30590","0.09906326","0","4"],["30591.7","0.00002944","0","1"],["30592","0.0001079","0","1"],["30592.2","0.00166906","0","2"],["30593.6","0.00319284","0","1"],["30593.9","0.00010803","0","1"],["30595","0.02848655","0","1"],["30595.7","0.00233328","0","7"],["30597.9","0.00012087","0","1"],["30599","0.00005185","0","1"],["30599.9","0.00138517","0","1"],["30600","10.37199376","0","48"],["30601.5","0.00076654","0","2"],["30603","0.00004492","0","1"],["30606.5","0.00073541","0","1"],["30606.6","0.00110782","0","1"],["30607.3","0.0001771","0","1"],["30607.4","6.53869423","0","1"],["30607.8","0.0027406","0","1"],["30608.1","0.00165441","0","1"],["30609.1","0.00010952","0","1"],["30610","0.099","0","3"],["30610.8","0.009747","0","1"],["30612","3.3923","0","1"],["30613.4","0.001","0","1"],["30615","0.00003597","0","1"],["30616.1","1.9597532","0","1"],["30616.2","0.00011287","0","1"],["30617.1","0.00655799","0","1"],["30617.6","0.00029888","0","1"],["30619.1","0.00078608","0","1"],["30619.2","0.00545437","0","4"],["30620","0.09903514","0","4"],["30620.3","0.03495864","0","1"],["30621.1","0.00001779","0","1"],["30621.5","0.00065509","0","1"],["30621.9","0.00004842","0","1"],["30622.9","0.0002498","0","1"],["30624.4","0.0002498","0","1"],["30625","0.00025083","0","4"],["30625.9","0.06729446","0","1"],["30626.6","0.00033139","0","1"],["30627.4","0.00453815","0","1"],["30629.6","0.00045906","0","1"],["30629.8","0.00010625","0","1"],["30630","0.09955051","0","4"],["30630.1","0.00001013","0","1"],["30630.3","0.00001158","0","1"],["30630.6","0.00105588","0","1"],["30631.1","0.09529384","0","1"],["30633.3","0.00073181","0","2"],["30634.4","0.00066689","0","1"],["30636","0.00004972","0","1"],["30636.3","0.00008138","0","1"],["30636.7","0.00155815","0","2"],["30637.9","0.00012767","0","1"],["30638.9","0.0019984","0","1"],["30639","0.00001067","0","1"],["30639.5","0.00003044","0","1"],["30640","0.97036266","0","9"],["30641.6","0.00065466","0","1"],["30642.3","0.00025498","0","1"],["30642.8","0.00164802","0","1"],["30643.5","0.00265198","0","1"],["30644.5","0.00016417","0","1"],["30645.9","0.0003738","0","1"],["30646.6","0.00023887","0","1"],["30650","0.10083281","0","7"],["30650.2","0.00102749","0","1"]],"bids":[["30243.4","0.0012029","0","1"],["30236.6","0.007903","0","1"],["30236.1","0.05452","0","1"],["30235.9","0.1016","0","2"],["30235","0.0002","0","1"],["30234.1","0.16","0","1"],["30234","0.07239171","0","4"],["30233.9","0.79685801","0","2"],["30232","0.01","0","1"],["30230.8","0.28156443","0","2"],["30230.2","0.85","0","1"],["30230.1","0.12784965","0","1"],["30229.3","0.00798335","0","1"],["30229.2","5.04689973","0","1"],["30228.9","0.07189416","0","1"],["30228.7","0.85286652","0","2"],["30228.6","0.01223199","0","1"],["30227.7","0.16","0","1"],["30226.8","0.12158052","0","1"],["30225.2","0.02098","0","1"],["30225.1","0.05","0","1"],["30224.8","0.01137","0","1"],["30223.4","0.33086945","0","1"],["30222.8","0.12","0","2"],["30222.5","0.00662176","0","1"],["30222.4","0.22","0","2"],["30221.3","0.075","0","1"],["30220.1","0.01648681","0","1"],["30219.9","0.000824","0","1"],["30219.3","0.16","0","1"],["30218.8","0.15","0","1"],["30218.4","0.000682","0","1"],["30218.1","0.08249","0","1"],["30216.7","0.08255","0","1"],["30216.1","0.04972912","0","1"],["30215.9","0.1","0","1"],["30215.3","0.00974381","0","1"],["30215.2","0.03147972","0","2"],["30215.1","0.78561816","0","2"],["30215","0.00042332","0","1"],["30214.8","0.16","0","1"],["30214.7","0.16558675","0","1"],["30214.6","0.025324","0","2"],["30213.3","0.00015039","0","1"],["30212.9","0.39715286","0","2"],["30212.6","0.00025519","0","1"],["30212.4","0.1","0","1"],["30212.1","0.00032352","0","1"],["30211.8","0.09957802","0","1"],["30211.7","0.16","0","1"],["30211.5","0.00001068","0","1"],["30211","0.07166424","0","1"],["30210.5","0.33239391","0","2"],["30210.4","0.02455801","0","2"],["30210","5.38148701","0","3"],["30208.9","0.01643806","0","1"],["30208.6","0.00001159","0","1"],["30208.5","0.00160826","0","1"],["30208","0.04395727","0","1"],["30207.3","0.20891382","0","2"],["30207","0.037824","0","2"],["30206.3","2.31208898","0","1"],["30205.9","0.33106115","0","1"],["30205.6","0.24666201","0","1"],["30205.3","0.05000231","0","1"],["30205.2","0.00138968","0","1"],["30205","0.00138809","0","2"],["30204.6","0.00012778","0","1"],["30204.3","0.00504249","0","1"],["30203.9","0.06202373","0","1"],["30203.1","0.16","0","1"],["30202.9","0.000824","0","1"],["30202.7","0.00165574","0","1"],["30201.8","0.09532244","0","1"],["30201.7","0.02414205","0","2"],["30201.6","0.58799999","0","1"],["30201.4","1","0","1"],["30200.9","0.01149066","0","16"],["30200","16.36561501","0","58"],["30199.9","0.00008983","0","1"],["30199.8","0.48","0","1"],["30199.6","0.00004496","0","1"],["30199.5","0.00171877","0","1"],["30199","0.0000519","0","1"],["30198.9","0.557","0","1"],["30198.5","0.16","0","1"],["30197.9","0.06852715","0","1"],["30196.4","0.24843132","0","1"],["30196","0.00193166","0","3"],["30195.9","0.00002947","0","1"],["30194.9","0.16540135","0","1"],["30194.6","0.00062297","0","2"],["30194.4","0.08","0","1"],["30194.2","0.16","0","1"],["30193.5","0.00253303","0","1"],["30193.1","0.82493","0","1"],["30192.8","0.00043358","0","1"],["30192.3","0.00112438","0","1"],["30190.2","0.25","0","1"],["30190.1","0.16","0","1"],["30190","0.03366247","0","2"],["30189.3","0.0298","0","1"],["30188.3","0.00453815","0","1"],["30187.8","0.00126666","0","1"],["30187.4","0.0006249","0","2"],["30187.2","0.06729446","0","1"],["30186.9","0.5","0","1"],["30185.9","0.00039949","0","2"],["30185.8","0.00031028","0","1"],["30185.5","0.05","0","1"],["30185.3","0.16","0","1"],["30185","0.34193049","0","1"],["30184.8","0.00422481","0","2"],["30184","0.06","0","1"],["30183.7","0.00694598","0","1"],["30183","0.24","0","1"],["30182.8","0.25","0","1"],["30182.4","0.02067639","0","1"],["30182.2","0.0016974","0","2"],["30181.9","0.00023907","0","1"],["30181.7","0.01315873","0","1"],["30181.5","0.00174519","0","1"],["30181.2","0.0000994","0","1"],["30180.9","0.00006806","0","1"],["30180","0.03618479","0","2"],["30179.9","0.33088755","0","2"],["30179.2","0.16","0","1"],["30177.4","0.00070577","0","1"],["30177","0.00441393","0","1"],["30176.6","0.0010008","0","1"],["30176.5","0.00263878","0","1"],["30176.4","0.00983197","0","2"],["30175.8","0.25146076","0","2"],["30175.7","0.00074894","0","1"],["30175.5","0.00025","0","1"],["30175.3","0.25","0","1"],["30175.2","0.005","0","1"],["30175","0.00003958","0","1"],["30174.5","0.00021792","0","1"],["30173.8","0.16","0","1"],["30173.6","0.00108744","0","2"],["30173.4","0.0003805","0","2"],["30173.3","0.02493166","0","2"],["30172.5","0.00025","0","1"],["30171.4","0.00003977","0","1"],["30170","0.03366291","0","2"],["30169.9","0.0000119","0","1"],["30169.8","0.16","0","1"],["30169.7","0.00009288","0","1"],["30169.6","0.00331459","0","1"],["30169.5","2.44699","0","1"],["30169.2","0.00001312","0","1"],["30168.9","0.00274984","0","1"],["30168.8","0.0004972","0","1"],["30168.6","0.00005058","0","1"],["30168.4","0.0077151","0","1"],["30168","0.00005829","0","1"],["30167.9","0.16546703","0","1"],["30167.4","0.00218825","0","1"],["30166.7","2.44845","0","1"],["30166.6","0.06924117","0","8"],["30166.2","0.00078671","0","1"],["30165.3","0.649","0","1"],["30164.9","0.00938518","0","1"],["30164.1","0.02210139","0","1"],["30163.7","0.16","0","1"],["30163.5","0.03987689","0","1"],["30162.9","0.00319284","0","1"],["30162.7","0.00016309","0","1"],["30162","1.00170093","0","3"],["30161.1","0.00180466","0","1"],["30160.9","0.00234309","0","1"],["30160","0.0920666","0","8"],["30159.9","0.00005943","0","1"],["30159","0.16068811","0","2"],["30158.8","0.02391009","0","1"],["30157.8","0.00008145","0","1"],["30157.3","1.68732155","0","1"],["30156.8","0.00044935","0","1"],["30156.7","0.007","0","1"],["30155.9","0.16524938","0","1"],["30154.1","0.00012248","0","1"],["30153.3","0.00110871","0","1"],["30153.2","0.00832477","0","1"],["30153.1","0.00049746","0","1"],["30153","0.00004976","0","1"],["30152.1","0.00008516","0","1"],["30151.4","0.00099498","0","1"],["30151.1","0.00003047","0","1"],["30150.7","0.00037808","0","1"],["30150.6","0.0027428","0","1"],["30150","0.06781283","0","9"],["30149.9","0.00002285","0","1"],["30149.8","2.44776","0","1"],["30147.9","0.01511238","0","1"],["30147.3","0.03317046","0","1"],["30146.4","0.00016431","0","1"],["30145.1","0.00047083","0","1"],["30144","0.51885778","0","2"],["30143.9","0.16529363","0","1"],["30143.3","2.45015","0","1"],["30143.1","0.00002073","0","1"],["30142.8","0.00004654","0","1"],["30142.4","0.00018156","0","1"],["30140.8","0.00019445","0","2"],["30140","0.03303113","0","2"],["30139.9","0.00006835","0","1"],["30138.9","0.00016551","0","1"],["30137.3","0.00656292","0","1"],["30136.9","0.00012125","0","2"],["30136.5","4.62417796","0","1"],["30135.2","0.00087403","0","1"],["30135","0.28294583","0","1"],["30134.6","0.00013","0","1"],["30134","0.00027314","0","1"],["30133.6","0.0000278","0","1"],["30133.4","0.06485789","0","2"],["30133.3","0.00744646","0","9"],["30132.7","0.00010967","0","1"],["30130.1","1.67922815","0","1"],["30130","0.03369896","0","3"],["30129.7","0.00009487","0","1"],["30129.6","0.000736","0","1"],["30128.8","0.00053924","0","2"],["30128.4","0.0003","0","1"],["30126.3","0.00001102","0","1"],["30125","0.00299602","0","4"],["30123.6","0.00010103","0","1"],["30123.4","0.02787474","0","1"],["30123.3","0.0003769","0","1"],["30122.6","0.33131275","0","1"],["30122.1","2.5","0","1"],["30120.8","0.00154236","0","1"],["30120.4","0.00003005","0","1"],["30120","0.02","0","1"],["30119.9","0.52924778","0","2"],["30119.6","0.00051537","0","1"],["30119","0.0000519","0","1"],["30117","0.00017567","0","1"],["30116","0.09532244","0","1"],["30115.8","0.00453815","0","1"],["30115.4","1.964","0","1"],["30115","0.0284951","0","1"],["30114.5","0.00127484","0","1"],["30113.2","0.00020229","0","1"],["30112.2","0.00027886","0","1"],["30112.1","0.00082143","0","1"],["30111.1","0.04777297","0","1"],["30111","0.19264785","0","5"],["30110.7","1.04799683","0","1"],["30110","0.00197517","0","3"],["30109.7","0.01338242","0","2"],["30108","0.00001293","0","1"],["30107.8","0.00059136","0","1"],["30104.1","0.00033218","0","1"],["30103","0.00166903","0","1"],["30102.9","1.67626034","0","1"],["30102.3","0.00138809","0","2"],["30102","0.00007007","0","1"],["30101.7","0.03008347","0","1"],["30101.3","0.00165574","0","1"],["30100.9","0.03307873","0","1"],["30100.1","0.001","0","1"],["30100","10.44053638","0","36"],["30099.9","0.00125898","0","3"],["30098.8","0.00020584","0","1"],["30098.6","0.01376238","0","1"],["30098.5","0.00166932","0","1"],["30097.7","0.00192522","0","1"],["30097.1","0.00015831","0","1"],["30096.6","0.05125581","0","1"],["30095.1","0.00005021","0","1"],["30093","0.00521587","0","1"],["30092.1","0.00007131","0","1"],["30091","0.00042318","0","1"],["30090.9","0.00042318","0","1"],["30090.4","0.00002299","0","1"],["30090","0.00066467","0","1"],["30089.6","0.00126666","0","1"],["30089.4","0.00001131","0","1"],["30088","0.00001812","0","1"],["30087","0.00079736","0","1"],["30086","0.00046464","0","1"],["30084.8","0.00029692","0","1"],["30084","0.00006523","0","2"],["30083.3","0.0010596","0","1"],["30083.1","0.00004353","0","1"],["30082.4","0.00943009","0","1"],["30080","0.0280102","0","3"],["30079.9","0.00071546","0","1"],["30079.6","0.00036769","0","1"],["30079.3","0.00003675","0","1"],["30075.6","0.00001581","0","1"],["30075","0.00016186","0","1"],["30070.8","0.00121268","0","1"],["30070.3","0.00001068","0","1"],["30070","0.00193548","0","2"],["30069.7","0.00003047","0","1"],["30069.6","0.00332561","0","1"],["30069.1","0.0000459","0","1"],["30068.5","0.00004654","0","1"],["30068.3","0.00001014","0","1"],["30067.9","1.58376093","0","1"],["30066.7","0.00008204","0","1"],["30066.6","0.00029214","0","1"],["30066.2","0.00011057","0","1"],["30064.7","0.3239921","0","1"],["30063.4","0.00006806","0","1"],["30061.8","0.00629768","0","1"],["30061","0.1487884","0","1"],["30060.6","0.00032352","0","1"],["30060","0.00021343","0","3"],["30059.9","0.3299067","0","1"],["30057.8","0.00138317","0","1"],["30057.7","5.722","0","1"],["30057.1","0.00033698","0","1"],["30056.9","0.00154236","0","1"],["30056.5","0.00033684","0","1"],["30056.3","0.0002255","0","1"],["30056.2","0.00319284","0","1"],["30055.5","0.00102832","0","1"],["30054.7","0.00001014","0","1"],["30053","0.00130157","0","1"],["30050.3","0.00011028","0","1"],["30050.1","0.001","0","1"],["30050","0.00542046","0","7"],["30048.2","0.00269896","0","1"],["30047.4","0.01920316","0","1"],["30046.5","0.00033282","0","1"],["30046.2","0.0014977","0","1"],["30045","0.00002073","0","1"],["30044.3","0.00017725","0","1"],["30043.4","0.00453815","0","1"],["30041.6","0.00451315","0","1"],["30040.6","0.00067598","0","1"],["30040.1","0.00009283","0","1"],["30040","0.02001654","0","2"],["30039.9","0.00110871","0","1"],["30039","0.0017164","0","2"],["30037.5","0.00006515","0","1"],["30037.3","0.0004","0","1"],["30036","0.00084576","0","1"],["30035.4","0.00233518","0","7"],["30033.5","0.00044935","0","1"],["30033.3","0.00003103","0","1"],["30033","0.01040859","0","3"],["30032.7","0.33115222","0","1"],["30032.3","0.00008106","0","1"],["30031.6","0.0004","0","1"],["30030.7","0.00001312","0","1"],["30030.6","0.00039528","0","2"],["30030.5","3.30003028","0","2"],["30030.3","0.00005209","0","1"],["30030.1","0.09532244","0","1"],["30030","0.000666","0","1"],["30029","0.00010967","0","1"],["30028.7","0.00002049","0","1"],["30028.5","0.00023907","0","1"],["30027.4","0.00025","0","1"],["30027.1","0.00012248","0","1"],["30026.6","0.00015039","0","1"],["30025.8","0.00066743","0","1"],["30025","0.00291469","0","1"],["30023.9","0.00025","0","1"],["30023.4","0.00152677","0","1"],["30022.2","0.00038274","0","1"],["30021.6","0.00110003","0","1"],["30021.4","0.00001562","0","1"],["30021","0.00113138","0","1"],["30020.8","0.00044167","0","1"],["30020.5","0.00145229","0","2"],["30020","0.20486038","0","2"],["30018.9","0.02041634","0","1"],["30018.5","0.00656292","0","1"],["30016.3","0.0000946","0","1"],["30015","0.00004976","0","1"],["30013.7","0.0010008","0","1"],["30011.6","0.000736","0","1"],["30011","0.0059978","0","1"],["30010.6","0.0000495","0","1"],["30010.5","0.00216456","0","1"],["30010","0.00066644","0","1"],["30009.9","0.00036393","0","1"],["30009.8","0.00017567","0","1"],["30009","0.00002316","0","1"],["30008.9","0.00247073","0","1"],["30006.7","0.01320342","0","2"],["30006","0.00166903","0","1"],["30005","0.12943899","0","2"],["30004.8","0.00018898","0","1"],["30004.2","0.00025375","0","1"],["30001.3","0.00004758","0","1"],["30001.1","0.00073738","0","1"],["30001","0.11337186","0","6"],["30000.5","0.00666655","0","1"],["30000.3","0.00029527","0","1"],["30000.1","0.00025519","0","1"],["30000","20.11183989","0","278"],["29999.9","0.41835049","0","24"],["29999.7","0.00276686","0","3"]],"ts":"1652459225381","checksum":47640993}]}
1652459225.708481: {"arg":{"channel":"books","instId":"BTC-USD-220527"},"action":"update","data":[{"asks":[["30249.4","0","0","0"],["30261","4","0","1"],["30310.3","19","0","1"]],"bids":[["30182.6","452","0","1"]],"ts":"1652459225464","checksum":-914047754}]}
1652459225.7087345: {"arg":{"channel":"books","instId":"BTC-USDT"},"action":"update","data":[{"asks":[["30243.5","1.2112","0","4"],["30243.6","0.059","0","1"],["30246.6","0.16","0","1"],["30247.5","0","0","0"],["30249.3","0.06523858","0","1"],["30249.7","0","0","0"],["30254.8","0.635","0","1"],["30259.5","0","0","0"],["30260.4","2.52627349","0","3"],["30261","0","0","0"],["30261.1","0","0","0"],["30264.9","0.03","0","1"],["30265.6","0","0","0"],["30265.9","0.06","0","1"],["30268","0.4","0","2"],["30268.2","0.15","0","1"],["30275","0.883","0","1"],["30283.2","0","0","0"],["30284.7","3.018","0","1"],["30293.1","0.00265859","0","1"],["30536.2","0","0","0"],["30616.1","1.9597532","0","1"],["30650","0","0","0"],["30650.2","0","0","0"],["30650.3","0","0","0"],["30651","0","0","0"]],"bids":[["30237.2","0","0","0"],["30236.1","0.05452","0","1"],["30235.9","0.1016","0","2"],["30231.6","0.07189062","0","1"],["30228.9","0","0","0"],["30227","2.244","0","1"],["30225.1","0","0","0"],["30215.2","0.00011028","0","1"],["30209.4","0.01643806","0","1"],["30209.2","0","0","0"],["30208.9","0","0","0"],["30202.7","2.96765574","0","2"],["30177.8","0.649","0","1"],["30175.3","0","0","0"],["30165.3","0","0","0"],["29999.7","0.00276686","0","3"],["29999.6","0.04507001","0","1"]],"ts":"1652459225453","checksum":-652563973}]}
1652459225.7091627: {"arg":{"channel":"books","instId":"UNI-USD-SWAP"},"action":"update","data":[{"asks":[["5.158","129","0","2"],["5.233","240","0","1"]],"bids":[["5.14","427","0","4"],["5.138","26","0","2"],["5.117","0","0","0"]],"ts":"1652459225464","checksum":1361161687}]}
1652459225.8791106: {"arg":{"channel":"books","instId":"BTC-USD-220527"},"action":"update","data":[{"asks":[["30249.6","0","0","0"],["30261","97","0","1"],["30261.1","0","0","0"],["30261.2","28","0","1"],["30264.5","0","0","0"],["30265.8","0","0","0"],["30267.3","215","0","1"],["30268.4","0","0","0"],["30270.5","468","0","1"],["30273.7","11","0","1"],["30275.1","33","0","1"],["30280.7","4","0","1"]],"bids":[["30236.6","0","0","0"],["30233.6","0","0","0"],["30232.5","3","0","1"],["30219.6","222","0","4"],["30219.5","0","0","0"],["30219.4","0","0","0"],["30218.9","0","0","0"],["30217","214","0","1"],["30215.3","214","0","1"],["30209.8","5","0","1"],["30193.9","24","0","1"],["30192.9","11","0","1"],["30185.4","0","0","0"],["30181.3","0","0","0"]],"ts":"1652459225569","checksum":1488647618}]}
1652459225.8793643: {"arg":{"channel":"books","instId":"BTC-USDT"},"action":"update","data":[{"asks":[["30243.5","0.0112","0","3"],["30243.6","0","0","0"],["30244","0","0","0"],["30244.3","0","0","0"],["30246.1","0","0","0"],["30246.6","0","0","0"],["30248.1","0","0","0"],["30249.1","0","0","0"],["30249.3","0.00087743","0","1"],["30250.1","0","0","0"],["30251.8","0.0657147","0","2"],["30251.9","0.194","0","3"],["30254","0","0","0"],["30259.5","0","0","0"],["30259.6","0","0","0"],["30262.8","0","0","0"],["30274.2","0.16","0","1"],["30280.3","0.11975743","0","2"],["30283.2","0.00798335","0","1"],["30348.4","0","0","0"],["30367.9","0.0471802","0","1"],["30616.1","0","0","0"],["30619.1","1.96034727","0","2"],["30650","0.10083281","0","7"],["30650.2","0.00102749","0","1"],["30650.3","0.00230626","0","1"],["30651","0.00007125","0","1"],["30651.4","0.00010958","0","1"],["30652.2","0.00894205","0","1"],["30653.8","0.0000131","0","1"],["30654.8","0.00044899","0","1"],["30655","0.5312","0","1"]],"bids":[["30243.4","0.3066629","0","3"],["30237.2","0.16","0","1"],["30235.5","0.12154554","0","1"],["30233.2","0.05","0","1"],["30223.5","0.00661842","0","1"],["30222.8","0.48087602","0","2"],["30222.5","0","0","0"],["30222.4","0.16","0","1"],["30218.8","0","0","0"],["30218.1","0","0","0"],["30215.1","0.76061816","0","1"],["30214.2","0.01643806","0","1"],["30211.8","0","0","0"],["30210.5","0.00138317","0","1"],["30209.4","0","0","0"],["30208.8","0","0","0"],["30201.9","0.00265028","0","1"],["30193.1","0","0","0"],["30191.9","0.16533899","0","1"],["30183","0","0","0"],["29999.9","0.41835049","0","24"],["29999.7","0.00276686","0","3"],["29999.6","0.04507001","0","1"],["29999.4","0","0","0"]],"ts":"1652459225569","checksum":2021784338}]}
1652459225.879957: {"arg":{"channel":"books","instId":"UNI-USD-SWAP"},"action":"update","data":[{"asks":[["5.153","228","0","2"],["5.155","644","0","4"],["5.157","88","0","2"],["5.16","157","0","2"]],"bids":[["5.14","350","0","3"],["5.137","146","0","1"],["5.131","406","0","5"],["5.12","150","0","3"]],"ts":"1652459225576","checksum":-1199621822}]}
1652459225.8801415: {"arg":{"channel":"books","instId":"BTC-USD-220527"},"action":"update","data":[{"asks":[["30238.8","0","0","0"],["30243.1","3","0","1"],["30244.2","2","0","1"],["30244.3","0","0","0"],["30246.9","0","0","0"],["30249.5","0","0","0"],["30255.4","50","0","1"],["30260.9","4","0","1"],["30261","0","0","0"],["30261.3","0","0","0"],["30261.5","0","0","0"],["30265.8","0","0","0"],["30265.9","0","0","0"],["30267.2","97","0","1"],["30267.7","215","0","1"],["30268.3","0","0","0"],["30270.5","0","0","0"],["30273.6","97","0","1"],["30276.1","249","0","1"],["30280.7","0","0","0"],["30280.8","97","0","1"],["30291","0","0","0"],["30304.2","19","0","1"],["30310.3","0","0","0"],["30323.1","0","0","0"],["30358.9","373","0","1"]],"bids":[["30236.9","0","0","0"],["30232.6","0","0","0"],["30232.5","0","0","0"],["30219.9","72","0","1"],["30219.8","4","0","1"],["30219.7","100","0","1"],["30219.6","0","0","0"],["30219.4","0","0","0"],["30218.8","0","0","0"],["30217","0","0","0"],["30214.9","30","0","1"],["30212.3","0","0","0"],["30211.5","50","0","1"],["30205.9","0","0","0"],["30205.8","0","0","0"],["30202.1","0","0","0"],["30190.8","249","0","1"],["30180.7","0","0","0"],["29874.1","2005","0","1"],["29846","0","0","0"],["29783.3","2002","0","1"],["29755.3","0","0","0"],["29692.6","2010","0","1"],["29664.7","0","0","0"],["29601.9","2006","0","1"],["29574","0","0","0"],["29511.2","2008","0","1"],["29483.4","0","0","0"]],"ts":"1652459225683","checksum":-1316308284}]}
1652459225.8804908: {"arg":{"channel":"books","instId":"BTC-USDT"},"action":"update","data":[{"asks":[["30243.5","0.0112","0","3"],["30247.6","0","0","0"],["30249.3","0","0","0"],["30249.4","0","0","0"],["30251.8","0.00047612","0","1"],["30252.6","0","0","0"],["30260.5","0","0","0"],["30262.7","0","0","0"],["30265.7","0.00079299","0","1"],["30269.3","0.08249","0","1"],["30275.2","0.33030335","0","1"],["30279.1","0","0","0"],["30282","0","0","0"],["30283.5","0","0","0"],["30288","0.06615944","0","1"],["30300","0.71966573","0","5"],["30310.4","0.02285387","0","1"],["30655.4","0.000068","0","1"],["30655.5","0.00038243","0","1"],["30656.5","0.00031003","0","1"],["30658.9","0","0","0"],["30660","0","0","0"]],"bids":[["30234.2","0.07189062","0","1"],["30231.6","0","0","0"],["30229.3","0.03798335","0","2"],["30226.8","0","0","0"],["30225.3","0","0","0"],["30224.5","0.08249","0","1"],["30224","0.04929","0","1"],["30222.9","0.15","0","2"],["30219.2","0.13226091","0","1"],["30215.3","0.00974381","0","1"],["30214.2","0","0","0"],["30213.1","0.01643806","0","1"],["30213","0","0","0"],["30212.9","0.33098444","0","1"],["30205.6","0","0","0"],["30205.3","0","0","0"],["30205","0.82631809","0","3"],["30197.9","0","0","0"],["30188.6","0.24","0","1"],["30183.7","0","0","0"],["30140.1","0.01382863","0","1"],["30000.1","0.00025519","0","1"],["30000","20.11183989","0","278"],["29999.9","0.41835049","0","24"],["29999.7","0.00276686","0","3"],["29999.6","0","0","0"]],"ts":"1652459225684","checksum":2101105642}]}
1652459225.8807719: {"arg":{"channel":"books","instId":"UNI-USD-SWAP"},"action":"update","data":[{"asks":[["5.155","346","0","3"]],"bids":[["5.133","407","0","4"],["5.132","453","0","4"],["5.131","351","0","4"]],"ts":"1652459225680","checksum":-96367939}]}
1652459225.9121544: {"arg":{"channel":"books","instId":"BTC-USDT"},"action":"update","data":[{"asks":[["30243.5","0.0112","0","3"],["30249.3","0","0","0"],["30251.7","0","0","0"],["30251.8","0.00047612","0","1"],["30252.1","0.06523858","0","1"],["30257","0","0","0"],["30260.3","0","0","0"],["30262.4","0.16556309","0","1"],["30264.9","0","0","0"],["30265.7","0","0","0"],["30265.8","0","0","0"],["30265.9","0","0","0"],["30266.4","0","0","0"],["30267.8","0.04903737","0","2"],["30268.2","0","0","0"],["30268.3","0.03","0","1"],["30273.1","0.06","0","1"],["30273.4","0.09","0","1"],["30274.1","0.75472509","0","1"],["30275.7","0.15","0","1"],["30655.4","0.000068","0","1"],["30655.5","0.00038243","0","1"],["30656.5","0.00031003","0","1"],["30658.9","0","0","0"],["30660","0","0","0"]],"bids":[["30243.4","0.33732919","0","4"],["30240.8","0.052","0","1"],["30240.4","0","0","0"],["30239.6","0.08108943","0","2"],["30237.1","0.01648681","0","1"],["30234.2","0","0","0"],["30227.9","0.000824","0","1"],["30224.9","0.24745648","0","1"],["30224.8","0","0","0"],["30224.6","0.00661842","0","1"],["30223.5","0","0","0"],["30220.1","0","0","0"],["30216.5","0.01643806","0","1"],["30216.4","0","0","0"],["30215.9","0","0","0"],["30214.3","0.0069404","0","1"],["30213.1","0.037","0","1"],["30212.9","0.33098444","0","1"],["30212.4","0","0","0"],["30207.6","0.557","0","1"],["30207","0.000824","0","1"],["30205.9","0.81106115","0","2"],["30199.8","0","0","0"],["30198.9","0","0","0"],["29999.9","0.41835049","0","24"],["29999.7","0","0","0"],["29999.6","0","0","0"],["29999.4","0","0","0"]],"ts":"1652459225794","checksum":-818012654}]}
1652459225.9129002: {"arg":{"channel":"books","instId":"BTC-USD-220527"},"action":"update","data":[{"asks":[["30239.6","0","0","0"],["30242.8","0","0","0"],["30243.1","0","0","0"],["30243.7","3","0","1"],["30260.9","0","0","0"],["30261.1","4","0","1"],["30261.6","0","0","0"],["30267.1","0","0","0"],["30267.2","97","0","1"],["30267.6","0","0","0"],["30273.6","97","0","1"],["30274.8","447","0","1"],["30275","0","0","0"],["30280.8","97","0","1"]],"bids":[["30236","3","0","1"],["30235.8","0","0","0"],["30232.3","0","0","0"],["30232.2","0","0","0"],["30220.2","4","0","1"],["30220.1","72","0","1"],["30220","65","0","1"],["30219.9","0","0","0"],["30219.8","0","0","0"],["30219.4","100","0","1"],["30218.9","0","0","0"]],"ts":"1652459225798","checksum":-1273685206}]}
1652459225.9132345: {"arg":{"channel":"books","instId":"UNI-USD-SWAP"},"action":"update","data":[{"asks":[["5.162","516","0","2"],["5.167","163","0","1"],["5.169","324","0","1"],["5.173","3375","0","1"],["5.175","0","0","0"],["5.178","95","0","5"]],"bids":[["5.133","507","0","5"],["5.132","439","0","3"],["5.119","455","0","3"],["5.105","4005","0","2"]],"ts":"1652459225743","checksum":1401038370}]}
1652459226.0258358: {"arg":{"channel":"books","instId":"BTC-USD-220527"},"action":"update","data":[{"asks":[["30239.6","0","0","0"],["30242.6","3","0","1"],["30243.6","2","0","1"],["30243.7","0","0","0"],["30255.3","0","0","0"],["30261.1","4","0","1"],["30261.6","0","0","0"],["30267.2","97","0","1"],["30267.6","0","0","0"],["30273.6","97","0","1"],["30274.7","0","0","0"],["30280.8","97","0","1"]],"bids":[["30236","0","0","0"],["30232.4","4","0","1"],["30232.3","3","0","1"],["30220.4","0","0","0"],["30220.3","137","0","2"],["30220.2","0","0","0"],["30220.1","0","0","0"],["30220","0","0","0"],["30219.4","0","0","0"],["30216.7","171","0","1"],["30211.6","0","0","0"]],"ts":"1652459225903","checksum":2020897465}]}
1652459226.0260785: {"arg":{"channel":"books","instId":"BTC-USDT"},"action":"update","data":[{"asks":[["30243.5","0.0112","0","3"],["30251.7","0.06523858","0","1"],["30252.1","0","0","0"],["30267.7","0.00390852","0","1"],["30267.8","0.04632884","0","1"],["30271","0.00034593","0","1"],["30275.9","0","0","0"],["30278.7","0.05","0","1"],["30279.3","0.00965369","0","1"],["30295.9","0.5","0","1"],["30299.9","0","0","0"],["30360","0.21836849","0","4"],["30655.4","0","0","0"],["30655.5","0","0","0"],["30656.5","0","0","0"]],"bids":[["30243.4","0.3066629","0","3"],["30240.8","0","0","0"],["30239.6","0.00919881","0","1"],["30237.2","0.16","0","1"],["30235.7","0.33073485","0","1"],["30234.9","0.07189062","0","1"],["30233.2","0.050824","0","2"],["30230.4","0.01565795","0","1"],["30229.3","0.00841661","0","2"],["30229","0","0","0"],["30227.9","0","0","0"],["30226.1","0.3308399","0","1"],["30225.9","0.03","0","1"],["30225.6","0.1","0","1"],["30224.5","0.23249","0","3"],["30223.4","0","0","0"],["30222.9","0","0","0"],["30221.9","0.08255","0","1"],["30219.9","0","0","0"],["30218.6","0.00792185","0","1"],["30217.4","0.06615966","0","1"],["30216.7","0","0","0"],["30216.5","0","0","0"],["30216.4","0.01643806","0","1"],["30215.3","0","0","0"],["30214.6","0.0245","0","1"],["30212.9","0","0","0"],["30209.9","0.06048955","0","1"],["30207","0","0","0"],["30202.9","0","0","0"],["29999.9","0.41835049","0","24"]],"ts":"1652459225905","checksum":1908682337}]}
1652459226.0263984: {"arg":{"channel":"books","instId":"UNI-USD-SWAP"},"action":"update","data":[{"asks":[["5.153","192","0","1"],["5.155","346","0","3"],["5.157","124","0","3"],["5.161","64","0","1"],["5.162","16","0","1"],["5.167","500","0","1"],["5.169","0","0","0"],["5.176","163","0","1"],["5.178","419","0","6"]],"bids":[["5.142","97","0","2"],["5.141","0","0","0"],["5.14","350","0","3"],["5.138","6","0","1"],["5.137","0","0","0"],["5.134","44","0","2"],["5.133","371","0","3"],["5.131","346","0","3"],["5.13","0","0","0"],["5.126","95","0","2"],["5.124","12582","0","3"],["5.122","64","0","1"],["5.118","45","0","1"],["5.114","163","0","1"],["5.113","0","0","0"],["5.105","614","0","1"]],"ts":"1652459225907","checksum":767349579}]}
1652459226.1355913: {"arg":{"channel":"books","instId":"BTC-USD-220527"},"action":"update","data":[{"asks":[["30242.6","0","0","0"],["30255.3","0","0","0"],["30261.1","4","0","1"],["30261.2","31","0","2"]],"bids":[["30235.4","0","0","0"],["30232.4","0","0","0"],["30232.3","0","0","0"],["30220.4","4","0","1"]],"ts":"1652459226019","checksum":-187595038}]}
1652459226.1357617: {"arg":{"channel":"books","instId":"BTC-USDT"},"action":"update","data":[{"asks":[["30243.5","0.0112","0","3"],["30251.6","0.00087743","0","1"],["30251.7","0","0","0"],["30252.2","0.06523858","0","1"],["30260.4","0.28027349","0","2"],["30262.2","0","0","0"],["30263.4","0.42","0","1"],["30268.3","0","0","0"],["30273","0.03","0","1"],["30279","0","0","0"],["30616.1","1.9597532","0","1"],["30619.1","0.00078608","0","1"],["30653.8","0.0000131","0","1"],["30654.8","0.00044899","0","1"],["30655","0","0","0"],["30655.4","0","0","0"]],"bids":[["30243.4","0.33732919","0","4"],["30243.3","0","0","0"],["30239.6","0.08108943","0","2"],["30234.9","0","0","0"],["30233.2","0.05","0","1"],["30229.3","0.00798335","0","1"],["30228.6","0","0","0"],["30225.9","0","0","0"],["30222.8","0.33087602","0","1"],["30216.6","0","0","0"],["30216.4","0.01643806","0","1"],["30206.6","0.05","0","1"],["30201.6","0","0","0"],["30107.7","3.5","0","1"],["30000","20.11183989","0","278"],["29999.9","0.41835049","0","24"],["29999.7","0.00276686","0","3"],["29999.6","0.04507001","0","1"]],"ts":"1652459226019","checksum":1342226290}]}
1652459226.136001: {"arg":{"channel":"books","instId":"UNI-USD-SWAP"},"action":"update","data":[{"asks":[["5.156","109","0","3"],["5.157","88","0","2"],["5.164","45","0","1"]],"bids":[["5.142","196","0","3"],["5.14","251","0","2"],["5.134","124","0","3"],["5.133","74","0","2"],["5.126","16","0","1"]],"ts":"1652459226010","checksum":541012296}]}
1652459226.1638422: {"arg":{"channel":"trades","instId":"BTC-USDT"},"data":[{"instId":"BTC-USDT","tradeId":"338476308","px":"30243.5","sz":"0.001","side":"buy","ts":"1652459226050"}]}
1652459226.1639628: {"arg":{"channel":"trades","instId":"BTC-USDT"},"data":[{"instId":"BTC-USDT","tradeId":"338476309","px":"30243.5","sz":"0.0002","side":"buy","ts":"1652459226050"}]}
1652459226.1640239: {"arg":{"channel":"trades","instId":"BTC-USDT"},"data":[{"instId":"BTC-USDT","tradeId":"338476310","px":"30243.5","sz":"0.00684062","side":"buy","ts":"1652459226050"}]}
1652459226.2522354: {"arg":{"channel":"books","instId":"BTC-USD-220527"},"action":"update","data":[{"asks":[["30240.8","0","0","0"],["30243.3","0","0","0"],["30261","4","0","1"],["30261.1","0","0","0"],["30261.2","28","0","1"],["30267.1","0","0","0"],["30267.2","97","0","1"],["30273.6","97","0","1"],["30274.8","0","0","0"]],"bids":[["30235.5","0","0","0"],["30234.2","0","0","0"],["30233.5","4","0","1"],["30233.4","0","0","0"],["30220.6","0","0","0"],["30220.5","0","0","0"],["30220.4","0","0","0"],["30211.6","0","0","0"],["30194","0","0","0"],["30156.6","19","0","1"],["30109.9","373","0","1"],["30074.6","0","0","0"]],"ts":"1652459226123","checksum":1610921771}]}
1652459226.252521: {"arg":{"channel":"books","instId":"BTC-USDT"},"action":"update","data":[{"asks":[["30243.5","0.00315938","0","1"],["30251","0.01","0","1"],["30251.6","0","0","0"],["30251.7","0.00087743","0","1"],["30251.9","0.034","0","2"],["30252","0.01","0","1"],["30252.1","0.01648681","0","1"],["30252.2","0","0","0"],["30253","0.06523858","0","1"],["30253.5","0","0","0"],["30254.4","0.01","0","1"],["30267.7","2.22290852","0","2"],["30279.1","0.24831872","0","1"],["30279.3","0","0","0"],["30284.4","0.00864367","0","1"],["30288.6","0.037","0","1"],["30294","0.89576464","0","2"],["30295.9","0","0","0"],["30316.4","0","0","0"],["30321.6","0.08255","0","1"],["30651","0","0","0"],["30651.4","0","0","0"],["30652.2","0","0","0"],["30653.8","0","0","0"],["30654.8","0","0","0"],["30655","0","0","0"],["30655.4","0","0","0"]],"bids":[["30240.3","0.16","0","1"],["30239.6","0.07189062","0","1"],["30239.2","0.12153067","0","1"],["30237.8","0.01","0","1"],["30237.1","0","0","0"],["30237","0.0002","0","1"],["30235","0","0","0"],["30234","0.06239171","0","3"],["30232","0","0","0"],["30230.3","0.0005787","0","1"],["30229.6","0.03","0","1"],["30229","0.000824","0","1"],["30228","0.06","0","1"],["30226.1","0.4805399","0","2"],["30225.9","0.15","0","1"],["30225","0.00661842","0","1"],["30224.9","0.24745648","0","1"],["30224.6","0","0","0"],["30224.5","0.08249","0","1"],["30223.7","0.00706267","0","1"],["30220","0.033","0","1"],["30219.5","0.33091215","0","1"],["30218.6","0","0","0"],["30218.4","0.000682","0","1"],["30217.7","0.01643806","0","1"],["30216.4","0","0","0"],["30210.7","0.58799999","0","1"],["30210","0.03366203","0","2"],["30209.1","1","0","1"],["30205.9","0.48","0","1"],["30203.9","0.08268932","0","2"],["30201.4","0","0","0"],["30195.4","0.24","0","1"],["30188.6","0","0","0"],["30182.4","0","0","0"],["30168.9","0","0","0"],["30000.5","0","0","0"],["30000.3","0","0","0"],["30000.1","0","0","0"],["30000","0","0","0"],["29999.9","0","0","0"],["29999.7","0","0","0"],["29999.6","0","0","0"]],"ts":"1652459226124","checksum":1141622510}]}
1652459226.2529209: {"arg":{"channel":"books","instId":"UNI-USD-SWAP"},"action":"update","data":[{"asks":[["5.148","0","0","0"],["5.149","252","0","2"]],"bids":[["5.142","97","0","2"],["5.14","350","0","3"],["5.134","44","0","2"],["5.133","154","0","3"]],"ts":"1652459226125","checksum":1975754545}]}
1652459226.2530074: {"arg":{"channel":"tickers","instId":"BTC-USDT"},"data":[{"instType":"SPOT","instId":"BTC-USDT","last":"30243.5","lastSz":"0.00684062","askPx":"30228.7","askSz":"1.55896972","bidPx":"30228.6","bidSz":"0.23393","open24h":"29700.4","high24h":"31073","low24h":"28020.3","sodUtc0":"29028.8","sodUtc8":"30337.7","volCcy24h":"525802333.80365708","vol24h":"17602.13889433","ts":"1652459226124"}]}
1652459226.2702572: {"arg":{"channel":"trades","instId":"BTC-USDT"},"data":[{"instId":"BTC-USDT","tradeId":"338476311","px":"30243.5","sz":"0.00315","side":"buy","ts":"1652459226153"}]}
1652459226.298611: {"arg":{"channel":"trades","instId":"BTC-USDT"},"data":[{"instId":"BTC-USDT","tradeId":"338476312","px":"30243.5","sz":"0.00000938","side":"buy","ts":"1652459226187"}]}
1652459226.2987268: {"arg":{"channel":"trades","instId":"BTC-USDT"},"data":[{"instId":"BTC-USDT","tradeId":"338476313","px":"30243.5","sz":"0.00019062","side":"buy","ts":"1652459226187"}]}
1652459226.3173435: {"arg":{"channel":"trades","instId":"BTC-USDT"},"data":[{"instId":"BTC-USDT","tradeId":"338476314","px":"30243.5","sz":"0.00000938","side":"buy","ts":"1652459226199"}]}
1652459226.3174298: {"arg":{"channel":"trades","instId":"BTC-USDT"},"data":[{"instId":"BTC-USDT","tradeId":"338476315","px":"30243.5","sz":"0.00000062","side":"buy","ts":"1652459226199"}]}
1652459226.363386: {"arg":{"channel":"books","instId":"BTC-USD-220527"},"action":"update","data":[{"asks":[["30243","0","0","0"],["30261","0","0","0"],["30261.2","31","0","2"],["30261.7","0","0","0"],["30267.1","4","0","1"],["30267.2","0","0","0"],["30267.6","269","0","2"],["30273.5","0","0","0"],["30273.6","97","0","1"],["30275","0","0","0"],["30280.8","97","0","1"]],"bids":[["30237.4","0","0","0"],["30234.4","4","0","1"],["30234.3","3","0","1"],["30233.5","0","0","0"],["30220.5","153","0","2"],["30220.4","0","0","0"],["30220.3","0","0","0"],["30219.8","0","0","0"],["30219.4","100","0","1"],["30211.6","0","0","0"],["30194","0","0","0"],["30184","0","0","0"],["30182.6","0","0","0"],["30156.6","0","0","0"]],"ts":"1652459226237","checksum":1660628780}]}
1652459226.3636534: {"arg":{"channel":"books","instId":"BTC-USDT"},"action":"update","data":[{"asks":[["30243.5","0","0","0"],["30250.9","0","0","0"],["30251.7","0","0","0"],["30253","0","0","0"],["30254.2","0.06523858","0","1"],["30254.7","0","0","0"],["30255.2","0","0","0"],["30260.4","0.28026349","0","2"],["30267.6","0.04632884","0","1"],["30267.7","2.219","0","1"],["30267.8","0","0","0"],["30288","0","0","0"],["30306","0.06816069","0","1"],["30321.6","0","0","0"],["30330","0.11555","0","2"],["30539.3","1.96468157","0","1"],["30616.1","0","0","0"],["30651","0.00007125","0","1"],["30651.4","0.00010958","0","1"],["30652.2","0.00894205","0","1"],["30653.8","0.0000131","0","1"]],"bids":[["30243.5","0.006","0","1"],["30240.3","0","0","0"],["30238.9","0","0","0"],["30237","0","0","0"],["30233.2","0.050824","0","2"],["30230.3","0","0","0"],["30229.7","0.00123481","0","1"],["30228.1","0.09","0","1"],["30225.4","0.02097","0","1"],["30225.2","0","0","0"],["30217.8","0.01643806","0","1"],["30217.7","0","0","0"],["30217.4","0","0","0"],["30215.1","0","0","0"],["30203.9","0.02066559","0","1"],["30202.7","0.00165574","0","1"],["30001","0.11337186","0","6"],["30000.5","0.00666655","0","1"],["30000.3","0.00029527","0","1"]],"ts":"1652459226229","checksum":-151662203}]}
1652459226.3639212: {"arg":{"channel":"books","instId":"UNI-USD-SWAP"},"action":"update","data":[{"asks":[["5.154","1824","0","1"],["5.156","301","0","4"]],"bids":[["5.134","152","0","3"],["5.133","74","0","2"]],"ts":"1652459226228","checksum":-380357418}]}
1652459226.3850417: {"arg":{"channel":"tickers","instId":"BTC-USDT"},"data":[{"instType":"SPOT","instId":"BTC-USDT","last":"30243.5","lastSz":"0.00000062","askPx":"30243.5","askSz":"0.00315938","bidPx":"30243.4","bidSz":"0.33732919","open24h":"29700.4","high24h":"31073","low24h":"28020.3","sodUtc0":"29028.8","sodUtc8":"30337.7","volCcy24h":"525802435.42181708","vol24h":"17602.14225433","ts":"1652459226240"}]}
1652459226.4800148: {"arg":{"channel":"books","instId":"BTC-USD-220527"},"action":"update","data":[{"asks":[["30243.6","2","0","1"],["30261.1","4","0","1"],["30261.2","31","0","2"],["30267.1","0","0","0"],["30267.2","0","0","0"],["30267.6","97","0","1"],["30273.5","0","0","0"],["30279.3","462","0","1"],["30280.9","0","0","0"],["30288.8","19","0","1"],["30291.1","0","0","0"],["30312","217","0","1"],["30334.7","442","0","1"],["31151.6","0","0","0"],["31158.1","6","0","1"]],"bids":[["30236.9","3","0","1"],["30234.4","0","0","0"],["30234.3","0","0","0"],["30220.7","4","0","1"],["30220.6","38","0","1"],["29339.4","6","0","1"],["29331.8","0","0","0"]],"ts":"1652459226333","checksum":1299676699}]}
1652459226.4802594: {"arg":{"channel":"books","instId":"BTC-USDT"},"action":"update","data":[{"asks":[["30250.4","0.08","0","1"],["30250.6","0.001","0","1"],["30250.7","0.01","0","1"],["30250.8","0","0","0"],["30250.9","0","0","0"],["30252.1","0","0","0"],["30253.8","0","0","0"],["30254.2","0","0","0"],["30254.3","0","0","0"],["30259.9","0.01648681","0","1"],["30261.9","0","0","0"],["30267.5","0.00396025","0","1"],["30269.3","0","0","0"],["30271","0.00696435","0","2"],["30274.5","0.08249","0","1"],["30276.9","0","0","0"],["30284.7","3.02066134","0","2"],["30385.7","0.47452829","0","1"],["30652.2","0","0","0"],["30653.8","0","0","0"],["30654.8","0","0","0"],["30655","0","0","0"]],"bids":[["30248.3","0","0","0"],["30246.9","0.0015029","0","1"],["30246.8","0","0","0"],["30245.3","0","0","0"],["30245.2","0","0","0"],["30245.1","0","0","0"],["30243.7","0.05452","0","1"],["30243.6","0.06179","0","2"],["30243.5","0.04859","0","1"],["30243.4","0.23273","0","1"],["30240.3","0.16","0","1"],["30239.6","0","0","0"],["30239.2","0.12153067","0","1"],["30239","0.0002","0","1"],["30237.8","0.01","0","1"],["30236.3","0.07188414","0","1"],["30236.1","0","0","0"],["30235.9","0.0884","0","1"],["30234","0.05145171","0","2"],["30230.8","0.16","0","1"],["30230.5","0","0","0"],["30230.3","0","0","0"],["30229.7","0","0","0"],["30229.4","0.00661842","0","1"],["30229.3","0.09047335","0","2"],["30229.2","5.04689973","0","1"],["30228.2","0","0","0"],["30225","0","0","0"],["30224.5","0","0","0"],["30222.5","0","0","0"],["30219.3","0.16","0","1"],["30218.8","0.01643806","0","1"],["30217.8","0","0","0"],["30214.4","0.06","0","1"],["30204.7","2.971","0","1"],["30184","0","0","0"],["30130","0.00069896","0","2"],["30004.2","0.00025375","0","1"],["30001.3","0.00004758","0","1"],["30001.1","0.00073738","0","1"],["30001","0","0","0"],["30000.5","0","0","0"],["30000.3","0","0","0"],["30000.1","0","0","0"],["30000","0","0","0"]],"ts":"1652459226350","checksum":-1137548519}]}
1652459226.4806352: {"arg":{"channel":"books","instId":"UNI-USD-SWAP"},"action":"update","data":[{"asks":[["5.154","1874","0","2"]],"bids":[["5.134","41","0","2"],["5.133","192","0","3"],["5.132","333","0","3"],["5.13","0","0","0"]],"ts":"1652459226346","checksum":1200718641}]}
1652459226.5797434: {"arg":{"channel":"books","instId":"BTC-USDT"},"action":"update","data":[{"asks":[["30250.2","0.0012","0","2"],["30250.3","0","0","0"],["30250.4","0","0","0"],["30250.6","0","0","0"],["30251","0","0","0"],["30251.9","0","0","0"],["30252","0","0","0"],["30252.3","0","0","0"],["30254.4","0","0","0"],["30254.6","0","0","0"],["30254.8","0","0","0"],["30255","0","0","0"],["30255.4","0.0132","0","1"],["30256.4","0.06523858","0","1"],["30257.5","0.05064799","0","1"],["30261","0.635","0","1"],["30267.5","0","0","0"],["30272.7","0.04940324","0","1"],["30280.3","0.06","0","1"],["30287.8","0.13224364","0","1"],["30539.3","0","0","0"],["30545.1","1.96430851","0","1"],["30651.4","0.00010958","0","1"],["30652.2","0.00894205","0","1"],["30653.8","0.0000131","0","1"],["30654.8","0.00044899","0","1"],["30655","0","0","0"]],"bids":[["30250.1","0.2742329","0","3"],["30250","0","0","0"],["30248.5","0","0","0"],["30248.4","0","0","0"],["30247.3","0","0","0"],["30247.2","0","0","0"],["30246.9","0","0","0"],["30243.9","0.16","0","1"],["30243.6","0.04859","0","1"],["30243.4","0","0","0"],["30238.9","0.07188243","0","1"],["30236.3","0","0","0"],["30230.9","0.03604722","0","2"],["30230.4","0","0","0"],["30230.3","0.77572356","0","1"],["30230.2","0.85","0","1"],["30229.4","0","0","0"],["30227","2.32655","0","2"],["30223.4","0.06614566","0","1"],["30222.9","0.00034593","0","1"],["30221.9","0","0","0"],["30218.9","0","0","0"],["30218.8","0","0","0"],["30216.8","0.01643806","0","1"],["30215.9","0.05990056","0","1"],["30209.9","0.22583347","0","2"],["30179.9","0.16540299","0","1"],["30168.4","1.66514381","0","2"],["30159","0.00068811","0","1"],["30157.3","0","0","0"],["30141.1","1.68552497","0","1"],["30130.1","0","0","0"],["30113.9","1.66640917","0","1"],["30102.9","0","0","0"],["30004.8","0.00018898","0","1"],["30004.2","0.00025375","0","1"],["30001.3","0.00004758","0","1"],["30001.1","0","0","0"],["30001","0","0","0"]],"ts":"1652459226454","checksum":541102824}]}
1652459226.5805345: {"arg":{"channel":"books","instId":"BTC-USD-220527"},"action":"update","data":[{"asks":[["30241.6","0","0","0"],["30243.6","0","0","0"],["30244.2","0","0","0"],["30247.9","2","0","1"],["30248","3","0","1"],["30261.2","28","0","1"],["30267.2","97","0","1"],["30267.6","0","0","0"],["30273.6","97","0","1"],["30275","0","0","0"],["30276","97","0","1"],["30280.8","0","0","0"],["30283","97","0","1"]],"bids":[["30240.7","0","0","0"],["30237","0","0","0"],["30236.9","0","0","0"],["30234.4","0","0","0"],["30234.3","0","0","0"],["30220.9","104","0","2"],["30220.8","65","0","1"],["30220.7","38","0","1"],["30220.6","0","0","0"],["30219.4","0","0","0"],["30211.7","0","0","0"],["30211.6","0","0","0"],["30199.4","11","0","1"],["30192.9","0","0","0"],["30184.1","470","0","1"]],"ts":"1652459226458","checksum":-707774218}]}
1652459226.580866: {"arg":{"channel":"books","instId":"UNI-USD-SWAP"},"action":"update","data":[{"asks":[],"bids":[["5.134","127","0","3"],["5.133","192","0","3"],["5.132","247","0","2"]],"ts":"1652459226428","checksum":-756333598}]}
1652459226.693954: {"arg":{"channel":"books","instId":"BTC-USD-220527"},"action":"update","data":[{"asks":[["30242.6","3","0","1"],["30243","0","0","0"],["30248","0","0","0"],["30255.3","0","0","0"],["30261","4","0","1"],["30261.1","0","0","0"],["30267.2","97","0","1"],["30273.6","97","0","1"],["30276","97","0","1"],["30279.3","0","0","0"],["30283","0","0","0"],["30316","0","0","0"],["30324.9","81","0","1"],["30358.8","202","0","1"],["30371.7","0","0","0"],["30464.9","0","0","0"],["30486.8","706","0","2"],["30590.9","0","0","0"],["30608.7","202","0","1"]],"bids":[["30235.6","0","0","0"],["30232.7","0","0","0"],["30232.6","3","0","1"],["30222.6","214","0","1"],["30221.1","4","0","1"],["30221","0","0","0"],["30220.9","100","0","1"],["30220.8","0","0","0"],["30220.7","0","0","0"],["30220.5","0","0","0"],["30219.7","0","0","0"],["30211.6","0","0","0"],["30133.3","81","0","1"],["30117.7","0","0","0"],["30110","202","0","1"],["30074.9","0","0","0"],["29974.6","202","0","1"],["29955.3","0","0","0"],["29837.5","202","0","1"],["29817.9","0","0","0"]],"ts":"1652459226561","checksum":-864714409}]}
1652459226.6946027: {"arg":{"channel":"books","instId":"BTC-USDT"},"action":"update","data":[{"asks":[["30250.2","0.28252","0","4"],["30254.4","0.06523858","0","1"],["30255.1","0","0","0"],["30256.4","0","0","0"],["30260.4","0.03306","0","1"],["30263.5","0.06862558","0","1"],["30267.7","0","0","0"],["30267.8","0.00273703","0","1"],["30270.9","0","0","0"],["30273","0.30412546","0","2"],["30284.7","0.00266134","0","1"],["30325","0.08255","0","1"],["30330","0.033","0","1"],["30652.2","0.00894205","0","1"],["30653.8","0","0","0"],["30654.8","0","0","0"],["30655","0","0","0"]],"bids":[["30250.1","0.0015029","0","1"],["30246.1","5.40679115","0","1"],["30243.9","0","0","0"],["30243.7","0","0","0"],["30243.6","0","0","0"],["30243.5","0","0","0"],["30242.8","0.05452","0","1"],["30239.2","0.13473067","0","2"],["30238.9","0","0","0"],["30236.4","0.07188243","0","1"],["30231","0","0","0"],["30230.9","0.03604722","0","2"],["30230.4","0.00284164","0","1"],["30217.6","0.08","0","1"],["30216.9","0.01643806","0","1"],["30216.8","0","0","0"],["30212.7","0.48","0","1"],["30209.9","0.22850422","0","3"],["30205.9","0","0","0"],["30194.4","0","0","0"],["30001.3","0.00004758","0","1"],["30001.1","0.00073738","0","1"],["30001","0","0","0"],["30000.5","0","0","0"]],"ts":"1652459226566","checksum":-1671876413}]}
1652459226.6952546: {"arg":{"channel":"books","instId":"UNI-USD-SWAP"},"action":"update","data":[{"asks":[["5.16","122","0","1"],["5.162","51","0","2"]],"bids":[["5.142","196","0","3"],["5.14","251","0","2"],["5.122","99","0","2"],["5.12","115","0","2"]],"ts":"1652459226561","checksum":1378967421}]}
1652459226.8000443: {"arg":{"channel":"books","instId":"BTC-USD-220527"},"action":"update","data":[{"asks":[["30242.6","0","0","0"],["30242.9","2","0","1"],["30243","0","0","0"],["30250.3","3","0","1"],["30255.3","4","0","1"],["30255.4","53","0","2"],["30261","0","0","0"],["30273.6","0","0","0"],["30276","97","0","1"],["30283","0","0","0"]],"bids":[["30235.9","3","0","1"],["30232.6","0","0","0"],["30231.2","65","0","1"],["30223.7","0","0","0"],["30222.7","4","0","1"],["30222.6","0","0","0"],["30221.2","0","0","0"],["30221.1","0","0","0"],["30220.9","0","0","0"],["30219.4","428","0","2"],["30219.3","0","0","0"],["30216.8","0","0","0"],["30215.3","0","0","0"],["30215","0","0","0"],["30204.2","100","0","1"]],"ts":"1652459226677","checksum":1068906520}]}
1652459226.8006694: {"arg":{"channel":"books","instId":"BTC-USDT"},"action":"update","data":[{"asks":[["30250.2","0.31210561","0","5"],["30253.3","0.16","0","1"],["30254","0.06523858","0","1"],["30254.4","0","0","0"],["30257.5","0","0","0"],["30260.4","0","0","0"],["30267.1","0.03306","0","1"],["30267.5","0.00423552","0","1"],["30267.8","0","0","0"],["30267.9","0.64776755","0","3"],["30269.5","0.00661842","0","1"],["30269.6","2.258","0","1"],["30271","0.00034593","0","1"],["30282.8","0.05","0","1"],["30286.1","0","0","0"],["30292.7","0.0291571","0","1"],["30293.9","3.285","0","2"],["30295","0.25","0","1"],["30298.5","0","0","0"],["30545.1","0","0","0"],["30618.6","1.95959319","0","1"],["30651","0","0","0"],["30651.4","0","0","0"],["30652.2","0","0","0"],["30653.8","0","0","0"]],"bids":[["30246.2","0.00798335","0","1"],["30246.1","0","0","0"],["30244.4","0","0","0"],["30240.3","0.1732","0","2"],["30239.2","0.12153067","0","1"],["30237.8","0","0","0"],["30236.4","0","0","0"],["30232.1","0.02097","0","1"],["30231.6","0.07188243","0","1"],["30231","0","0","0"],["30230.9","0.03755872","0","3"],["30230.4","0","0","0"],["30229.3","0.09047335","0","2"],["30225.4","0","0","0"],["30217.5","0.01643806","0","1"],["30217.1","0","0","0"],["30216.9","0","0","0"],["30214.3","0","0","0"],["30200.2","0.25","0","1"],["30181.7","0","0","0"],["30176.5","0","0","0"],["30001.3","0.00004758","0","1"],["30001.1","0.00073738","0","1"],["30001","0.11337186","0","6"],["30000.5","0.00666655","0","1"],["30000.3","0.00029527","0","1"],["30000.1","0.00025519","0","1"]],"ts":"1652459226682","checksum":-353378943}]}
1652459226.801265: {"arg":{"channel":"books","instId":"UNI-USD-SWAP"},"action":"update","data":[{"asks":[["5.149","272","0","3"],["5.151","0","0","0"],["5.153","240","0","2"],["5.161","0","0","0"],["5.165","64","0","1"]],"bids":[["5.14","20","0","1"],["5.135","67","0","2"],["5.131","284","0","2"]],"ts":"1652459226676","checksum":1330940026}]}
1652459226.8689554: {"arg":{"channel":"trades","instId":"BTC-USDT"},"data":[{"instId":"BTC-USDT","tradeId":"338476316","px":"30250.1","sz":"0.00066996","side":"sell","ts":"1652459226753"}]}
1652459226.877533: {"arg":{"channel":"trades","instId":"BTC-USDT"},"data":[{"instId":"BTC-USDT","tradeId":"338476317","px":"30250.1","sz":"0.00083294","side":"sell","ts":"1652459226765"}]}
1652459226.9097915: {"arg":{"channel":"books","instId":"BTC-USDT"},"action":"update","data":[{"asks":[["30242","0.0002","0","1"],["30242.1","0.0005","0","1"],["30250.1","0.856","0","2"],["30250.2","0.05245","0","3"],["30250.3","0","0","0"],["30250.4","0","0","0"],["30252.3","0.0132","0","1"],["30255.4","0","0","0"],["30259.6","0.04944869","0","1"],["30261.9","0.04632884","0","1"],["30266.9","0.00383651","0","1"],["30267","0.06233182","0","1"],["30267.5","0","0","0"],["30267.8","0.00661842","0","1"],["30269.5","0","0","0"],["30272.7","0.37940324","0","5"],["30273","0.27412546","0","1"],["30273.1","0","0","0"],["30273.4","0","0","0"],["30273.8","0","0","0"],["30274.5","0.08249","0","1"],["30274.7","0.09921356","0","1"],["30275.7","0","0","0"],["30278.6","0.00794887","0","1"],["30284.4","0","0","0"],["30287.8","0","0","0"],["30290.5","0","0","0"],["30302.4","0.00008241","0","1"],["30360","0.05304972","0","3"],["30545.1","1.96430851","0","1"],["30618.6","0","0","0"],["30650","0","0","0"],["30650.2","0","0","0"],["30650.3","0","0","0"],["30651","0","0","0"],["30651.4","0","0","0"]],"bids":[["30250.1","0","0","0"],["30246.2","0","0","0"],["30242.8","0","0","0"],["30242","0","0","0"],["30241.9","0.23273","0","1"],["30241.2","0","0","0"],["30240.3","0","0","0"],["30237.7","0.07188243","0","1"],["30236.8","0.0114","0","1"],["30233.9","0.4","0","1"],["30233.2","0.000824","0","1"],["30231.6","0","0","0"],["30230.9","0.0294288","0","1"],["30230.4","0","0","0"],["30223.7","0","0","0"],["30222.9","0.00696435","0","2"],["30219.5","0","0","0"],["30218.8","0.0211722","0","1"],["30217.9","0.00919365","0","1"],["30217.5","0","0","0"],["30216.6","0","0","0"],["30216.4","0.01643806","0","1"],["30212.7","0","0","0"],["30210.7","0","0","0"],["30209.1","0","0","0"],["30206.6","0.05694056","0","2"],["30206.4","0.48","0","1"],["30204.7","0","0","0"],["30203.8","0.58799999","0","1"],["30202.1","1","0","1"],["30195.4","0","0","0"],["30193.6","0.01315619","0","1"],["30188.9","0.24","0","1"],["30056.3","0","0","0"],["30000.3","0.00029527","0","1"],["30000.1","0.00025519","0","1"],["30000","20.11183989","0","278"],["29999.9","0.41835049","0","24"],["29999.7","0.00276686","0","3"]],"ts":"1652459226784","checksum":1955057806}]}
1652459226.9106293: {"arg":{"channel":"books","instId":"BTC-USD-220527"},"action":"update","data":[{"asks":[["30237.7","0","0","0"],["30239.4","3","0","1"],["30241.3","2","0","1"],["30241.4","0","0","0"],["30247.8","0","0","0"],["30247.9","0","0","0"],["30250.3","0","0","0"],["30255.3","4","0","1"],["30255.4","50","0","1"],["30261.1","97","0","1"],["30267.2","0","0","0"],["30267.6","97","0","1"],["30279.4","19","0","1"],["30279.7","452","0","1"],["30304.2","0","0","0"],["30605.4","0","0","0"],["30606","202","0","1"],["30608.7","0","0","0"],["31149.3","6","0","1"],["31158.1","0","0","0"]],"bids":[["30235.9","0","0","0"],["30233.6","0","0","0"],["30231.2","0","0","0"],["30230.4","3","0","1"],["30222.7","0","0","0"],["30219.7","104","0","2"],["30219.6","0","0","0"],["30219.5","0","0","0"],["30219.4","0","0","0"],["30218.1","0","0","0"],["30218","0","0","0"],["30217","0","0","0"],["30216.8","0","0","0"],["30216.4","214","0","1"],["30211.6","100","0","1"],["30204.2","100","0","1"],["30199.4","0","0","0"],["30192.4","11","0","1"],["30184.1","0","0","0"],["30133.3","0","0","0"],["30130.4","81","0","1"],["30110","0","0","0"],["30066.2","202","0","1"],["29974.6","0","0","0"],["29971.4","202","0","1"],["29837.5","0","0","0"],["29834.2","202","0","1"],["29339.4","0","0","0"],["29333.1","5","0","1"]],"ts":"1652459226792","checksum":2085193407}]}
1652459226.9110608: {"arg":{"channel":"books","instId":"UNI-USD-SWAP"},"action":"update","data":[{"asks":[["5.151","53","0","1"],["5.153","192","0","1"]],"bids":[["5.135","5","0","1"],["5.133","254","0","4"]],"ts":"1652459226727","checksum":-1107069311}]}
1652459226.9507754: {"arg":{"channel":"trades","instId":"BTC-USDT"},"data":[{"instId":"BTC-USDT","tradeId":"338476318","px":"30241.9","sz":"0.0009","side":"sell","ts":"1652459226834"}]}
1652459226.9578824: {"arg":{"channel":"tickers","instId":"BTC-USDT"},"data":[{"instType":"SPOT","instId":"BTC-USDT","last":"30250.1","lastSz":"0.00083294","askPx":"30243.5","askSz":"0.00315938","bidPx":"30243.4","bidSz":"0.33732919","open24h":"29700.4","high24h":"31073","low24h":"28020.3","sodUtc0":"29028.8","sodUtc8":"30337.7","volCcy24h":"525802480.88469237","vol24h":"17602.14375723","ts":"1652459226825"}]}
1652459227.0224605: {"arg":{"channel":"books","instId":"BTC-USD-220527"},"action":"update","data":[{"asks":[["30239.4","0","0","0"],["30240.6","3","0","1"],["30261.1","0","0","0"],["30266.3","215","0","1"],["30267.2","97","0","1"],["30267.6","0","0","0"],["30267.7","0","0","0"],["30273.6","97","0","1"],["30606","0","0","0"],["30606.9","202","0","1"]],"bids":[["30230.5","0","0","0"],["30219.7","0","0","0"],["30217.6","0","0","0"],["30217.5","214","0","1"],["30216.9","4","0","1"],["30216.8","100","0","1"],["30215","100","0","1"],["30211.6","0","0","0"],["30133.3","81","0","1"],["30130.4","0","0","0"],["30109.9","575","0","2"],["30066.2","0","0","0"],["29972.8","202","0","1"],["29971.4","0","0","0"],["29835.7","202","0","1"],["29834.2","0","0","0"]],"ts":"1652459226908","checksum":-1893960378}]}
1652459227.0228462: {"arg":{"channel":"books","instId":"BTC-USDT"},"action":"update","data":[{"asks":[["30242","0.0012","0","2"],["30242.1","0","0","0"],["30248.5","0","0","0"],["30248.9","0.00087743","0","1"],["30249","0.06523858","0","1"],["30250","0","0","0"],["30250.1","0.85","0","1"],["30250.2","0.04859","0","1"],["30254","0","0","0"],["30257","0.1","0","1"],["30261.9","0.05294726","0","2"],["30266.9","0","0","0"],["30267.6","0","0","0"],["30267.8","0","0","0"],["30273.5","0.56837991","0","1"],["30277.1","0.00253853","0","1"],["30283.2","0.00798335","0","1"],["30325","0","0","0"],["30333.7","0.08255","0","1"],["30650","0","0","0"],["30650.2","0","0","0"]],"bids":[["30241.9","0.25630659","0","3"],["30240.4","0.00183347","0","2"],["30237.7","0","0","0"],["30237.2","0","0","0"],["30236.8","0.0246","0","2"],["30236.7","0.4","0","1"],["30234.2","0.07189337","0","1"],["30230.9","0","0","0"],["30224.3","0.02302647","0","1"],["30213.4","0.33097896","0","1"],["30209.9","0.22583347","0","2"],["30168.4","0.0077151","0","1"],["30158.6","1.66738962","0","1"],["30141.1","0","0","0"],["30131.4","1.67268343","0","1"],["30113.9","0","0","0"],["30104.2","1.67816196","0","1"],["30000","0","0","0"],["29999.9","0","0","0"],["29999.7","0","0","0"]],"ts":"1652459226888","checksum":1278364416}]}
1652459227.0237007: {"arg":{"channel":"books","instId":"UNI-USD-SWAP"},"action":"update","data":[{"asks":[["5.149","212","0","2"]],"bids":[],"ts":"1652459226883","checksum":1146082652}]}
1652459227.1152577: {"arg":{"channel":"tickers","instId":"BTC-USDT"},"data":[{"instType":"SPOT","instId":"BTC-USDT","last":"30241.9","lastSz":"0.0009","askPx":"30243.5","askSz":"0.00315938","bidPx":"30243.4","bidSz":"0.33732919","open24h":"29700.4","high24h":"31073","low24h":"28020.3","sodUtc0":"29028.8","sodUtc8":"30337.7","volCcy24h":"525802508.10240237","vol24h":"17602.14465723","ts":"1652459226978"}]}
1652459227.132311: {"arg":{"channel":"books","instId":"BTC-USD-220527"},"action":"update","data":[{"asks":[],"bids":[["30217.6","38","0","1"],["30216.4","0","0","0"],["30215","100","0","1"],["30189","465","0","1"]],"ts":"1652459227010","checksum":-1764497054}]}
1652459227.132517: {"arg":{"channel":"books","instId":"BTC-USDT"},"action":"update","data":[{"asks":[["30242","0.0012","0","2"],["30248.9","0","0","0"],["30249","0","0","0"],["30249.5","0.06523858","0","1"],["30273.5","0","0","0"],["30283.2","0.00798335","0","1"],["30650","0.10083281","0","7"],["30650.2","0.00102749","0","1"]],"bids":[["30240.4","0","0","0"],["30234","0.05943506","0","3"],["30233.9","2.693","0","2"],["30232.8","0.01648681","0","1"],["30230.3","0.80072356","0","2"],["30229.3","0.08249","0","1"],["30227","2.244","0","1"],["30221.6","0.08255","0","1"],["30214.6","0","0","0"],["30175.8","0.00146076","0","1"],["30140.1","0","0","0"],["30000","20.11183989","0","278"]],"ts":"1652459227004","checksum":-1485453296}]}
1652459227.1328664: {"arg":{"channel":"books","instId":"UNI-USD-SWAP"},"action":"update","data":[{"asks":[["5.189","6807","0","2"]],"bids":[["5.121","1999","0","4"]],"ts":"1652459226926","checksum":1339352176}]}
1652459227.2438974: {"arg":{"channel":"books","instId":"BTC-USDT"},"action":"update","data":[{"asks":[["30242","0.0012","0","2"],["30249.2","0","0","0"],["30249.5","0","0","0"],["30249.7","0","0","0"],["30250.1","0","0","0"],["30250.2","0","0","0"],["30250.4","0.06523858","0","1"],["30275.7","0.0265","0","1"],["30312","0.16530346","0","1"],["30326.8","0.08255","0","1"],["30333.7","0","0","0"],["30545.1","0","0","0"],["30611.9","1.96002208","0","1"],["30650.2","0.00102749","0","1"],["30650.3","0","0","0"]],"bids":[["30238.8","0.16","0","1"],["30217.5","0.01643806","0","1"],["30216.4","0","0","0"],["30000","0","0","0"]],"ts":"1652459227127","checksum":637351193}]}
1652459227.2442498: {"arg":{"channel":"books","instId":"BTC-USD-220527"},"action":"update","data":[{"asks":[["30240.6","0","0","0"],["30241.1","0","0","0"],["30255.3","0","0","0"],["30255.4","53","0","2"],["30261.1","0","0","0"],["30266.3","0","0","0"],["30267.1","4","0","1"]],"bids":[["30233.7","3","0","1"],["30230.5","0","0","0"],["30230.4","0","0","0"],["30217.7","4","0","1"],["30217.6","0","0","0"],["30216.9","0","0","0"],["30215","0","0","0"]],"ts":"1652459227125","checksum":1023321165}]}
1652459227.24443: {"arg":{"channel":"books","instId":"UNI-USD-SWAP"},"action":"update","data":[{"asks":[["5.149","272","0","3"]],"bids":[["5.134","131","0","3"]],"ts":"1652459227127","checksum":-1724950524}]}
1652459227.3373353: {"arg":{"channel":"trades","instId":"BTC-USDT"},"data":[{"instId":"BTC-USDT","tradeId":"338476319","px":"30242","sz":"0.0002","side":"buy","ts":"1652459227219"}]}
1652459227.3374891: {"arg":{"channel":"trades","instId":"BTC-USDT"},"data":[{"instId":"BTC-USDT","tradeId":"338476320","px":"30242","sz":"0.001","side":"buy","ts":"1652459227219"}]}
1652459227.3541384: {"arg":{"channel":"books","instId":"BTC-USD-220527"},"action":"update","data":[{"asks":[["30255.4","50","0","1"],["30261.1","4","0","1"],["30267.1","0","0","0"],["30270","172","0","1"],["30276","0","0","0"],["30279.4","0","0","0"],["30279.7","0","0","0"],["30283","97","0","1"]],"bids":[["30233.8","4","0","1"],["30227","1702","0","1"],["30219.8","0","0","0"],["30217.7","0","0","0"],["30217.6","0","0","0"],["30217.5","0","0","0"],["30216.8","0","0","0"],["30211.6","0","0","0"],["30204.2","0","0","0"],["30193.5","20","0","1"],["30181.2","0","0","0"],["30168.9","0","0","0"]],"ts":"1652459227237","checksum":614805369}]}
1652459227.3546443: {"arg":{"channel":"books","instId":"BTC-USDT"},"action":"update","data":[{"asks":[["30242","0","0","0"],["30247.6","0.00002","0","1"],["30250.1","0","0","0"],["30250.4","0","0","0"],["30250.6","0.00087743","0","1"],["30251.1","0.06523858","0","1"],["30252","0.01","0","1"],["30253","0.01","0","1"],["30253.3","0","0","0"],["30254.4","0.16","0","1"],["30259","0.03307","0","1"],["30266.9","0","0","0"],["30267.1","0","0","0"],["30269.6","0","0","0"],["30278.6","0","0","0"],["30283.2","0.00798335","0","1"],["30284.3","0.0078776","0","1"],["30293.9","0.16","0","1"],["30305.5","0.5","0","1"],["30317","0.02555244","0","1"],["30326.8","0","0","0"],["30333.5","0.08255","0","1"],["30645.9","0","0","0"],["30646.6","0","0","0"],["30650","0","0","0"],["30650.2","0","0","0"]],"bids":[["30242","0.006","0","1"],["30241.9","0.41630659","0","4"],["30237.7","0.01","0","1"],["30232.1","0","0","0"],["30230.4","0.00230813","0","1"],["30230.3","0.77572356","0","1"],["30227.8","0.08255","0","1"],["30223.8","0.02097","0","1"],["30223.6","0.00791868","0","1"],["30221.6","0","0","0"],["30218.7","0.01643806","0","1"],["30218.3","0","0","0"],["30217.9","0","0","0"],["30217.5","0","0","0"],["30216.1","0","0","0"],["30207.3","0.16","0","1"],["30200.1","0.02037169","0","1"],["30107.7","0","0","0"],["30000.5","0.00666655","0","1"],["30000.3","0","0","0"],["30000.1","0","0","0"]],"ts":"1652459227231","checksum":260823837}]}
1652459227.3554955: {"arg":{"channel":"books","instId":"UNI-USD-SWAP"},"action":"update","data":[{"asks":[],"bids":[["5.134","127","0","3"]],"ts":"1652459227179","checksum":-1219754310}]}
1652459227.4627194: {"arg":{"channel":"tickers","instId":"BTC-USDT"},"data":[{"instType":"SPOT","instId":"BTC-USDT","last":"30242","lastSz":"0.001","askPx":"30243.5","askSz":"0.00315938","bidPx":"30243.4","bidSz":"0.33732919","open24h":"29700.4","high24h":"31073","low24h":"28020.3","sodUtc0":"29028.8","sodUtc8":"30337.7","volCcy24h":"525802544.39280237","vol24h":"17602.14585723","ts":"1652459227340"}]}
1652459227.4648912: {"arg":{"channel":"books","instId":"BTC-USD-220527"},"action":"update","data":[{"asks":[["30241.3","0","0","0"],["30242.9","0","0","0"],["30245.5","3","0","1"],["30247.2","2","0","1"],["30247.3","0","0","0"],["30255.4","50","0","1"],["30267.2","0","0","0"],["30269.9","0","0","0"],["30270","0","0","0"],["30273.6","97","0","1"],["30275","97","0","1"],["30277.1","470","0","1"],["30283","97","0","1"],["30288.7","0","0","0"]],"bids":[["30240","0","0","0"],["30237","3","0","1"],["30233.8","0","0","0"],["30233.7","0","0","0"],["30227.3","104","0","2"],["30227.2","65","0","1"],["30227.1","0","0","0"],["30227","0","0","0"],["30225.6","0","0","0"],["30220.5","100","0","1"],["30220.4","214","0","1"],["30216.8","0","0","0"],["30211.6","100","0","1"]],"ts":"1652459227342","checksum":-250750059}]}
1652459227.465067: {"arg":{"channel":"books","instId":"BTC-USDT"},"action":"update","data":[{"asks":[["30247.6","0.0012","0","2"],["30250.6","0","0","0"],["30251.1","0","0","0"],["30251.5","0.06523858","0","1"],["30251.9","0","0","0"],["30252","0","0","0"],["30253","0","0","0"],["30254.4","0","0","0"],["30258.1","0.21","0","2"],["30261.9","0","0","0"],["30263.3","0.02472725","0","1"],["30267","2.31833182","0","2"],["30268.1","0.00798335","0","1"],["30268.2","6.01300526","0","1"],["30271","0.05197237","0","3"],["30274.7","0","0","0"],["30283.2","0","0","0"],["30284.6","0.12937117","0","1"],["30291.3","2.988","0","1"],["30333.5","0","0","0"],["30340.9","0.08255","0","1"],["30645.9","0.0003738","0","1"],["30646.6","0.00023887","0","1"],["30650","0","0","0"]],"bids":[["30247.5","0.00135203","0","1"],["30245.6","0","0","0"],["30245.1","0","0","0"],["30243.6","0","0","0"],["30243.5","0","0","0"],["30242.1","0.1372082","0","3"],["30242","0.4132","0","2"],["30241.9","0.18342456","0","2"],["30241","0.0002","0","1"],["30240.3","0.04858363","0","1"],["30239","0","0","0"],["30237.7","0.081829","0","2"],["30236.8","0.0114","0","1"],["30234.2","0","0","0"],["30233","0.08255","0","1"],["30232.9","0.03","0","1"],["30230.9","0","0","0"],["30230.4","0","0","0"],["30229.6","0","0","0"],["30229.3","0.23249","0","2"],["30227.8","0.00661842","0","1"],["30226.2","0","0","0"],["30225.9","0","0","0"],["30225.1","0.05028971","0","1"],["30223.6","0","0","0"],["30222.9","0.00034593","0","1"],["30219.7","0","0","0"],["30219.2","0.14166574","0","2"],["30218.7","0","0","0"],["30216.4","0.01643806","0","1"],["30160.6","2.45015","0","1"],["30145.2","0.01382629","0","1"],["30143.3","0","0","0"],["30005","0.12943899","0","2"],["30004.8","0.00018898","0","1"],["30004.2","0.00025375","0","1"],["30001.3","0.00004758","0","1"],["30001.1","0.00073738","0","1"],["30001","0","0","0"],["30000.5","0","0","0"]],"ts":"1652459227353","checksum":850097887}]}
1652459227.578889: {"arg":{"channel":"books","instId":"BTC-USDT"},"action":"update","data":[{"asks":[["30247.6","0.0012","0","2"],["30250.9","0.06523858","0","1"],["30251.5","0","0","0"],["30258.1","0.16","0","1"],["30266.9","0.00354398","0","1"],["30322.5","0.08255","0","1"],["30340.9","0","0","0"],["30611.9","0","0","0"],["30637.7","1.95837155","0","1"],["30646.6","0","0","0"]],"bids":[["30247.5","0.07408203","0","2"],["30242.1","0.09732","0","2"],["30242","0.0132","0","1"],["30241.9","0.16","0","1"],["30233","0","0","0"],["30221.4","0.08255","0","1"],["30219","0.01643806","0","1"],["30216.4","0","0","0"]],"ts":"1652459227436","checksum":675913805}]}
1652459227.5791776: {"arg":{"channel":"books","instId":"BTC-USD-220527"},"action":"update","data":[{"asks":[["30245.4","2","0","1"],["30261.1","4","0","1"],["30267.2","0","0","0"]],"bids":[["29340.1","6","0","1"],["29333.1","0","0","0"]],"ts":"1652459227416","checksum":1415764812}]}
1652459227.6873095: {"arg":{"channel":"books","instId":"BTC-USD-220527"},"action":"update","data":[{"asks":[["30245.5","0","0","0"],["30255.4","0","0","0"],["30261.1","4","0","1"],["30267.2","0","0","0"],["30267.3","218","0","2"],["30269.1","215","0","1"],["30273.6","0","0","0"]],"bids":[["30239.8","0","0","0"],["30237.1","0","0","0"],["30237","0","0","0"],["30227.4","4","0","1"],["30227.3","100","0","1"],["30220.1","0","0","0"],["30211.5","0","0","0"]],"ts":"1652459227570","checksum":163895810}]}
1652459227.6876147: {"arg":{"channel":"books","instId":"BTC-USDT"},"action":"update","data":[{"asks":[["30247.6","0.0012","0","2"],["30250.9","0","0","0"],["30251.4","0","0","0"],["30252.1","0.06523858","0","1"],["30266.9","0","0","0"],["30268.1","0","0","0"],["30268.2","0","0","0"],["30274.5","0","0","0"],["30283.2","0.00798335","0","1"],["30294","0.07083464","0","1"],["30456.1","0.00049251","0","1"],["30646.6","0.00023887","0","1"],["30650","0.10083281","0","7"],["30650.2","0.00102749","0","1"]],"bids":[["30247.5","0.30681203","0","3"],["30239.3","0.05","0","1"],["30232.9","0","0","0"],["30229.3","0.18","0","2"],["30219.7","0.01643806","0","1"],["30219","0","0","0"],["30218.1","0","0","0"],["30216.4","0","0","0"],["30205","0.00138809","0","2"],["30167.3","2.44776","0","1"],["30149.8","0","0","0"],["30030.5","0.00031028","0","1"]],"ts":"1652459227572","checksum":611664851}]}
1652459227.68798: {"arg":{"channel":"books","instId":"UNI-USD-SWAP"},"action":"update","data":[{"asks":[],"bids":[["5.099","3177","0","1"]],"ts":"1652459227514","checksum":-1219754310}]}
1652459227.800407: {"arg":{"channel":"books","instId":"BTC-USDT"},"action":"update","data":[{"asks":[["30247.6","0.23393","0","3"],["30252","0.01","0","1"],["30252.1","0.06523858","0","1"],["30252.5","0","0","0"],["30253.8","0.16","0","1"],["30259","0","0","0"],["30264.6","0.03307","0","1"],["30275.7","0","0","0"],["30650.2","0","0","0"],["30650.3","0","0","0"]],"bids":[["30247.5","0.07408203","0","2"],["30242.1","0.0428","0","1"],["30241.9","0","0","0"],["30239","0.01","0","1"],["30238","0.01","0","1"],["30237.7","0.071829","0","1"],["30229.4","0.02097","0","1"],["30229.3","0.03","0","1"],["30226.8","0.15","0","1"],["30223.8","0","0","0"],["30219.7","0","0","0"],["30218.2","0.01643806","0","1"],["30216.4","0","0","0"],["30211.6","0.58799999","0","1"],["30203.8","0","0","0"],["30001.3","0","0","0"],["30001.1","0","0","0"],["30001","0","0","0"]],"ts":"1652459227676","checksum":2134570732}]}
1652459227.8009017: {"arg":{"channel":"books","instId":"BTC-USD-220527"},"action":"update","data":[{"asks":[["30244.4","0","0","0"],["30261.1","4","0","1"],["30267.2","0","0","0"],["30267.3","218","0","2"],["30269.1","0","0","0"],["30273.6","97","0","1"],["30275","97","0","1"],["30276.1","0","0","0"],["30277","0","0","0"],["30283","97","0","1"],["30358.9","0","0","0"],["30599.4","0","0","0"]],"bids":[["30237.1","0","0","0"],["30237","3","0","1"],["30227.7","4","0","1"],["30227.6","100","0","1"],["30227.5","65","0","1"],["30227.4","0","0","0"],["30227.3","0","0","0"],["30227.2","0","0","0"],["30226.1","0","0","0"],["30221.2","100","0","1"],["30221.1","0","0","0"],["30220.5","0","0","0"],["30216.8","0","0","0"],["30215","100","0","1"],["30211.6","0","0","0"],["30204.2","0","0","0"],["30190.8","0","0","0"],["30109.9","202","0","1"],["30016.8","0","0","0"]],"ts":"1652459227676","checksum":1833756640}]}
1652459227.8012784: {"arg":{"channel":"books","instId":"UNI-USD-SWAP"},"action":"update","data":[{"asks":[["5.149","252","0","2"],["5.151","0","0","0"],["5.152","25","0","2"],["5.153","249","0","2"]],"bids":[["5.136","300","0","2"],["5.134","64","0","2"]],"ts":"1652459227680","checksum":137859130}]}
1652459227.9085546: {"arg":{"channel":"books","instId":"BTC-USDT"},"action":"update","data":[{"asks":[["30247.6","0.23393","0","3"],["30247.8","0","0","0"],["30251.3","0.06523858","0","1"],["30251.7","0","0","0"],["30252","0","0","0"],["30252.1","0","0","0"],["30253.3","0.09999997","0","1"],["30253.8","0.16","0","1"],["30266.9","0","0","0"],["30267.8","0.05162644","0","2"],["30271","0.00034593","0","1"],["30464.7","0","0","0"],["30617.7","1.95965079","0","1"],["30637.7","0","0","0"],["30650.2","0","0","0"],["30650.3","0","0","0"],["30651","0","0","0"]],"bids":[["30247.5","0.00135203","0","1"],["30242.1","0","0","0"],["30241.4","0.05452","0","1"],["30237.7","0","0","0"],["30234.7","0.071829","0","1"],["30218.2","0","0","0"],["30217.7","0","0","0"],["30216.4","0.01643806","0","1"],["30207.1","1","0","1"],["30202.1","0","0","0"],["30001.3","0","0","0"]],"ts":"1652459227790","checksum":-33444428}]}
1652459227.9089382: {"arg":{"channel":"books","instId":"BTC-USD-220527"},"action":"update","data":[{"asks":[["30267.3","218","0","2"],["30268.7","97","0","1"],["30268.8","215","0","1"],["30273.6","0","0","0"]],"bids":[["30227.6","0","0","0"],["30221.4","100","0","1"],["30221.3","38","0","1"],["30221.2","0","0","0"],["30220.5","0","0","0"],["30220.4","0","0","0"],["30219.7","0","0","0"],["30219.6","214","0","1"],["30216.8","0","0","0"],["30215","100","0","1"],["30204.2","0","0","0"]],"ts":"1652459227789","checksum":669423422}]}
1652459227.9091296: {"arg":{"channel":"books","instId":"UNI-USD-SWAP"},"action":"update","data":[{"asks":[["5.152","25","0","2"],["5.153","249","0","2"]],"bids":[["5.134","59","0","2"],["5.133","136","0","3"],["5.131","547","0","3"],["5.126","11867","0","2"],["5.124","731","0","2"]],"ts":"1652459227785","checksum":-1108930323}]}
1652459228.024033: {"arg":{"channel":"books","instId":"BTC-USD-220527"},"action":"update","data":[{"asks":[["30269.2","172","0","1"],["30304.2","20","0","1"]],"bids":[["30227.7","0","0","0"],["30227.5","0","0","0"],["30222.8","104","0","2"],["30222.7","1777","0","1"],["30221.4","0","0","0"],["30221.3","0","0","0"],["30220","171","0","1"],["30219.9","0","0","0"],["30219.7","0","0","0"],["30219.6","0","0","0"],["30216.7","0","0","0"],["30215","0","0","0"]],"ts":"1652459227881","checksum":-2044872963}]}
1652459228.0244522: {"arg":{"channel":"books","instId":"BTC-USDT"},"action":"update","data":[{"asks":[["30247.6","0.23393","0","3"],["30247.8","0","0","0"],["30247.9","0","0","0"],["30650","0.10083281","0","7"]],"bids":[["30237.7","0.071829","0","1"],["30234.7","0","0","0"],["30217.4","0","0","0"],["30216.4","0.01643806","0","1"]],"ts":"1652459227861","checksum":-10135460}]}
1652459228.0246935: {"arg":{"channel":"books","instId":"UNI-USD-SWAP"},"action":"update","data":[{"asks":[["5.151","57","0","1"],["5.153","192","0","1"]],"bids":[],"ts":"1652459227888","checksum":-575901983}]}
1652459228.1269076: {"arg":{"channel":"books","instId":"BTC-USD-220527"},"action":"update","data":[{"asks":[],"bids":[["30189","0","0","0"]],"ts":"1652459227954","checksum":67565745}]}
1652459228.1271129: {"arg":{"channel":"books","instId":"BTC-USDT"},"action":"update","data":[{"asks":[["30247.6","0.23393","0","3"],["30250.9","0.06523858","0","1"],["30251.3","0","0","0"],["30327.2","0","0","0"],["30650.2","0.00102749","0","1"],["30650.3","0","0","0"]],"bids":[["30236.7","0","0","0"],["30234.2","0.01565813","0","1"],["30234","0.05145171","0","2"],["30233.9","0.4","0","1"],["30229.3","0.03798335","0","2"],["30227","0","0","0"],["30216.5","0.01643806","0","1"],["30216.4","0","0","0"],["30001.3","0.00004758","0","1"]],"ts":"1652459228009","checksum":-147379158}]}
1652459228.1274726: {"arg":{"channel":"books","instId":"UNI-USD-SWAP"},"action":"update","data":[{"asks":[["5.17","0","0","0"],["5.174","64","0","1"]],"bids":[["5.136","231","0","1"],["5.134","128","0","3"]],"ts":"1652459227978","checksum":-1141734217}]}
1652459228.2405875: {"arg":{"channel":"books","instId":"BTC-USDT"},"action":"update","data":[{"asks":[["30247.6","0.23393","0","3"],["30269.5","0.00798335","0","1"],["30269.6","5.97833133","0","1"],["30283.2","0","0","0"],["30305.5","0","0","0"],["30326.9","0.4","0","1"],["30650","0.10083281","0","7"],["30650.2","0","0","0"]],"bids":[["30241.4","0","0","0"],["30240.5","0.05452","0","1"],["30236.6","0","0","0"],["30234.6","2.219","0","1"],["30216.9","0.01643806","0","1"],["30216.5","0","0","0"],["30216.4","0","0","0"],["30210.4","3.10455801","0","3"],["30001.1","0","0","0"]],"ts":"1652459228114","checksum":-764702519}]}
1652459228.241052: {"arg":{"channel":"books","instId":"BTC-USD-220527"},"action":"update","data":[{"asks":[],"bids":[["30190.1","470","0","1"]],"ts":"1652459228097","checksum":-887746123}]}
1652459228.241193: {"arg":{"channel":"books","instId":"UNI-USD-SWAP"},"action":"update","data":[{"asks":[],"bids":[["5.136","300","0","2"],["5.134","59","0","2"]],"ts":"1652459228051","checksum":676634976}]}
1652459228.3272204: {"arg":{"channel":"trades","instId":"BTC-USDT"},"data":[{"instId":"BTC-USDT","tradeId":"338476321","px":"30247.5","sz":"0.00135203","side":"sell","ts":"1652459228210"}]}
1652459228.3477354: {"arg":{"channel":"books","instId":"BTC-USDT"},"action":"update","data":[{"asks":[["30242.5","0.0005","0","1"],["30244","0.0002","0","1"],["30247.5","0.86168686","0","3"],["30247.6","0.001","0","1"],["30250.9","0","0","0"],["30251.3","0.06523858","0","1"],["30266.9","0.00661842","0","1"],["30279.3","0.00682431","0","1"],["30284.3","0","0","0"],["30292.1","0.25","0","1"],["30401","0","0","0"],["30644.5","0","0","0"],["30645.9","0","0","0"],["30646.6","0","0","0"],["30650","0","0","0"],["30650.2","0","0","0"]],"bids":[["30247.5","0","0","0"],["30242.4","0.01","0","1"],["30240.9","0.01","0","1"],["30239.7","0.01","0","1"],["30217.4","0","0","0"],["30216.9","0.01643806","0","1"],["30211.6","0","0","0"],["30207.1","1.05","0","2"],["30206.6","0.00694056","0","1"],["30205.3","0.58799999","0","1"],["30004.8","0.00018898","0","1"],["30004.2","0","0","0"],["30001.3","0","0","0"],["30001.1","0","0","0"]],"ts":"1652459228228","checksum":-163517608}]}
1652459228.348079: {"arg":{"channel":"books","instId":"BTC-USD-220527"},"action":"update","data":[{"asks":[["30244.9","2","0","1"],["30245","0","0","0"],["30247.2","0","0","0"],["30261.2","31","0","2"],["30267.2","0","0","0"],["30267.3","215","0","1"],["30268.7","0","0","0"],["30268.8","0","0","0"],["30269.1","97","0","1"],["30269.2","215","0","1"],["30273.6","0","0","0"],["30279.4","19","0","1"]],"bids":[["30222.8","4","0","1"],["30222.7","0","0","0"],["30220.3","100","0","1"],["30220.2","38","0","1"],["30220.1","100","0","1"],["30219.4","214","0","1"],["30219","214","0","1"],["30204.2","100","0","1"],["30181.2","19","0","1"]],"ts":"1652459228236","checksum":1819592519}]}
1652459228.3482857: {"arg":{"channel":"books","instId":"UNI-USD-SWAP"},"action":"update","data":[{"asks":[["5.158","130","0","3"]],"bids":[["5.136","231","0","1"]],"ts":"1652459228228","checksum":1119324166}]}
1652459228.3615592: {"arg":{"channel":"trades","instId":"BTC-USDT"},"data":[{"instId":"BTC-USDT","tradeId":"338476322","px":"30242.5","sz":"0.001","side":"buy","ts":"1652459228246"}]}
1652459228.3617551: {"arg":{"channel":"trades","instId":"BTC-USDT"},"data":[{"instId":"BTC-USDT","tradeId":"338476323","px":"30244","sz":"0.0002","side":"buy","ts":"1652459228246"}]}
1652459228.4101129: {"arg":{"channel":"trades","instId":"BTC-USDT"},"data":[{"instId":"BTC-USDT","tradeId":"338476324","px":"30247.5","sz":"0.00568686","side":"buy","ts":"1652459228289"}]}
1652459228.428348: {"arg":{"channel":"tickers","instId":"BTC-USDT"},"data":[{"instType":"SPOT","instId":"BTC-USDT","last":"30247.5","lastSz":"0.00568686","askPx":"30243.5","askSz":"0.00315938","bidPx":"30243.4","bidSz":"0.33732919","open24h":"29700.4","high24h":"31073","low24h":"28020.3","sodUtc0":"29028.8","sodUtc8":"30337.7","volCcy24h":"525802793.59292764","vol24h":"17602.15409612","ts":"1652459228299"}]}
1652459228.457653: {"arg":{"channel":"books","instId":"BTC-USD-220527"},"action":"update","data":[{"asks":[["30243.4","3","0","1"],["30261.2","28","0","1"],["30267.2","97","0","1"],["30269.1","0","0","0"],["30269.2","0","0","0"],["30273.6","97","0","1"],["30275","97","0","1"],["30283","0","0","0"],["30606.8","0","0","0"],["30606.9","202","0","1"]],"bids":[["30239","0","0","0"],["30237","0","0","0"],["30235.3","3","0","1"],["30223.2","4","0","1"],["30223.1","0","0","0"],["30223","191","0","3"],["30222.9","0","0","0"],["30222.8","0","0","0"],["30220.4","0","0","0"],["30220.3","100","0","1"],["30220.2","0","0","0"],["30220.1","0","0","0"],["30215","0","0","0"],["30168.9","20","0","1"],["30109.9","202","0","1"],["30066.2","0","0","0"],["29972.8","202","0","1"],["29972.7","0","0","0"],["29835.7","202","0","1"],["29835.6","0","0","0"]],"ts":"1652459228340","checksum":-2037805113}]}
1652459228.4582467: {"arg":{"channel":"books","instId":"BTC-USDT"},"action":"update","data":[{"asks":[["30242.5","0","0","0"],["30244","0","0","0"],["30247.5","0.001","0","1"],["30247.6","0","0","0"],["30249.3","0","0","0"],["30250.2","0","0","0"],["30250.8","0.06523858","0","1"],["30251.3","0","0","0"],["30252.2","0.0132","0","1"],["30252.3","0","0","0"],["30253.3","0","0","0"],["30253.7","0.16","0","1"],["30253.8","0","0","0"],["30266.9","0.0513834","0","2"],["30267.8","0","0","0"],["30269.5","0","0","0"],["30269.6","0","0","0"],["30277","0.0302","0","1"],["30283.2","0.00798335","0","1"],["30322.5","0","0","0"],["30331.6","0.08255","0","1"],["30617.7","0","0","0"],["30620.7","1.9594588","0","1"],["30644.5","0.00016417","0","1"],["30645.9","0.0003738","0","1"],["30646.6","0.00023887","0","1"],["30650","0.10083281","0","7"],["30650.2","0.00102749","0","1"],["30650.3","0","0","0"]],"bids":[["30247.4","0.11033642","0","2"],["30243.9","0.23273","0","1"],["30243.6","0","0","0"],["30243","0.0002","0","1"],["30242.5","0.85","0","1"],["30242.4","0.04419636","0","1"],["30241","0","0","0"],["30240.9","0","0","0"],["30239.7","0","0","0"],["30239.3","0.21","0","2"],["30239","0","0","0"],["30238.8","0","0","0"],["30234.2","0","0","0"],["30230.1","0.21039965","0","2"],["30227.8","0","0","0"],["30226.2","0.00661842","0","1"],["30225.7","0","0","0"],["30221.4","0","0","0"],["30221.3","0.075","0","1"],["30219.2","0.1581038","0","3"],["30216.9","0","0","0"],["30004.8","0.00018898","0","1"],["30004.2","0.00025375","0","1"],["30001.3","0.00004758","0","1"],["30001.1","0.00073738","0","1"],["30001","0.11337186","0","6"]],"ts":"1652459228344","checksum":1066810455}]}
1652459228.4597816: {"arg":{"channel":"books","instId":"UNI-USD-SWAP"},"action":"update","data":[{"asks":[],"bids":[["5.134","36","0","1"],["5.133","167","0","4"],["5.132","306","0","3"]],"ts":"1652459228320","checksum":1362459986}]}
1652459228.4818895: {"arg":{"channel":"trades","instId":"BTC-USDT"},"data":[{"instId":"BTC-USDT","tradeId":"338476325","px":"30247.4","sz":"0.00042377","side":"sell","ts":"1652459228367"}]}
1652459228.499604: {"arg":{"channel":"trades","instId":"BTC-USDT"},"data":[{"instId":"BTC-USDT","tradeId":"338476326","px":"30247.4","sz":"0.00042211","side":"sell","ts":"1652459228383"}]}
1652459228.515715: {"arg":{"channel":"trades","instId":"BTC-USDT"},"data":[{"instId":"BTC-USDT","tradeId":"338476327","px":"30247.4","sz":"0.00143753","side":"sell","ts":"1652459228398"}]}
1652459228.5344024: {"arg":{"channel":"tickers","instId":"BTC-USDT"},"data":[{"instType":"SPOT","instId":"BTC-USDT","last":"30247.4","lastSz":"0.00042211","askPx":"30243.5","askSz":"0.00315938","bidPx":"30243.4","bidSz":"0.33732919","open24h":"29700.4","high24h":"31073","low24h":"28020.3","sodUtc0":"29028.8","sodUtc8":"30337.7","volCcy24h":"525802819.17859835","vol24h":"17602.154942","ts":"1652459228401"}]}
1652459228.5701928: {"arg":{"channel":"books","instId":"BTC-USDT"},"action":"update","data":[{"asks":[["30247.5","0.0012","0","2"],["30250.8","0","0","0"],["30251.3","0.06523858","0","1"],["30253.7","0","0","0"],["30650.3","0.00230626","0","1"],["30651","0","0","0"]],"bids":[["30247.4","0.34078301","0","3"],["30243.9","0","0","0"],["30230.1","0.12784965","0","1"],["30226.8","0.15661673","0","2"],["30226.2","0","0","0"],["30223.7","0.08255","0","1"],["30222.4","0.17643806","0","2"],["30220.1","0","0","0"],["30219.2","0.14166574","0","2"],["30000.5","0.00666655","0","1"],["30000.3","0","0","0"]],"ts":"1652459228457","checksum":-2114630375}]}
1652459228.5706618: {"arg":{"channel":"books","instId":"UNI-USD-SWAP"},"action":"update","data":[{"asks":[["5.158","136","0","3"]],"bids":[["5.136","231","0","1"],["5.133","238","0","5"],["5.132","247","0","2"]],"ts":"1652459228434","checksum":1296494846}]}
1652459228.5783563: {"arg":{"channel":"books","instId":"BTC-USD-220527"},"action":"update","data":[{"asks":[["30243.4","0","0","0"],["30261.1","4","0","1"],["30267.1","0","0","0"],["30267.2","3","0","1"],["30273.6","97","0","1"],["30275","97","0","1"],["30277","0","0","0"],["30283","97","0","1"]],"bids":[["30238.7","3","0","1"],["30235.9","0","0","0"],["30235.8","0","0","0"],["30235.4","0","0","0"],["30235.3","0","0","0"],["30223.3","4","0","1"],["30223.2","100","0","1"],["30223.1","0","0","0"],["30223","81","0","1"],["30220.3","0","0","0"],["30219.5","100","0","1"],["30215","100","0","1"],["30204.2","0","0","0"]],"ts":"1652459228433","checksum":-1716271076}]}
1652459228.6767962: {"arg":{"channel":"tickers","instId":"BTC-USDT"},"data":[{"instType":"SPOT","instId":"BTC-USDT","last":"30247.4","lastSz":"0.00143753","askPx":"30243.5","askSz":"0.00315938","bidPx":"30243.4","bidSz":"0.33732919","open24h":"29700.4","high24h":"31073","low24h":"28020.3","sodUtc0":"29028.8","sodUtc8":"30337.7","volCcy24h":"525802862.66014328","vol24h":"17602.15637953","ts":"1652459228536"}]}
1652459228.6832824: {"arg":{"channel":"books","instId":"BTC-USDT"},"action":"update","data":[{"asks":[["30247.5","0.00406","0","3"],["30263.4","0","0","0"],["30617.7","1.95965079","0","1"],["30620.7","0","0","0"],["30651","0.00007125","0","1"]],"bids":[["30247.4","0.34078301","0","3"]],"ts":"1652459228568","checksum":308193036}]}
1652459228.6836336: {"arg":{"channel":"books","instId":"BTC-USD-220527"},"action":"update","data":[{"asks":[["30275","97","0","1"],["30277","0","0","0"]],"bids":[["30168.9","0","0","0"]],"ts":"1652459228504","checksum":-2028729695}]}
1652459228.683851: {"arg":{"channel":"books","instId":"UNI-USD-SWAP"},"action":"update","data":[{"asks":[["5.149","356","0","5"],["5.151","0","0","0"],["5.155","382","0","4"],["5.156","265","0","3"]],"bids":[["5.142","77","0","1"],["5.14","119","0","2"],["5.133","84","0","3"],["5.132","340","0","3"],["5.131","284","0","2"],["5.129","47","0","1"]],"ts":"1652459228558","checksum":1605311632}]}
1652459228.7936335: {"arg":{"channel":"books","instId":"BTC-USDT"},"action":"update","data":[{"asks":[["30247.5","0.00406","0","3"],["30251.3","0","0","0"],["30251.8","0.0657147","0","2"],["30256.4","0.01","0","1"],["30264.5","0.03306","0","1"],["30264.6","0","0","0"],["30323.8","0.08255","0","1"],["30331.6","0","0","0"]],"bids":[["30239.7","0.01","0","1"],["30238","0","0","0"],["30229.4","0","0","0"],["30229.1","0.02097","0","1"],["30145.2","0","0","0"],["30000.3","0.00029527","0","1"]],"ts":"1652459228673","checksum":1914620269}]}
1652459228.7939935: {"arg":{"channel":"books","instId":"BTC-USD-220527"},"action":"update","data":[{"asks":[["30270.2","97","0","1"],["30270.3","215","0","1"],["30273.6","0","0","0"]],"bids":[],"ts":"1652459228636","checksum":1018159803}]}
1652459228.7941508: {"arg":{"channel":"books","instId":"UNI-USD-SWAP"},"action":"update","data":[{"asks":[["5.148","60","0","1"],["5.149","297","0","4"],["5.151","0","0","0"],["5.152","25","0","2"],["5.154","2157","0","3"],["5.155","105","0","3"],["5.157","89","0","3"],["5.158","129","0","2"]],"bids":[["5.133","131","0","4"],["5.131","284","0","2"],["5.129","293","0","1"]],"ts":"1652459228672","checksum":1589108891}]}
1652459228.8690083: {"arg":{"channel":"trades","instId":"BTC-USDT"},"data":[{"instId":"BTC-USDT","tradeId":"338476328","px":"30247.4","sz":"0.00124642","side":"sell","ts":"1652459228754"}]}
1652459228.8691819: {"arg":{"channel":"trades","instId":"BTC-USDT"},"data":[{"instId":"BTC-USDT","tradeId":"338476329","px":"30247.4","sz":"0.00232917","side":"sell","ts":"1652459228754"}]}
1652459228.9003394: {"arg":{"channel":"tickers","instId":"BTC-USDT"},"data":[{"instType":"SPOT","instId":"BTC-USDT","last":"30247.4","lastSz":"0.00124642","askPx":"30243.5","askSz":"0.00315938","bidPx":"30243.4","bidSz":"0.33732919","open24h":"29700.4","high24h":"31073","low24h":"28020.3","sodUtc0":"29028.8","sodUtc8":"30337.7","volCcy24h":"525802970.81244424","vol24h":"17602.15995512","ts":"1652459228758"}]}
1652459228.9043617: {"arg":{"channel":"books","instId":"BTC-USDT"},"action":"update","data":[{"asks":[["30247.5","0.23393","0","3"],["30251.3","0.06523858","0","1"],["30251.8","0.00047612","0","1"],["30253.2","0.703","0","1"],["30253.5","0.09999997","0","1"],["30253.7","0.16","0","1"],["30263.6","0.00798335","0","1"],["30263.7","5.9790638","0","1"],["30266.8","0","0","0"],["30283.2","0","0","0"],["30491.5","0.3774513","0","1"],["30645.9","0","0","0"],["30646.6","0","0","0"],["30650","0","0","0"],["30650.2","0","0","0"],["30650.3","0","0","0"],["30651","0","0","0"]],"bids":[["30247.4","0","0","0"],["30242.4","0","0","0"],["30239.7","0","0","0"],["30236.5","0.4","0","1"],["30234.6","0","0","0"],["30230.4","0.00201533","0","1"],["30230","0.033","0","1"],["30226.1","0.3308399","0","1"],["30210.4","0.02455801","0","2"],["30110.7","0","0","0"],["30000.3","0.00029527","0","1"],["30000.1","0.00025519","0","1"],["30000","20.11183989","0","278"]],"ts":"1652459228787","checksum":1696417398}]}
1652459228.9049976: {"arg":{"channel":"books","instId":"BTC-USD-220527"},"action":"update","data":[{"asks":[["30244.1","3","0","1"],["30267.2","97","0","1"],["30270.2","0","0","0"],["30275","97","0","1"],["30277","0","0","0"],["30283","97","0","1"]],"bids":[["30238.7","0","0","0"],["30236.7","0","0","0"],["30223.6","137","0","2"],["30223.5","100","0","1"],["30223.4","0","0","0"],["30223.3","0","0","0"],["30223.2","0","0","0"],["30223","0","0","0"],["30222.6","81","0","1"],["30220.2","4","0","1"],["30220.1","0","0","0"],["30219.8","0","0","0"],["30219.6","214","0","1"],["30219.5","0","0","0"],["30219.4","214","0","1"],["30219","0","0","0"],["30215","100","0","1"],["30204.2","100","0","1"],["30190.1","0","0","0"],["30182.9","2627","0","1"]],"ts":"1652459228781","checksum":-1441129697}]}
1652459228.9053116: {"arg":{"channel":"books","instId":"UNI-USD-SWAP"},"action":"update","data":[{"asks":[["5.148","20","0","1"],["5.151","60","0","1"],["5.166","12043","0","2"]],"bids":[["5.132","247","0","2"]],"ts":"1652459228747","checksum":-1980943189}]}
1652459229.0082831: {"arg":{"channel":"tickers","instId":"BTC-USDT"},"data":[{"instType":"SPOT","instId":"BTC-USDT","last":"30247.4","lastSz":"0.00232917","askPx":"30243.5","askSz":"0.00315938","bidPx":"30243.4","bidSz":"0.33732919","open24h":"29700.4","high24h":"31073","low24h":"28020.3","sodUtc0":"29028.8","sodUtc8":"30337.7","volCcy24h":"525802970.81244424","vol24h":"17602.15995512","ts":"1652459228866"}]}
1652459229.0233908: {"arg":{"channel":"books","instId":"BTC-USD-220527"},"action":"update","data":[{"asks":[["30243.4","0","0","0"],["30244.1","0","0","0"],["30261.2","31","0","2"],["30267.2","97","0","1"],["30270.2","0","0","0"],["30270.3","0","0","0"],["30273.6","97","0","1"],["30275","0","0","0"],["30283","97","0","1"]],"bids":[["30236.1","3","0","1"],["30234.3","0","0","0"],["30223.9","0","0","0"],["30223.8","0","0","0"],["30223.7","0","0","0"],["30223.6","0","0","0"],["30223.5","0","0","0"],["30222.6","0","0","0"],["30220.4","138","0","2"],["30220.3","0","0","0"],["30220.2","4","0","1"],["30220.1","100","0","1"],["30219.6","0","0","0"],["30219.5","0","0","0"],["30219.4","214","0","1"],["30215","0","0","0"],["30204.2","100","0","1"],["30184.2","447","0","1"]],"ts":"1652459228894","checksum":-1678906396}]}
1652459229.023761: {"arg":{"channel":"books","instId":"BTC-USDT"},"action":"update","data":[{"asks":[["30246","0.0013275","0","2"],["30247.4","0.00047854","0","1"],["30247.5","0","0","0"],["30248.7","0","0","0"],["30250.2","0.06523858","0","1"],["30251.3","0","0","0"],["30253.7","0","0","0"],["30644.5","0.00016417","0","1"],["30645.9","0","0","0"]],"bids":[["30245.9","0.041","0","2"],["30245.7","0","0","0"],["30245.6","0","0","0"],["30245.5","0","0","0"],["30244.9","0","0","0"],["30230.9","0.00054788","0","1"],["30230.4","0","0","0"],["30229.1","2.33297","0","2"],["30204.8","3.175","0","1"],["30154.7","1.04752909","0","1"],["30150.8","0.01382373","0","1"],["30044.2","0.00023644","0","1"],["30001","0","0","0"],["30000.5","0","0","0"],["30000.3","0","0","0"],["30000.1","0","0","0"],["30000","0","0","0"]],"ts":"1652459228900","checksum":1313097392}]}
1652459229.0240343: {"arg":{"channel":"books","instId":"UNI-USD-SWAP"},"action":"update","data":[{"asks":[["5.151","0","0","0"],["5.152","85","0","3"]],"bids":[["5.136","291","0","2"]],"ts":"1652459228863","checksum":-1450041411}]}
1652459229.1285007: {"arg":{"channel":"books","instId":"BTC-USD-220527"},"action":"update","data":[{"asks":[["30261.2","31","0","2"],["30267.2","0","0","0"],["30273.6","97","0","1"],["30275","97","0","1"]],"bids":[["30236.2","0","0","0"],["30220.5","4","0","1"],["30220.2","0","0","0"]],"ts":"1652459228995","checksum":-503589553}]}
1652459229.128735: {"arg":{"channel":"books","instId":"BTC-USDT"},"action":"update","data":[{"asks":[["30246","0.0013275","0","2"],["30250.2","0","0","0"],["30250.7","0.01","0","1"],["30253.5","0","0","0"],["30256.4","0","0","0"],["30263.6","0","0","0"],["30263.7","0","0","0"],["30282.8","0","0","0"],["30283.2","0.00798335","0","1"],["30284.9","0.02275718","0","1"],["30644.5","0.00016417","0","1"],["30645.9","0.0003738","0","1"],["30646.6","0.00023887","0","1"],["30650","0.10083281","0","7"],["30650.2","0.00102749","0","1"]],"bids":[["30242.8","0.16","0","1"],["30230.9","0","0","0"],["30204.8","0","0","0"],["30140","0.00003113","0","1"],["30001.1","0.00073738","0","1"],["30001","0.11337186","0","6"],["30000.5","0","0","0"]],"ts":"1652459229014","checksum":1351340957}]}
1652459229.129118: {"arg":{"channel":"books","instId":"UNI-USD-SWAP"},"action":"update","data":[{"asks":[["5.157","88","0","2"]],"bids":[["5.142","97","0","2"],["5.133","107","0","3"],["5.131","331","0","3"]],"ts":"1652459229009","checksum":-372364468}]}
1652459229.1618903: {"arg":{"channel":"trades","instId":"BTC-USDT"},"data":[{"instId":"BTC-USDT","tradeId":"338476330","px":"30246","sz":"0.0002","side":"buy","ts":"1652459229038"}]}
1652459229.1620386: {"arg":{"channel":"trades","instId":"BTC-USDT"},"data":[{"instId":"BTC-USDT","tradeId":"338476331","px":"30246","sz":"0.0011275","side":"buy","ts":"1652459229038"}]}
1652459229.162124: {"arg":{"channel":"trades","instId":"BTC-USDT"},"data":[{"instId":"BTC-USDT","tradeId":"338476332","px":"30246","sz":"0.0028525","side":"buy","ts":"1652459229038"}]}
1652459229.1961296: {"arg":{"channel":"trades","instId":"BTC-USDT"},"data":[{"instId":"BTC-USDT","tradeId":"338476333","px":"30247.4","sz":"0.0004","side":"buy","ts":"1652459229080"}]}
1652459229.2392883: {"arg":{"channel":"books","instId":"BTC-USDT"},"action":"update","data":[{"asks":[["30246","0","0","0"],["30247.4","0.00107854","0","2"],["30251.7","0","0","0"],["30252.2","0","0","0"],["30254.4","0","0","0"],["30255.9","0.0132","0","1"],["30258.1","0","0","0"],["30259.8","0","0","0"],["30260","0.16","0","1"],["30266.8","0","0","0"],["30266.9","0","0","0"],["30272.6","0.05035243","0","2"],["30272.7","0.07940324","0","2"],["30274","0","0","0"],["30275.9","0.06","0","1"],["30276.4","0.24","0","2"],["30279.3","0","0","0"],["30287.4","0.00981128","0","1"],["30297","0.16","0","1"],["30302.4","0","0","0"],["30650","0.10083281","0","7"],["30650.2","0","0","0"],["30650.3","0","0","0"]],"bids":[["30247.3","0.23185135","0","5"],["30246.8","0","0","0"],["30246.1","0","0","0"],["30246","0","0","0"],["30245.9","0.106199","0","2"],["30245","0.0002","0","1"],["30243","0","0","0"],["30242.8","0.32151652","0","3"],["30242","0","0","0"],["30235.5","0","0","0"],["30232.9","0.1","0","1"],["30230.9","0","0","0"],["30228.1","0.09661673","0","2"],["30228","0","0","0"],["30226.9","0","0","0"],["30226.8","0","0","0"],["30226.7","0.00878509","0","1"],["30225.1","0.38114055","0","2"],["30224","0.06572806","0","2"],["30223.6","0","0","0"],["30222.4","0.16","0","1"],["30219.2","0.13226091","0","1"],["30213.4","0","0","0"],["30213.2","0.48","0","1"],["30213","0.24830785","0","1"],["30212.5","1","0","1"],["30212.2","0.58799999","0","1"],["30207.1","0.05","0","1"],["30206.4","0","0","0"],["30205.3","0","0","0"],["30196.4","0","0","0"],["30196","0.24193166","0","4"],["30193.6","0","0","0"],["30188.9","0","0","0"],["30143.9","0","0","0"],["30001.3","0.00004758","0","1"],["30001.1","0.00073738","0","1"],["30001","0.11337186","0","6"],["30000.5","0.00666655","0","1"],["30000.3","0.00029527","0","1"],["30000.1","0.00025519","0","1"],["30000","20.11183989","0","278"]],"ts":"1652459229118","checksum":332600564}]}
1652459229.2400215: {"arg":{"channel":"books","instId":"UNI-USD-SWAP"},"action":"update","data":[{"asks":[["5.148","0","0","0"],["5.149","272","0","3"],["5.152","25","0","2"]],"bids":[["5.142","196","0","3"],["5.14","20","0","1"],["5.134","36","0","1"],["5.133","152","0","4"],["5.132","351","0","3"],["5.131","284","0","2"],["5.129","0","0","0"]],"ts":"1652459229121","checksum":-614255143}]}
1652459229.2402961: {"arg":{"channel":"books","instId":"BTC-USD-220527"},"action":"update","data":[{"asks":[["30244.9","0","0","0"],["30245.4","0","0","0"],["30251.2","0","0","0"],["30254.1","2","0","1"],["30254.2","0","0","0"],["30261.1","0","0","0"],["30261.2","0","0","0"],["30267.1","2","0","1"],["30267.2","4","0","1"],["30268.2","19","0","1"],["30273.6","0","0","0"],["30275","97","0","1"],["30279.4","0","0","0"],["30283","97","0","1"],["30288.7","97","0","1"],["30304.1","0","0","0"]],"bids":[["30243.9","0","0","0"],["30236.2","0","0","0"],["30236.1","0","0","0"],["30220.6","104","0","2"],["30220.5","38","0","1"],["30220.4","100","0","1"],["30215","0","0","0"],["30204.2","0","0","0"],["30184.2","0","0","0"]],"ts":"1652459229110","checksum":617817468}]}
1652459229.267918: {"arg":{"channel":"trades","instId":"BTC-USDT"},"data":[{"instId":"BTC-USDT","tradeId":"338476334","px":"30247.4","sz":"0.00007854","side":"buy","ts":"1652459229151"}]}
1652459229.268039: {"arg":{"channel":"trades","instId":"BTC-USDT"},"data":[{"instId":"BTC-USDT","tradeId":"338476335","px":"30247.4","sz":"0.00099146","side":"buy","ts":"1652459229151"}]}
1652459229.2680914: {"arg":{"channel":"tickers","instId":"BTC-USDT"},"data":[{"instType":"SPOT","instId":"BTC-USDT","last":"30247.4","lastSz":"0.0004","askPx":"30243.5","askSz":"0.00315938","bidPx":"30243.4","bidSz":"0.33732919","open24h":"29700.4","high24h":"31073","low24h":"28020.3","sodUtc0":"29028.8","sodUtc8":"30337.7","volCcy24h":"525803109.33968424","vol24h":"17602.16453512","ts":"1652459229140"}]}
1652459229.3201816: {"arg":{"channel":"trades","instId":"BTC-USDT"},"data":[{"instId":"BTC-USDT","tradeId":"338476336","px":"30247.4","sz":"0.00000854","side":"buy","ts":"1652459229207"}]}
1652459229.3203483: {"arg":{"channel":"trades","instId":"BTC-USDT"},"data":[{"instId":"BTC-USDT","tradeId":"338476337","px":"30248","sz":"0.00019146","side":"buy","ts":"1652459229207"}]}
1652459229.3475158: {"arg":{"channel":"books","instId":"BTC-USD-220527"},"action":"update","data":[{"asks":[["30246","0","0","0"],["30249.5","3","0","1"],["30249.6","0","0","0"],["30254.1","0","0","0"],["30267.1","0","0","0"],["30267.2","0","0","0"],["30267.3","0","0","0"],["30268.1","101","0","2"],["30273.6","0","0","0"],["30273.9","215","0","1"],["30275","0","0","0"],["30277","97","0","1"],["30283","0","0","0"],["30288.7","0","0","0"]],"bids":[["30242.2","0","0","0"],["30241.8","3","0","1"],["30238.7","0","0","0"],["30221","4","0","1"],["30220.9","119","0","2"],["30220.8","0","0","0"],["30220.7","137","0","2"],["30220.6","0","0","0"],["30220.5","0","0","0"],["30220.4","0","0","0"],["30215.3","693","0","1"],["30215.2","0","0","0"],["30215.1","0","0","0"],["30215","100","0","1"],["30204.3","0","0","0"],["30204.2","100","0","1"],["30189.5","455","0","1"]],"ts":"1652459229228","checksum":1725331760}]}
1652459229.3478456: {"arg":{"channel":"books","instId":"BTC-USDT"},"action":"update","data":[{"asks":[["30247.4","0","0","0"],["30248","0","0","0"],["30249.9","0.0002","0","1"],["30255.2","0","0","0"],["30256.4","0","0","0"],["30257","0","0","0"],["30260","0","0","0"],["30260.4","0.16","0","1"],["30263.5","0","0","0"],["30264.4","0.03306","0","1"],["30264.5","0","0","0"],["30267","2.256","0","1"],["30270.9","0","0","0"],["30303.4","0.00007973","0","1"],["30323.8","0","0","0"],["30333.7","0.08255","0","1"],["30367.9","0","0","0"],["30382.4","0.0471802","0","1"],["30646.6","0.00023887","0","1"],["30650","0.10083281","0","7"],["30650.2","0.00102749","0","1"]],"bids":[["30247.9","0.12905061","0","3"],["30247.4","0.03202513","0","1"],["30247.3","0.71912135","0","6"],["30246.9","0.0002","0","1"],["30245.9","0.0884","0","1"],["30245","0","0","0"],["30242.8","0.32151652","0","3"],["30241.5","0.07182924","0","1"],["30237.7","0","0","0"],["30237.1","0.03","0","1"],["30233.1","2.338","0","1"],["30231.4","0.15","0","2"],["30231.1","0.01643806","0","1"],["30230.8","0.31","0","2"],["30229.3","0.01460008","0","2"],["30229.1","2.312","0","1"],["30229","0.03002544","0","2"],["30228.8","0.02097","0","1"],["30228.1","0","0","0"],["30226.8","0.1655291","0","1"],["30224.3","0","0","0"],["30224","0.04929","0","1"],["30218.8","0","0","0"],["30214.7","0","0","0"],["30200.1","0","0","0"],["30194.6","0.01377648","0","3"],["30144","0.01885778","0","1"],["30000.5","0.00666655","0","1"],["30000.3","0","0","0"],["30000.1","0","0","0"],["30000","0","0","0"]],"ts":"1652459229233","checksum":-858033022}]}
1652459229.3481781: {"arg":{"channel":"books","instId":"UNI-USD-SWAP"},"action":"update","data":[{"asks":[["5.152","87","0","3"],["5.153","277","0","2"],["5.154","1874","0","2"],["5.156","265","0","3"]],"bids":[["5.134","78","0","2"],["5.133","110","0","3"],["5.132","351","0","3"]],"ts":"1652459229226","checksum":-1778014846}]}
1652459229.4039402: {"arg":{"channel":"trades","instId":"BTC-USDT"},"data":[{"instId":"BTC-USDT","tradeId":"338476338","px":"30249.9","sz":"0.0002","side":"buy","ts":"1652459229279"}]}
1652459229.4207125: {"arg":{"channel":"tickers","instId":"BTC-USDT"},"data":[{"instType":"SPOT","instId":"BTC-USDT","last":"30248","lastSz":"0.00019146","askPx":"30243.5","askSz":"0.00315938","bidPx":"30243.4","bidSz":"0.33732919","open24h":"29700.4","high24h":"31073","low24h":"28020.3","sodUtc0":"29028.8","sodUtc8":"30337.7","volCcy24h":"525803147.75399712","vol24h":"17602.16580512","ts":"1652459229267"}]}
1652459229.4208493: {"arg":{"channel":"trades","instId":"BTC-USDT"},"data":[{"instId":"BTC-USDT","tradeId":"338476339","px":"30250.7","sz":"0.01","side":"buy","ts":"1652459229308"}]}
1652459229.4599485: {"arg":{"channel":"books","instId":"BTC-USD-220527"},"action":"update","data":[{"asks":[["30249.5","0","0","0"],["30255","0","0","0"],["30256.9","2","0","1"],["30257","0","0","0"],["30268.1","101","0","2"],["30268.2","19","0","1"],["30273.5","0","0","0"],["30273.6","97","0","1"],["30274","172","0","1"],["30275","97","0","1"],["30277","97","0","1"],["30283","97","0","1"],["30288.7","0","0","0"],["30304.1","0","0","0"],["31149.3","0","0","0"],["31157.3","6","0","1"]],"bids":[["30247.6","0","0","0"],["30243","3","0","1"],["30242","0","0","0"],["30241.8","0","0","0"],["30225.2","65","0","1"],["30225.1","4","0","1"],["30225","0","0","0"],["30224.9","100","0","1"],["30224.8","1695","0","1"],["30221","0","0","0"],["30220.9","38","0","1"],["30220.7","0","0","0"],["30220.1","0","0","0"],["30219.4","0","0","0"],["30215.5","0","0","0"],["30215.4","0","0","0"],["30215.3","0","0","0"],["30215","705","0","1"],["30204.2","0","0","0"],["30198.7","11","0","1"],["30192.4","0","0","0"],["30066.1","520","0","2"],["30047.1","0","0","0"],["30005.6","510","0","1"],["29986.7","0","0","0"],["29945.1","503","0","1"],["29926.2","0","0","0"]],"ts":"1652459229341","checksum":-1866658742}]}
1652459229.4603007: {"arg":{"channel":"books","instId":"BTC-USDT"},"action":"update","data":[{"asks":[["30249.9","0","0","0"],["30250.7","0","0","0"],["30255.9","0","0","0"],["30256.9","0","0","0"],["30258.3","0","0","0"],["30259.5","0.06523858","0","1"],["30259.6","0","0","0"],["30260.4","0","0","0"],["30263.3","0","0","0"],["30266.4","0","0","0"],["30272.5","0","0","0"],["30272.7","0.04940324","0","1"],["30275","0","0","0"],["30275.2","0","0","0"],["30275.9","0","0","0"],["30276.4","0.03","0","1"],["30277","0","0","0"],["30277.1","0","0","0"],["30279.7","0.06","0","1"],["30280.3","0.09","0","1"],["30281.7","0.15","0","1"],["30284.6","0","0","0"],["30284.9","0.883","0","1"],["30287.4","0","0","0"],["30291.7","0.0088634","0","1"],["30292.2","0.13000236","0","1"],["30294","0","0","0"],["30296","2.51015","0","2"],["30297","0.22613757","0","2"],["30300","0.65716295","0","4"],["30305.6","0","0","0"],["30312","0.23306066","0","2"],["30325.3","2.31208898","0","1"],["30325.7","0.08255","0","1"],["30333.7","0","0","0"],["30617.7","0","0","0"],["30620.7","1.9594588","0","1"],["30650.3","0.00230626","0","1"],["30651","0.00007125","0","1"],["30651.4","0.00010958","0","1"],["30652.2","0.00894205","0","1"],["30653.8","0.0000131","0","1"],["30654.8","0.00044899","0","1"],["30655","0.5312","0","1"],["30655.4","0.000068","0","1"],["30655.5","0.00038243","0","1"]],"bids":[["30251.7","0.23814061","0","4"],["30250.8","0.00151074","0","1"],["30250.7","0.04859","0","1"],["30250.6","0.28738122","0","6"],["30249.9","0","0","0"],["30249.8","0.13699","0","2"],["30248.9","0.0002","0","1"],["30248","0.04859","0","1"],["30247.9","0.6484","0","3"],["30247.4","0.03202513","0","1"],["30247.3","0.513","0","4"],["30246.9","0","0","0"],["30244.2","0.07182449","0","1"],["30241.5","0","0","0"],["30236.8","0","0","0"],["30235.9","0","0","0"],["30234","0.00286171","0","1"],["30233.9","0","0","0"],["30231.5","0.00661673","0","1"],["30230.4","0","0","0"],["30229.3","0.00798335","0","1"],["30223.4","0","0","0"],["30222.8","0","0","0"],["30213.8","0.557","0","1"],["30213.2","0","0","0"],["30209.6","0.00258583","0","1"],["30207.6","0","0","0"],["30203.9","0.18594009","0","2"],["30171.4","0.50003977","0","2"],["30168.1","1.67192005","0","1"],["30158.6","0","0","0"],["30140.9","1.68916642","0","1"],["30131.4","0","0","0"],["30119.9","0.85979679","0","3"],["30113.6","1.66152597","0","1"],["30104.2","0","0","0"],["30004.2","0.00025375","0","1"],["30001.3","0.00004758","0","1"],["30001.1","0.00073738","0","1"],["30001","0","0","0"],["30000.5","0","0","0"]],"ts":"1652459229337","checksum":-1765635342}]}
1652459229.4607947: {"arg":{"channel":"books","instId":"UNI-USD-SWAP"},"action":"update","data":[{"asks":[["5.149","252","0","2"],["5.153","192","0","1"],["5.155","366","0","4"]],"bids":[],"ts":"1652459229288","checksum":-3350281}]}
1652459229.5275373: {"arg":{"channel":"tickers","instId":"BTC-USDT"},"data":[{"instType":"SPOT","instId":"BTC-USDT","last":"30250.7","lastSz":"0.01","askPx":"30247.4","askSz":"0.00000854","bidPx":"30247.3","bidSz":"0.23185135","open24h":"29700.4","high24h":"31073","low24h":"28020.3","sodUtc0":"29028.8","sodUtc8":"30337.7","volCcy24h":"525803456.31097712","vol24h":"17602.17600512","ts":"1652459229410"}]}
1652459229.5710816: {"arg":{"channel":"books","instId":"BTC-USDT"},"action":"update","data":[{"asks":[["30251.8","0.00147612","0","2"],["30251.9","0.0002","0","1"],["30259.3","0.0132","0","1"],["30259.5","0","0","0"],["30259.9","0.08172539","0","2"],["30261","0","0","0"],["30268","1.035","0","3"],["30287.5","0.00964861","0","1"],["30287.7","0.52536703","0","3"],["30288.6","0","0","0"],["30291.7","0","0","0"],["30295","0.287","0","2"],["30312","0.0677572","0","1"],["30325.7","0","0","0"],["30335.9","0.08255","0","1"],["30655.5","0.00038243","0","1"],["30656.5","0.00031003","0","1"]],"bids":[["30251.7","0.19965135","0","4"],["30250.8","0","0","0"],["30250.7","0","0","0"],["30250.6","0.0884","0","1"],["30249.6","0.0132","0","1"],["30248","0","0","0"],["30247.3","0.4998","0","3"],["30247.2","0.12149853","0","1"],["30242.8","0.28151652","0","2"],["30239.2","0","0","0"],["30235.4","0.33073814","0","1"],["30234.2","0.15","0","1"],["30230.8","0.16","0","1"],["30229","0.04952544","0","3"],["30221.3","0","0","0"],["30219.8","0.037","0","1"],["30219.3","0.16","0","1"],["30215.6","0.48","0","1"],["30213.2","0.58799999","0","1"],["30213.1","0","0","0"],["30212.2","0","0","0"],["30191","0.649","0","1"],["30177.8","0","0","0"],["30001.1","0.00073738","0","1"],["30001","0","0","0"],["30000.5","0","0","0"],["30000.3","0","0","0"]],"ts":"1652459229453","checksum":-1163442897}]}
1652459229.5716472: {"arg":{"channel":"books","instId":"UNI-USD-SWAP"},"action":"update","data":[{"asks":[],"bids":[["5.135","47","0","2"],["5.134","68","0","2"],["5.133","67","0","2"],["5.129","16","0","1"],["5.126","11851","0","1"]],"ts":"1652459229431","checksum":1573501972}]}
1652459229.5717475: {"arg":{"channel":"books","instId":"BTC-USD-220527"},"action":"update","data":[{"asks":[["30251.7","0","0","0"],["30253.8","3","0","1"],["30254.9","0","0","0"],["30268.1","4","0","1"],["30273.5","0","0","0"],["30273.6","0","0","0"],["30274","0","0","0"],["30274.2","172","0","1"],["30275","0","0","0"],["30275.1","0","0","0"],["30275.7","0","0","0"],["30275.8","215","0","1"],["30277","0","0","0"],["30277.1","0","0","0"],["30281.6","40","0","1"],["30283","0","0","0"],["30288.7","0","0","0"],["30288.8","0","0","0"],["30304.1","0","0","0"]],"bids":[["30243.4","0","0","0"],["30243.3","0","0","0"],["30243.1","0","0","0"],["30243","0","0","0"],["30225.5","104","0","2"],["30225.4","65","0","1"],["30225.3","0","0","0"],["30225.2","0","0","0"],["30225.1","0","0","0"],["30225","38","0","1"],["30220.9","0","0","0"],["30215","0","0","0"],["30066.1","19","0","1"],["30043.9","503","0","1"],["30005.6","0","0","0"],["29983.4","507","0","1"],["29945.1","0","0","0"],["29922.9","500","0","1"]],"ts":"1652459229446","checksum":400009252}]}
1652459229.6924582: {"arg":{"channel":"books","instId":"BTC-USD-220527"},"action":"update","data":[{"asks":[["30253.2","3","0","1"],["30253.8","0","0","0"],["30259","3","0","1"],["30273.6","0","0","0"],["30275.7","0","0","0"],["30281.5","0","0","0"],["30283","97","0","1"],["30304.1","97","0","1"]],"bids":[["30243.5","3","0","1"],["30225.5","104","0","2"],["30207.4","20","0","1"],["30181.2","0","0","0"],["30062.1","507","0","1"],["30043.9","0","0","0"],["30001.6","507","0","1"],["29983.4","0","0","0"],["29941.1","504","0","1"],["29922.9","0","0","0"]],"ts":"1652459229538","checksum":1522986562}]}
1652459229.6927853: {"arg":{"channel":"books","instId":"BTC-USDT"},"action":"update","data":[{"asks":[["30251.8","0.01147612","0","3"],["30264.1","0.1","0","1"],["30267","0","0","0"],["30291.3","0","0","0"],["30296","0.06","0","1"],["30329","0.08255","0","1"],["30335.9","0","0","0"],["30656.5","0.00031003","0","1"],["30658.9","0.00017552","0","1"]],"bids":[["30251.7","0.11125135","0","3"],["30249.8","0.0884","0","1"],["30244.6","0.05","0","1"],["30239.3","0.16","0","1"],["30226.4","0.06613778","0","1"],["30166.7","0","0","0"],["30001.3","0.00004758","0","1"],["30001.1","0","0","0"]],"ts":"1652459229567","checksum":596704717}]}
1652459229.6930492: {"arg":{"channel":"books","instId":"UNI-USD-SWAP"},"action":"update","data":[{"asks":[],"bids":[["5.134","68","0","2"]],"ts":"1652459229495","checksum":1573501972}]}
1652459229.7898643: {"arg":{"channel":"books","instId":"BTC-USD-220527"},"action":"update","data":[{"asks":[["30247.4","3","0","1"],["30250.7","0","0","0"],["30253.2","0","0","0"],["30268.1","104","0","2"],["30273.6","0","0","0"],["30283","0","0","0"],["30283.1","581","0","2"],["30304.1","0","0","0"]],"bids":[["30244.1","0","0","0"],["30243.5","0","0","0"],["30240.9","0","0","0"],["30240","3","0","1"],["30225.7","4","0","1"],["30225.6","38","0","1"],["30225.5","0","0","0"],["30225","0","0","0"],["30224.9","0","0","0"],["30220.1","0","0","0"]],"ts":"1652459229662","checksum":-1092197047}]}
1652459229.7904475: {"arg":{"channel":"books","instId":"BTC-USDT"},"action":"update","data":[{"asks":[["30258.7","0.06523858","0","1"],["30259.3","0.0132","0","1"],["30259.9","0.01648681","0","1"],["30261.1","0.16","0","1"],["30262.4","0","0","0"],["30264.4","0","0","0"],["30268.9","0.03306","0","1"],["30274.7","0.16550161","0","1"],["30287.5","0","0","0"],["30291.6","0.00919295","0","1"],["30299","3.192","0","1"],["30311.2","0.5","0","1"],["30314.8","2.44922","0","1"],["30348","0.16865237","0","2"],["30620.7","0","0","0"],["30637.7","1.95837155","0","1"],["30655","0","0","0"],["30655.4","0","0","0"],["30655.5","0","0","0"],["30656.5","0","0","0"],["30658.9","0","0","0"]],"bids":[["30247.2","0","0","0"],["30232.9","0.12097","0","2"],["30229.3","0.09053335","0","2"],["30228.8","0","0","0"],["30223.7","0","0","0"],["30170.5","2.44752","0","1"],["30001.3","0.00004758","0","1"],["30001.1","0.00073738","0","1"],["30001","0.11337186","0","6"]],"ts":"1652459229671","checksum":-1991516600}]}
1652459229.791222: {"arg":{"channel":"books","instId":"UNI-USD-SWAP"},"action":"update","data":[{"asks":[],"bids":[["5.134","68","0","2"]],"ts":"1652459229648","checksum":1573501972}]}
1652459229.9018414: {"arg":{"channel":"books","instId":"BTC-USDT"},"action":"update","data":[{"asks":[["30251.8","0.24420612","0","4"],["30258.4","0.06523858","0","1"],["30258.7","0","0","0"],["30259.2","0","0","0"],["30259.3","0","0","0"],["30274.6","2.324","0","1"],["30287.2","2.45852005","0","2"],["30291.6","0","0","0"],["30623","1.95931163","0","1"],["30637.7","0","0","0"],["30654.8","0.00044899","0","1"],["30655","0.5312","0","1"]],"bids":[["30251.7","0.00216135","0","2"],["30250.6","0","0","0"],["30249.8","0","0","0"],["30248.7","0.04","0","1"],["30247.9","0.16","0","1"],["30247.3","0.4114","0","2"],["30001","0.11337186","0","6"],["30000.5","0.00666655","0","1"]],"ts":"1652459229786","checksum":169828269}]}
1652459229.90238: {"arg":{"channel":"books","instId":"UNI-USD-SWAP"},"action":"update","data":[{"asks":[],"bids":[["5.134","77","0","2"],["5.069","0","0","0"]],"ts":"1652459229773","checksum":-1325978424}]}
1652459229.9025369: {"arg":{"channel":"books","instId":"BTC-USD-220527"},"action":"update","data":[{"asks":[["30247.4","0","0","0"],["30247.6","3","0","1"],["30251","0","0","0"],["30256.8","0","0","0"],["30258.9","4","0","1"],["30268","4","0","1"],["30268.1","100","0","1"],["30273.6","0","0","0"],["30274.2","0","0","0"]],"bids":[["30240.2","0","0","0"],["30240","0","0","0"],["30238.8","0","0","0"],["30226","65","0","1"],["30225.9","4","0","1"],["30225.8","0","0","0"],["30225.7","0","0","0"],["30225.4","0","0","0"],["30224.8","0","0","0"],["30220.2","760","0","1"],["30220.1","0","0","0"],["30209.9","330","0","1"]],"ts":"1652459229785","checksum":-817702355}]}
1652459230.0124252: {"arg":{"channel":"books","instId":"BTC-USD-220527"},"action":"update","data":[{"asks":[["30247.1","0","0","0"],["30247.6","0","0","0"],["30250.2","3","0","1"],["30256.8","4","0","1"],["30258.9","0","0","0"],["30267.9","100","0","1"],["30268","0","0","0"],["30273.6","100","0","1"]],"bids":[["30240.1","3","0","1"],["30236.3","0","0","0"],["30226.1","4","0","1"],["30226","0","0","0"],["30225.9","0","0","0"],["30225.6","214","0","1"],["30224.9","38","0","1"],["30224.8","0","0","0"],["30223","0","0","0"],["30220.2","0","0","0"],["30209.9","57","0","1"],["30207.5","0","0","0"],["30204.2","57","0","1"],["30189.5","0","0","0"]],"ts":"1652459229860","checksum":1938068290}]}
1652459230.0130904: {"arg":{"channel":"books","instId":"BTC-USDT"},"action":"update","data":[{"asks":[["30256","0.0132","0","1"],["30256.3","0.06523858","0","1"],["30256.6","0.09999997","0","1"],["30256.8","0","0","0"],["30258.4","0","0","0"],["30268.8","0.02470432","0","1"],["30269.7","0.0094549","0","2"],["30269.8","5.87703968","0","1"],["30272.5","0","0","0"],["30283.2","0","0","0"],["30651.4","0.00010958","0","1"],["30652.2","0","0","0"],["30653.8","0","0","0"],["30654.8","0","0","0"],["30655","0","0","0"]],"bids":[["30251.7","0.00151074","0","1"],["30249.6","0","0","0"],["30247.9","0","0","0"],["30247.4","0","0","0"],["30247.3","0","0","0"],["30247","0.0132","0","1"],["30233.1","0","0","0"],["30231.1","0","0","0"],["30229.1","0","0","0"],["30229","0.03002544","0","2"],["30228","0","0","0"],["30224.8","0.01643806","0","1"],["30000.3","0.00029527","0","1"],["30000.1","0.00025519","0","1"],["30000","20.11183989","0","278"],["29999.9","0.08774465","0","23"],["29999.7","0.00276686","0","3"]],"ts":"1652459229887","checksum":1747783888}]}
1652459230.0144014: {"arg":{"channel":"books","instId":"UNI-USD-SWAP"},"action":"update","data":[{"asks":[],"bids":[["5.075","240","0","1"]],"ts":"1652459229795","checksum":-1325978424}]}
1652459230.1247194: {"arg":{"channel":"books","instId":"BTC-USD-220527"},"action":"update","data":[{"asks":[["30249.5","2","0","1"],["30249.6","3","0","1"],["30250.2","0","0","0"],["30273.6","0","0","0"],["30275.8","0","0","0"],["30283.1","461","0","1"],["30308","120","0","1"]],"bids":[["30241","0","0","0"],["30240.1","0","0","0"],["30226.2","137","0","2"],["30226.1","0","0","0"],["30225.7","4","0","1"],["30223.8","0","0","0"],["30215","0","0","0"],["30209.9","57","0","1"],["30207.5","0","0","0"],["30204.2","57","0","1"],["30187.4","0","0","0"]],"ts":"1652459229997","checksum":102994918}]}
1652459230.1250672: {"arg":{"channel":"books","instId":"BTC-USDT"},"action":"update","data":[{"asks":[["30254.1","0","0","0"],["30256.3","0.06523858","0","1"],["30256.6","0","0","0"],["30269.8","0","0","0"],["30277.7","0.15","0","1"],["30281.7","0","0","0"],["30652.2","0.00894205","0","1"],["30653.8","0.0000131","0","1"]],"bids":[["30245.9","0","0","0"],["30244.2","0","0","0"],["30237.9","0.000824","0","1"],["30237.1","0","0","0"],["30236.2","0.07182388","0","1"],["30234.2","0","0","0"],["30233.9","0.03","0","1"],["30233.2","0","0","0"],["30233.1","0.025","0","1"],["30232.8","0","0","0"],["30232.4","0","0","0"],["30232.3","2.25","0","1"],["30229","0.02920144","0","1"],["30224.8","0","0","0"],["30223.2","0.01643806","0","1"],["30222.5","0","0","0"],["30214.2","0.0188","0","1"],["30208","3.04995727","0","2"],["30000","20.11183989","0","278"],["29999.9","0.08774465","0","23"],["29999.7","0.00276686","0","3"]],"ts":"1652459230011","checksum":960615335}]}
1652459230.2413893: {"arg":{"channel":"books","instId":"BTC-USD-220527"},"action":"update","data":[{"asks":[["30245","0","0","0"],["30247.6","2","0","1"],["30247.7","0","0","0"],["30249.6","0","0","0"],["30256.9","0","0","0"],["30276.1","20","0","1"]],"bids":[["30238.7","0","0","0"],["30237.4","3","0","1"],["30226.3","4","0","1"],["30226.2","65","0","1"],["30225.7","0","0","0"],["30225","0","0","0"],["30224.9","0","0","0"],["30209.9","0","0","0"],["30207.5","0","0","0"],["30207.4","0","0","0"],["30204.2","57","0","1"],["30193.5","0","0","0"]],"ts":"1652459230118","checksum":1409164907}]}
1652459230.2417378: {"arg":{"channel":"books","instId":"BTC-USDT"},"action":"update","data":[{"asks":[["30251.8","0.33733489","0","5"],["30252.1","0.08204294","0","1"],["30252.8","1.01","0","1"],["30253.2","0","0","0"],["30254.5","0.059","0","1"],["30255.9","2.06","0","1"],["30258","0.16","0","1"],["30260.8","0.04955414","0","1"],["30269.7","0","0","0"],["30271","0.00242278","0","2"],["30271.1","0.2092412","0","3"],["30272.5","0","0","0"],["30272.6","0","0","0"],["30279.9","0.33025208","0","1"],["30280.1","0.1386","0","1"],["30283.2","0.00798335","0","1"],["30286.9","0.037","0","1"],["30287.7","0.1952","0","2"],["30295","0.25","0","1"],["30310.3","0.3475","0","1"],["30340.6","0.5312","0","1"],["30345.5","0","0","0"],["30364","4.62417796","0","1"],["30386","3.3923","0","1"],["30477.5","0","0","0"],["30507.8","0","0","0"],["30612","0","0","0"],["30650","0","0","0"],["30650.2","0","0","0"],["30650.3","0","0","0"],["30651","0","0","0"],["30651.4","0","0","0"],["30652.2","0","0","0"],["30653.8","0","0","0"]],"bids":[["30242.8","0.16","0","1"],["30239.4","0.12152987","0","1"],["30237.9","0","0","0"],["30235.5","0.1386","0","1"],["30235.4","0","0","0"],["30235.1","0","0","0"],["30231.1","0.15","0","1"],["30228.6","0.33081254","0","1"],["30225.1","0.05028971","0","1"],["30223.2","0","0","0"],["30218.2","0.01643806","0","1"],["30218.1","0","0","0"],["30215.6","0","0","0"],["30213.2","0","0","0"],["30212.5","0","0","0"],["30207.9","0.48","0","1"],["30206.9","0.58799999","0","1"],["30205.1","1","0","1"],["30204.8","0.3475","0","1"],["30203.9","0.02066559","0","1"],["30174.6","0.5312","0","1"],["30143.9","0.16530182","0","1"],["30129.1","3.5347","0","1"],["30119.9","0.52924778","0","2"],["30000.5","0","0","0"],["30000.3","0","0","0"],["30000.1","0","0","0"],["30000","0","0","0"],["29999.9","0","0","0"],["29999.7","0","0","0"],["29999.6","0","0","0"]],"ts":"1652459230103","checksum":560411934}]}
1652459230.242319: {"arg":{"channel":"books","instId":"UNI-USD-SWAP"},"action":"update","data":[{"asks":[["5.159","294","0","3"]],"bids":[["5.135","5","0","1"],["5.134","119","0","3"]],"ts":"1652459230091","checksum":-1865567379}]}
1652459230.34852: {"arg":{"channel":"books","instId":"BTC-USD-220527"},"action":"update","data":[{"asks":[["30243.6","0","0","0"],["30245.7","3","0","1"],["30247.1","2","0","1"],["30247.2","0","0","0"],["30249.5","0","0","0"],["30267.1","100","0","1"],["30267.2","0","0","0"],["30276.7","40","0","1"],["30281.6","0","0","0"],["30283.1","0","0","0"]],"bids":[["30239.9","0","0","0"],["30237.4","0","0","0"],["30236.9","3","0","1"],["30226.4","65","0","1"],["30226.3","0","0","0"],["30226.2","0","0","0"],["30225.7","4","0","1"],["30221.6","0","0","0"],["30204.2","57","0","1"],["30179.4","446","0","1"]],"ts":"1652459230223","checksum":1280085381}]}
1652459230.3486588: {"arg":{"channel":"books","instId":"BTC-USDT"},"action":"update","data":[{"asks":[["30251.8","1.40733489","0","6"],["30254.5","0","0","0"],["30254.9","0.16","0","1"],["30255.9","0","0","0"],["30267.8","0.00049068","0","1"],["30270.9","0.00360485","0","1"],["30271","0.00034593","0","1"],["30271.1","0.20262447","0","2"],["30271.5","0.18","0","3"],["30274.6","0","0","0"],["30276.4","0","0","0"],["30277","0","0","0"],["30277.9","0.05000223","0","1"],["30279.7","0","0","0"],["30280.3","0","0","0"],["30292.2","0","0","0"],["30299","0","0","0"],["30540.1","1.96463011","0","1"],["30623","0","0","0"],["30650","0.10083281","0","7"],["30650.2","0.00102749","0","1"],["30650.3","0.00230626","0","1"],["30651","0","0","0"],["30651.4","0","0","0"]],"bids":[["30248.7","0","0","0"],["30247","0","0","0"],["30245.2","0.01","0","1"],["30245","0.01","0","1"],["30244","0.01","0","1"],["30243.4","0.05452","0","1"],["30243","0.01","0","1"],["30242.8","0","0","0"],["30242.5","0.8632","0","2"],["30240.5","0","0","0"],["30223.2","0","0","0"],["30218.2","0.01643806","0","1"],["30214.2","0","0","0"],["30213.4","0","0","0"],["30208","0.04395727","0","1"],["30207.1","0","0","0"],["30000.5","0.00666655","0","1"],["30000.3","0","0","0"],["30000.1","0","0","0"],["30000","0","0","0"],["29999.9","0","0","0"]],"ts":"1652459230230","checksum":-1364881802}]}
1652459230.3488107: {"arg":{"channel":"books","instId":"UNI-USD-SWAP"},"action":"update","data":[{"asks":[["5.149","272","0","3"]],"bids":[["5.134","36","0","1"],["5.132","393","0","4"]],"ts":"1652459230219","checksum":-2076759326}]}
1652459230.457515: {"arg":{"channel":"books","instId":"BTC-USD-220527"},"action":"update","data":[{"asks":[["30241.7","0","0","0"],["30244.1","3","0","1"],["30245.7","0","0","0"]],"bids":[["30236.9","0","0","0"],["30236","0","0","0"],["30234.3","0","0","0"],["30226.6","0","0","0"],["30226.5","0","0","0"],["30226.4","0","0","0"],["30225.7","4","0","1"],["30204.2","57","0","1"]],"ts":"1652459230338","checksum":1621926680}]}
1652459230.457814: {"arg":{"channel":"books","instId":"BTC-USDT"},"action":"update","data":[{"asks":[["30270.9","0","0","0"],["30271","0.04958713","0","3"],["30271.1","0.16","0","1"],["30282.7","0.00663061","0","1"],["30285.2","0","0","0"],["30287.2","2.44996","0","1"],["30298.1","3.243","0","1"],["30540.1","0","0","0"],["30623","1.95931163","0","1"],["30650.3","0","0","0"]],"bids":[["30242.4","0","0","0"],["30232.3","2.250824","0","2"],["30226.7","0","0","0"],["30226.4","0","0","0"],["30224.9","0.3135993","0","2"],["30224.2","2.303","0","1"],["30222","0.0077937","0","1"],["30219.9","0","0","0"],["30218.2","0.01643806","0","1"],["30150.8","0","0","0"],["30000.3","0.00029527","0","1"]],"ts":"1652459230334","checksum":-1303146580}]}
1652459230.5784817: {"arg":{"channel":"books","instId":"BTC-USDT"},"action":"update","data":[{"asks":[["30273.8","2.213","0","1"],["30297","0.16","0","1"],["30312","0","0","0"],["30650.2","0.00102749","0","1"]],"bids":[["30244.6","0","0","0"],["30243.4","0","0","0"],["30238.3","0","0","0"],["30224.9","0.24745648","0","1"],["30219.8","0","0","0"],["30218.2","0","0","0"],["30218","0.01643806","0","1"],["30217.9","0","0","0"],["30210.5","2.31347215","0","2"],["30206.3","0","0","0"],["30000.1","0.00025519","0","1"],["30000","20.11183989","0","278"],["29999.9","0.4183483","0","24"],["29999.7","0.00276686","0","3"]],"ts":"1652459230449","checksum":-1604199913}]}
1652459230.5789542: {"arg":{"channel":"books","instId":"BTC-USD-220527"},"action":"update","data":[{"asks":[["30242.8","0","0","0"],["30244","3","0","1"],["30244.1","0","0","0"],["30255.4","30","0","1"],["30256.6","100","0","1"],["30256.7","0","0","0"],["30258.8","100","0","1"],["30258.9","24","0","1"],["30267.1","0","0","0"],["30267.9","0","0","0"],["30268.1","0","0","0"],["30268.2","0","0","0"],["30273.6","100","0","1"],["30283.9","469","0","1"],["30304.2","0","0","0"]],"bids":[["30234.4","0","0","0"],["30234.3","0","0","0"],["30226.8","0","0","0"],["30226.7","0","0","0"],["30225.7","0","0","0"],["30225.6","0","0","0"],["30220.1","4","0","1"],["30220","385","0","2"],["30209.9","0","0","0"],["30204.2","0","0","0"]],"ts":"1652459230452","checksum":1515944499}]}
1652459230.5792654: {"arg":{"channel":"books","instId":"UNI-USD-SWAP"},"action":"update","data":[{"asks":[],"bids":[["5.135","47","0","2"],["5.132","351","0","3"]],"ts":"1652459230372","checksum":-985747528}]}
1652459230.5857844: {"arg":{"channel":"trades","instId":"BTC-USDT"},"data":[{"instId":"BTC-USDT","tradeId":"338476340","px":"30251.7","sz":"0.00151","side":"sell","ts":"1652459230471"}]}
1652459230.6607094: {"arg":{"channel":"trades","instId":"BTC-USDT"},"data":[{"instId":"BTC-USDT","tradeId":"338476341","px":"30251.7","sz":"0.00000074","side":"sell","ts":"1652459230547"}]}
1652459230.6607947: {"arg":{"channel":"trades","instId":"BTC-USDT"},"data":[{"instId":"BTC-USDT","tradeId":"338476342","px":"30248.9","sz":"0.00019926","side":"sell","ts":"1652459230547"}]}
1652459230.6707811: {"arg":{"channel":"tickers","instId":"BTC-USDT"},"data":[{"instType":"SPOT","instId":"BTC-USDT","last":"30251.7","lastSz":"0.00000074","askPx":"30247.4","askSz":"0.00000854","bidPx":"30247.3","bidSz":"0.23185135","open24h":"29700.4","high24h":"31073","low24h":"28020.3","sodUtc0":"29028.8","sodUtc8":"30337.7","volCcy24h":"525803502.01343038","vol24h":"17602.17751586","ts":"1652459230554"}]}
1652459230.6738276: {"arg":{"channel":"trades","instId":"BTC-USDT"},"data":[{"instId":"BTC-USDT","tradeId":"338476343","px":"30248.9","sz":"0.00000074","side":"sell","ts":"1652459230560"}]}
1652459230.6764572: {"arg":{"channel":"books","instId":"BTC-USD-220527"},"action":"update","data":[{"asks":[["30236.1","3","0","1"],["30238.5","0","0","0"],["30243.8","4","0","1"],["30243.9","2","0","1"],["30244","0","0","0"],["30247","0","0","0"],["30247.6","0","0","0"],["30255.3","100","0","1"],["30256.8","0","0","0"],["30258.8","0","0","0"],["30258.9","0","0","0"],["30273.6","0","0","0"],["30283.9","0","0","0"],["30288.9","19","0","1"]],"bids":[["30231.2","0","0","0"],["30229.6","0","0","0"],["30229.5","0","0","0"],["30227.6","3","0","1"],["30220.4","4","0","1"],["30220.3","72","0","1"],["30220.2","65","0","1"],["30220.1","0","0","0"],["30219.6","214","0","1"],["30214.9","0","0","0"],["30209.9","0","0","0"],["30207.9","15","0","1"],["30198.7","0","0","0"],["30192.4","11","0","1"]],"ts":"1652459230567","checksum":-908549672}]}
1652459230.6767738: {"arg":{"channel":"books","instId":"BTC-USDT"},"action":"update","data":[{"asks":[["30249","1.24082","0","3"],["30251.7","0.006","0","1"],["30251.8","6.0146271","0","15"],["30252.6","0.0132","0","1"],["30252.7","2.04","0","1"],["30254.8","0","0","0"],["30255.5","0.06523858","0","1"],["30256","0","0","0"],["30256.3","0","0","0"],["30259.9","0","0","0"],["30261.1","0.795","0","2"],["30264.9","0.00983441","0","2"],["30265","5.64449544","0","1"],["30267.8","0.0492412","0","2"],["30268","0.4","0","2"],["30271","0.00034593","0","1"],["30271.5","0.33","0","4"],["30277.7","0","0","0"],["30279.9","0","0","0"],["30283.2","0","0","0"],["30287.4","0.3301703","0","1"],["30294","0.06614522","0","1"],["30298.1","0","0","0"],["30300","0.71673677","0","5"],["30322.5","0.08255","0","1"],["30329","0","0","0"],["30650","0","0","0"],["30650.2","0","0","0"]],"bids":[["30251.7","0","0","0"],["30248.9","0","0","0"],["30245.2","0","0","0"],["30245","0","0","0"],["30244","0","0","0"],["30243","0","0","0"],["30242.5","0","0","0"],["30239.3","0","0","0"],["30233.9","0","0","0"],["30232.9","0.02097","0","1"],["30231.5","0","0","0"],["30231.4","0","0","0"],["30231.1","0","0","0"],["30229.3","0.03798335","0","2"],["30228.1","0.15","0","2"],["30227.4","0.15","0","1"],["30223.6","0.08255","0","1"],["30223.4","0.06614544","0","1"],["30222.5","0.00661673","0","1"],["30218.3","0","0","0"],["30218","0","0","0"],["30217.9","0.01643806","0","1"],["30213","0.28530785","0","2"],["30196","0.00193166","0","3"],["30188.8","0.24","0","1"],["30148","0.01382501","0","1"],["29999.6","0.04507001","0","1"],["29999.4","0.00270878","0","1"],["29999","0.01500049","0","2"],["29998","0.00400028","0","1"],["29996.6","0.00166685","0","1"]],"ts":"1652459230563","checksum":1481517384}]}
1652459230.677256: {"arg":{"channel":"books","instId":"UNI-USD-SWAP"},"action":"update","data":[{"asks":[],"bids":[["5.142","77","0","1"],["5.135","5","0","1"],["5.134","36","0","1"],["5.132","393","0","4"]],"ts":"1652459230563","checksum":-1915435340}]}
1652459230.7805812: {"arg":{"channel":"tickers","instId":"BTC-USDT"},"data":[{"instType":"SPOT","instId":"BTC-USDT","last":"30248.9","lastSz":"0.00000074","askPx":"30247.4","askSz":"0.00000854","bidPx":"30247.3","bidSz":"0.23185135","open24h":"29700.4","high24h":"31073","low24h":"28020.3","sodUtc0":"29028.8","sodUtc8":"30337.7","volCcy24h":"525803508.06321038","vol24h":"17602.17771586","ts":"1652459230658"}]}
1652459230.7892504: {"arg":{"channel":"books","instId":"BTC-USD-220527"},"action":"update","data":[{"asks":[["30243.8","0","0","0"],["30247","0","0","0"],["30255.2","24","0","1"],["30256.5","4","0","1"],["30264.2","100","0","1"],["30264.3","40","0","1"],["30273.6","0","0","0"],["30273.7","0","0","0"],["30276.7","0","0","0"],["31147.6","5","0","1"],["31157.3","0","0","0"]],"bids":[["30227.6","3","0","1"],["30220.4","0","0","0"],["30220.3","0","0","0"],["30219.6","0","0","0"],["30218.9","0","0","0"],["30209.9","4","0","1"],["30194","0","0","0"],["30193.9","0","0","0"],["30186.7","39","0","1"],["30181.2","0","0","0"],["30062.1","0","0","0"],["30038.9","502","0","1"],["30001.6","0","0","0"],["29978.4","505","0","1"],["29941.1","0","0","0"],["29918","504","0","1"],["29340.1","0","0","0"],["29333.1","5","0","1"]],"ts":"1652459230669","checksum":172567265}]}
1652459230.7894723: {"arg":{"channel":"books","instId":"BTC-USDT"},"action":"update","data":[{"asks":[["30240.4","0.23373","0","2"],["30242.6","0.04859","0","1"],["30247.3","0.06523858","0","1"],["30248.9","0.00798335","0","1"],["30249","0.07829681","0","4"],["30249.9","0.0002","0","1"],["30250.2","0.23273","0","1"],["30250.9","0","0","0"],["30251.7","0.01","0","1"],["30251.8","0.78420489","0","7"],["30251.9","0","0","0"],["30252.1","0","0","0"],["30252.6","0","0","0"],["30252.7","0","0","0"],["30252.8","0.01","0","1"],["30253","0.01","0","1"],["30255.1","0.0273","0","1"],["30255.5","0","0","0"],["30257.5","0.03306","0","1"],["30261","0.0492412","0","2"],["30264","0.00319773","0","1"],["30264.1","0.1","0","1"],["30264.9","0.00798335","0","1"],["30267.8","0","0","0"],["30268.9","0","0","0"],["30269.7","0","0","0"],["30271.4","0","0","0"],["30273.4","0.33032298","0","1"],["30275.7","0.00256353","0","1"],["30277.6","0.00830854","0","1"],["30282.7","0","0","0"],["30289.2","0.02148131","0","1"],["30641.6","0","0","0"],["30642.3","0","0","0"],["30642.8","0","0","0"],["30643.5","0","0","0"],["30644.5","0","0","0"],["30645.9","0","0","0"],["30646.6","0","0","0"],["30650","0","0","0"],["30650.2","0","0","0"]],"bids":[["30240.3","0.00125752","0","2"],["30239.4","0","0","0"],["30238","0.01","0","1"],["30237.7","0","0","0"],["30236.6","0.05452","0","1"],["30236.2","0.0132","0","1"],["30235.4","0.12154594","0","1"],["30232.9","0","0","0"],["30232.1","0.07183779","0","1"],["30229","0","0","0"],["30228.6","0","0","0"],["30228.1","0","0","0"],["30227.4","0","0","0"],["30224.8","0.06","0","1"],["30224.4","0.09","0","1"],["30224.3","0.02027005","0","1"],["30224","0.19929","0","2"],["30222.5","0","0","0"],["30222.3","0.3308815","0","1"],["30222","0","0","0"],["30221.3","0.02097","0","1"],["30217.9","0","0","0"],["30216.1","0.00887193","0","1"],["30215.8","0.01643806","0","1"],["30215.4","0.33095706","0","1"],["30209.6","0","0","0"],["30205.1","0","0","0"],["30201.7","0.00004205","0","1"],["30198.7","1","0","1"],["30168.1","0","0","0"],["30158.6","1.66723722","0","1"],["30140.9","0","0","0"],["30131.4","1.68423567","0","1"],["30113.6","0","0","0"],["30104.2","1.68635424","0","1"],["29998","0","0","0"],["29996.6","0","0","0"],["29995.7","0","0","0"],["29995","0","0","0"],["29994.2","0","0","0"]],"ts":"1652459230678","checksum":-345789302}]}
1652459230.78982: {"arg":{"channel":"books","instId":"UNI-USD-SWAP"},"action":"update","data":[{"asks":[["5.159","321","0","3"]],"bids":[["5.14","119","0","2"],["5.134","132","0","2"],["5.132","351","0","3"],["5.131","230","0","2"]],"ts":"1652459230593","checksum":-337619542}]}
1652459230.903024: {"arg":{"channel":"books","instId":"BTC-USD-220527"},"action":"update","data":[{"asks":[["30235.7","3","0","1"],["30236","0","0","0"],["30236.1","0","0","0"],["30237.5","2","0","1"],["30237.6","0","0","0"],["30243.8","0","0","0"],["30247.1","0","0","0"],["30255.1","104","0","2"],["30256.5","0","0","0"],["30264.2","0","0","0"],["30265.7","11","0","1"],["30277.9","454","0","1"],["30604.6","202","0","1"],["30606.9","0","0","0"]],"bids":[["30227.7","0","0","0"],["30227.6","0","0","0"],["30226.9","0","0","0"],["30220.2","0","0","0"],["30220.1","69","0","2"],["30220","214","0","1"],["30209.9","0","0","0"],["30192.4","0","0","0"],["30133.3","0","0","0"],["30130.4","81","0","1"],["30109.9","0","0","0"],["30066.2","202","0","1"],["29972.8","0","0","0"],["29940.7","1563","0","2"],["29835.7","0","0","0"],["29833.4","202","0","1"]],"ts":"1652459230787","checksum":-1348557354}]}
1652459230.9033403: {"arg":{"channel":"books","instId":"BTC-USDT"},"action":"update","data":[{"asks":[["30244.2","0.06523858","0","1"],["30245.8","0","0","0"],["30246.6","0.16","0","1"],["30247.3","0","0","0"],["30248.9","0","0","0"],["30251.8","0.72520489","0","6"],["30255.8","0.635","0","1"],["30260.9","0.00064361","0","1"],["30261.1","0.16","0","1"],["30262.5","0.16557034","0","1"],["30264","0","0","0"],["30264.1","0","0","0"],["30267.7","2.227","0","1"],["30274.7","0","0","0"],["30294","0","0","0"],["30322.5","0","0","0"],["30326.9","0","0","0"],["30330.8","0.08255","0","1"],["30641.6","0.00065466","0","1"],["30642.3","0","0","0"]],"bids":[["30236.6","0","0","0"],["30236.5","0.04959563","0","1"],["30235.5","0","0","0"],["30235.1","0","0","0"],["30234.1","0","0","0"],["30232.3","0.000824","0","1"],["30232.1","0","0","0"],["30230.3","0","0","0"],["30229.5","0.1386","0","1"],["30229.3","0.00798335","0","1"],["30229","0.07183779","0","1"],["30225.6","0","0","0"],["30224.8","0","0","0"],["30224.4","0.03","0","1"],["30224","0.04929","0","1"],["30223.4","0","0","0"],["30219.2","0","0","0"],["30219","0.3","0","3"],["30218.9","0.06615682","0","1"],["30217.6","0","0","0"],["30216","0.00661673","0","1"],["30215.9","0","0","0"],["30213.8","0","0","0"],["30211.8","0.05000008","0","1"],["30208.4","0.08","0","1"],["30205.2","0.55838968","0","2"],["30203.9","0.08888173","0","2"],["30191","0","0","0"],["30178.6","0.649","0","1"],["29998","0.00400028","0","1"],["29996.6","0.00166685","0","1"],["29995.7","0.00087403","0","1"],["29995","0.0284951","0","1"],["29994.2","0.00004654","0","1"]],"ts":"1652459230782","checksum":1755447786}]}
1652459230.9036775: {"arg":{"channel":"books","instId":"UNI-USD-SWAP"},"action":"update","data":[{"asks":[["5.149","297","0","4"],["5.152","81","0","3"],["5.154","1910","0","3"],["5.155","330","0","3"],["5.159","316","0","3"]],"bids":[["5.142","0","0","0"],["5.141","77","0","1"],["5.137","214","0","1"],["5.134","98","0","2"],["5.133","204","0","2"],["5.132","400","0","4"],["5.131","188","0","1"],["5.13","0","0","0"],["5.129","58","0","2"]],"ts":"1652459230781","checksum":-1839843805}]}
1652459231.016202: {"arg":{"channel":"books","instId":"BTC-USD-220527"},"action":"update","data":[{"asks":[["30232.7","0","0","0"],["30234","0","0","0"],["30235.7","0","0","0"],["30243.5","4","0","1"],["30243.6","100","0","1"],["30243.7","24","0","1"],["30243.8","0","0","0"],["30255.1","0","0","0"],["30255.2","0","0","0"],["30256.6","0","0","0"],["30261","0","0","0"],["30261.4","0","0","0"],["30261.5","215","0","1"],["30264.2","0","0","0"],["30273.9","0","0","0"]],"bids":[["30225.6","0","0","0"],["30224.7","3","0","1"],["30220.2","65","0","1"],["30220.1","0","0","0"],["30220","0","0","0"],["30212.5","214","0","1"],["30211.9","214","0","1"],["30209.9","4","0","1"],["30204.2","0","0","0"],["30186.4","11","0","1"]],"ts":"1652459230892","checksum":243340204}]}
1652459231.016691: {"arg":{"channel":"books","instId":"BTC-USDT"},"action":"update","data":[{"asks":[["30240.4","1.26373","0","3"],["30240.6","0.08204294","0","1"],["30242.5","1.17","0","1"],["30243.7","0.11319997","0","2"],["30244.2","0","0","0"],["30244.7","0.06523858","0","1"],["30249","0.06509681","0","3"],["30260.9","0","0","0"],["30265.1","0.33","0","4"],["30268.8","0","0","0"],["30271.5","0","0","0"],["30273","1.15712546","0","2"],["30280.3","0.037","0","1"],["30284.9","0","0","0"],["30286.9","0","0","0"],["30302.4","2.31208898","0","1"],["30306","0","0","0"],["30323.9","0.08255","0","1"],["30325.3","0","0","0"],["30326.7","0.4","0","1"],["30330.8","0","0","0"],["30540.1","1.96463011","0","1"],["30623","0","0","0"],["30640","0.97036266","0","9"],["30641.6","0.00065466","0","1"],["30642.3","0","0","0"]],"bids":[["30238","0","0","0"],["30236.3","0.4","0","1"],["30235.7","0","0","0"],["30235.4","0","0","0"],["30234.1","0","0","0"],["30232.3","0","0","0"],["30232.1","0.12155921","0","1"],["30230.8","0.16","0","1"],["30229.3","0.33878823","0","2"],["30229","0","0","0"],["30226.5","0.07183779","0","1"],["30224.4","0","0","0"],["30219.5","0.03","0","1"],["30219.1","0.1","0","1"],["30218.9","0","0","0"],["30216.2","2.21","0","1"],["30215.8","0","0","0"],["30214.4","0","0","0"],["30213","0.24830785","0","1"],["30212.2","0.02353532","0","1"],["30209.9","0.06048955","0","1"],["30208.2","0.01643806","0","1"],["30207.9","0","0","0"],["30206.9","0","0","0"],["30206.6","0.04394056","0","2"],["30202.8","0.06","0","1"],["30201.6","0.48","0","1"],["30201.2","0.58799999","0","1"],["30200.2","0","0","0"],["30179.9","0.33075347","0","2"],["29995","0.0284951","0","1"],["29994.2","0.00004654","0","1"],["29993.2","0.00154236","0","1"],["29992.7","0","0","0"]],"ts":"1652459230888","checksum":-1246786079}]}
1652459231.0173392: {"arg":{"channel":"books","instId":"UNI-USD-SWAP"},"action":"update","data":[{"asks":[["5.149","353","0","5"],["5.151","0","0","0"],["5.152","25","0","2"]],"bids":[["5.141","0","0","0"],["5.137","0","0","0"],["5.134","36","0","1"],["5.133","5","0","1"],["5.132","435","0","5"],["5.131","188","0","1"],["5.129","327","0","3"],["5.128","738","0","3"]],"ts":"1652459230894","checksum":515882643}]}
1652459231.127986: {"arg":{"channel":"books","instId":"BTC-USD-220527"},"action":"update","data":[{"asks":[["30232.7","3","0","1"],["30243.6","100","0","1"],["30261.4","0","0","0"]],"bids":[["30224.7","0","0","0"],["30224.6","0","0","0"],["30224.2","0","0","0"],["30207.9","0","0","0"],["30201","15","0","1"],["30179.4","0","0","0"]],"ts":"1652459230999","checksum":2009979019}]}
1652459231.1281667: {"arg":{"channel":"books","instId":"BTC-USDT"},"action":"update","data":[{"asks":[["30240.4","3.39806661","0","5"],["30242.6","0.07259","0","2"],["30266.4","0.33039938","0","1"],["30267.2","0","0","0"],["30270.4","0.00887963","0","1"],["30273.4","0","0","0"],["30274","0.037","0","1"],["30277.6","0","0","0"],["30280.3","0","0","0"],["30287.4","0","0","0"],["30288","0.06615923","0","1"],["30294","0.05975831","0","1"],["30354.5","0.0471802","0","1"],["30382.4","0","0","0"],["30540.1","0","0","0"],["30619.9","1.95950999","0","1"],["30641.6","0","0","0"],["30642.3","0","0","0"],["30642.8","0","0","0"]],"bids":[["30236.2","0","0","0"],["30233.9","0.0132","0","1"],["30232.1","0","0","0"],["30230.1","0","0","0"],["30228.3","0.12157449","0","1"],["30228.1","0.000824","0","1"],["30226.1","0","0","0"],["30224.3","0","0","0"],["30222.3","0","0","0"],["30219.9","0.33090777","0","1"],["30219.6","0.02256429","0","1"],["30217.4","0.06615944","0","1"],["30216.1","0","0","0"],["30215.4","0","0","0"],["30215.2","0.33106953","0","2"],["30209.2","0.00766645","0","1"],["30208.3","0.01643806","0","1"],["30208.2","0","0","0"],["30206.6","0.00694056","0","1"],["30200","16.40261501","0","59"],["30191.9","0","0","0"],["30189.3","0","0","0"],["30188.8","0","0","0"],["30182.3","0.24","0","1"],["30151.8","4.62417796","0","1"],["30136.5","0","0","0"],["30131.9","0.16536852","0","1"],["30110.3","3.5","0","1"],["29992.7","0.00007716","0","1"],["29991.7","0","0","0"],["29990.1","0","0","0"],["29990","0","0","0"],["29988.3","0","0","0"],["29988.1","0","0","0"]],"ts":"1652459231002","checksum":473028940}]}
1652459231.1284943: {"arg":{"channel":"books","instId":"UNI-USD-SWAP"},"action":"update","data":[{"asks":[["5.152","150","0","3"],["5.155","69","0","2"]],"bids":[["5.14","196","0","3"],["5.132","448","0","5"],["5.131","230","0","2"],["5.129","285","0","2"],["5.128","738","0","3"]],"ts":"1652459230977","checksum":532069250}]}
1652459231.2306526: {"arg":{"channel":"books","instId":"BTC-USDT"},"action":"update","data":[{"asks":[["30240.4","3.38373","0","4"],["30240.6","0","0","0"],["30242.6","0.024","0","1"],["30246.6","0","0","0"],["30251.7","0","0","0"],["30252.8","0","0","0"],["30253","0","0","0"],["30254.8","0.1","0","1"],["30260.9","0.00052123","0","1"],["30264.9","0","0","0"],["30265","0","0","0"],["30266.4","0.33039938","0","1"],["30267.7","0","0","0"],["30273.8","0","0","0"],["30283.2","0.00798335","0","1"],["30315.9","0.08255","0","1"],["30323.9","0","0","0"],["30340.2","0.50010958","0","2"],["30616.9","1.95970199","0","1"],["30619.9","0","0","0"],["30641.6","0.00065466","0","1"],["30642.3","0.00025498","0","1"],["30642.8","0.00164802","0","1"],["30643.5","0.00265198","0","1"],["30644.5","0.00016417","0","1"],["30645.9","0.0003738","0","1"],["30646.6","0","0","0"]],"bids":[["30236.5","0","0","0"],["30234.1","0.16","0","1"],["30226.8","0","0","0"],["30223.6","0","0","0"],["30216.3","0.08255","0","1"],["30212.3","0.16560802","0","1"],["30208.3","0","0","0"],["30207.9","0.01643806","0","1"],["30206","0","0","0"],["30110.3","0","0","0"],["29991.7","0.00126666","0","1"],["29990.1","0","0","0"]],"ts":"1652459231118","checksum":386817009}]}
1652459231.233183: {"arg":{"channel":"books","instId":"BTC-USD-220527"},"action":"update","data":[{"asks":[["30232.7","0","0","0"],["30234.6","0","0","0"],["30235.9","0","0","0"],["30242.1","100","0","1"],["30242.2","0","0","0"],["30243.4","0","0","0"],["30243.5","0","0","0"],["30243.6","0","0","0"],["30243.7","0","0","0"],["30255.2","0","0","0"],["30255.3","0","0","0"],["30255.4","0","0","0"],["30258.1","30","0","1"],["30258.3","0","0","0"],["30258.4","0","0","0"],["30261.3","4","0","1"],["30261.4","100","0","1"],["30265.6","0","0","0"],["30276.1","0","0","0"],["30277.9","0","0","0"],["30288.9","0","0","0"]],"bids":[["30227.6","0","0","0"],["30226.7","3","0","1"],["30224.2","0","0","0"],["30224.1","0","0","0"],["30222.1","4","0","1"],["30222","1783","0","1"],["30220.3","0","0","0"],["30220.2","0","0","0"],["30213","214","0","1"],["30212.5","0","0","0"],["30211.9","0","0","0"],["30209.9","0","0","0"],["30171.4","461","0","1"],["30168.9","19","0","1"]],"ts":"1652459231116","checksum":-1742230574}]}
1652459231.2336028: {"arg":{"channel":"books","instId":"UNI-USD-SWAP"},"action":"update","data":[{"asks":[["5.148","98","0","1"],["5.149","297","0","4"],["5.151","54","0","1"],["5.158","134","0","3"],["5.159","288","0","2"]],"bids":[["5.14","97","0","2"],["5.138","105","0","2"],["5.132","490","0","6"],["5.131","188","0","1"]],"ts":"1652459231112","checksum":1525025120}]}
1652459231.3421328: {"arg":{"channel":"books","instId":"BTC-USD-220527"},"action":"update","data":[{"asks":[["30236.8","3","0","1"],["30236.9","0","0","0"],["30237.5","2","0","1"],["30242.1","0","0","0"],["30257.9","24","0","1"],["30258","104","0","2"],["30261.3","0","0","0"],["30261.4","0","0","0"],["30262.8","172","0","1"],["30263.8","215","0","1"]],"bids":[["30229.6","0","0","0"],["30229.5","0","0","0"],["30227.4","3","0","1"],["30226.8","0","0","0"],["30226.7","0","0","0"],["30222.1","4","0","1"],["30213.4","0","0","0"],["30213","0","0","0"],["30186.7","0","0","0"],["30180.4","24","0","1"],["30156.6","20","0","1"]],"ts":"1652459231218","checksum":1513502012}]}
1652459231.342672: {"arg":{"channel":"books","instId":"BTC-USDT"},"action":"update","data":[{"asks":[["30240.4","1.26373","0","3"],["30242.6","0","0","0"],["30243.7","0.0132","0","1"],["30244.7","0","0","0"],["30245.3","0","0","0"],["30245.6","0.06523858","0","1"],["30248.9","0.1","0","1"],["30256.2","0.06863228","0","1"],["30260.7","0.00065725","0","1"],["30260.9","0","0","0"],["30261.9","0","0","0"],["30266.8","0","0","0"],["30267.5","0.7100615","0","1"],["30270.4","0","0","0"],["30274","0","0","0"],["30274.1","0.76251172","0","2"],["30278.9","0.037","0","1"],["30287.2","2.69996","0","2"],["30645.9","0","0","0"],["30646.6","0","0","0"],["30650","0","0","0"]],"bids":[["30238","0.01","0","1"],["30222.5","0.1","0","1"],["30216.2","2.21661673","0","2"],["30216","0","0","0"],["30211.8","0","0","0"],["30208.8","0.01643806","0","1"],["30207.9","0","0","0"],["30202.7","0.08165825","0","2"],["29991.7","0.00126666","0","1"],["29990.1","0","0","0"]],"ts":"1652459231222","checksum":454446013}]}
1652459231.3436697: {"arg":{"channel":"books","instId":"UNI-USD-SWAP"},"action":"update","data":[{"asks":[["5.148","0","0","0"],["5.151","0","0","0"],["5.152","204","0","4"],["5.153","192","0","1"],["5.158","129","0","2"],["5.159","321","0","3"]],"bids":[["5.132","493","0","6"]],"ts":"1652459231226","checksum":-100726875}]}
1652459231.460653: {"arg":{"channel":"books","instId":"UNI-USD-SWAP"},"action":"update","data":[{"asks":[["5.147","20","0","1"],["5.148","25","0","1"],["5.149","272","0","3"],["5.15","6","0","1"],["5.151","72","0","1"],["5.152","204","0","4"],["5.153","192","0","1"],["5.157","161","0","3"],["5.158","129","0","2"],["5.159","1559","0","3"]],"bids":[["5.14","0","0","0"],["5.139","0","0","0"],["5.138","221","0","4"],["5.136","231","0","1"],["5.132","332","0","4"],["5.13","96","0","1"],["5.129","327","0","3"],["5.124","231","0","1"],["5.118","545","0","2"]],"ts":"1652459231330","checksum":-891821054}]}
1652459231.4612682: {"arg":{"channel":"books","instId":"BTC-USDT"},"action":"update","data":[{"asks":[["30245.1","0","0","0"],["30245.6","0","0","0"],["30246.6","0.16","0","1"],["30252.6","0.05","0","1"],["30252.8","0.02476197","0","1"],["30260.7","0","0","0"],["30260.9","0","0","0"],["30263.7","2.321","0","1"],["30267.5","0","0","0"],["30267.6","0","0","0"],["30283.2","0","0","0"],["30288","3.15015923","0","2"],["30385.7","0","0","0"],["30644.5","0.00016417","0","1"],["30645.9","0.0003738","0","1"]],"bids":[["30240","0.033","0","1"],["30238","0","0","0"],["30236.3","0.04","0","1"],["30234.1","0","0","0"],["30231.7","0.07113791","0","1"],["30229.3","0.33080488","0","1"],["30229.2","0","0","0"],["30226.5","0","0","0"],["30224.2","0","0","0"],["30219.4","0.73617144","0","1"],["30213.6","0.00921832","0","1"],["30209.2","0","0","0"],["30208.8","0","0","0"],["30208.3","0","0","0"],["30207.9","0","0","0"],["30206.8","0.01643806","0","1"],["30201.9","0","0","0"],["30131.9","0","0","0"],["29990.1","0.00012192","0","1"],["29990","0.01737427","0","3"],["29988.3","0.00003047","0","1"],["29988.1","0.00077825","0","1"]],"ts":"1652459231337","checksum":-397404380}]}
1652459231.462128: {"arg":{"channel":"books","instId":"BTC-USD-220527"},"action":"update","data":[{"asks":[["30232.3","0","0","0"],["30234.4","3","0","1"],["30236.8","0","0","0"],["30257.8","100","0","1"],["30262.8","0","0","0"],["30263.8","0","0","0"],["30273.8","449","0","1"]],"bids":[["30227.5","0","0","0"],["30227.4","0","0","0"],["30224.4","0","0","0"],["30222.1","0","0","0"],["30222","0","0","0"],["30210","4","0","1"],["30209.9","385","0","2"],["30204.2","0","0","0"]],"ts":"1652459231332","checksum":-1585551578}]}
1652459231.5623434: {"arg":{"channel":"books","instId":"BTC-USDT"},"action":"update","data":[{"asks":[["30245.8","0.06523858","0","1"],["30246.6","0","0","0"],["30283.2","0.00798335","0","1"],["30537","1.96482955","0","1"],["30616.9","0","0","0"],["30645.9","0","0","0"]],"bids":[["30234.1","0.16","0","1"],["30207.9","0.01643806","0","1"],["30206.8","0","0","0"],["30206.4","0","0","0"],["30192","3.012","0","1"],["29988.3","0","0","0"],["29988.1","0","0","0"]],"ts":"1652459231432","checksum":1414362108}]}
1652459231.5628865: {"arg":{"channel":"books","instId":"BTC-USD-220527"},"action":"update","data":[{"asks":[["30234.4","0","0","0"],["30235.5","3","0","1"],["30243.7","100","0","1"],["30243.8","24","0","1"],["30257.9","0","0","0"],["30258","104","0","2"],["30266.5","20","0","1"]],"bids":[["30226.8","3","0","1"],["30225.7","0","0","0"],["30210.1","73","0","1"],["30204.2","0","0","0"],["30168.9","0","0","0"],["30156.6","0","0","0"]],"ts":"1652459231448","checksum":-614499939}]}
1652459231.5632734: {"arg":{"channel":"books","instId":"UNI-USD-SWAP"},"action":"update","data":[{"asks":[["5.148","79","0","2"],["5.151","20","0","1"],["5.152","130","0","2"],["5.153","315","0","3"],["5.154","1874","0","2"],["5.157","74","0","2"],["5.159","288","0","2"],["5.162","11966","0","4"],["5.165","0","0","0"],["5.166","192","0","1"],["5.17","64","0","1"],["5.174","0","0","0"]],"bids":[["5.139","20","0","1"],["5.138","144","0","3"],["5.136","231","0","1"],["5.132","321","0","5"],["5.126","0","0","0"],["5.122","11950","0","3"]],"ts":"1652459231446","checksum":28662016}]}
1652459231.685562: {"arg":{"channel":"books","instId":"BTC-USDT"},"action":"update","data":[{"asks":[["30240.4","1.03102","0","3"],["30245.8","0","0","0"],["30246","0.06523858","0","1"],["30246.2","0","0","0"],["30249","0.06507681","0","2"],["30250.2","0","0","0"],["30250.6","0.0391","0","1"],["30251.8","0.71520489","0","5"],["30260.7","0","0","0"],["30283.2","0.00798335","0","1"],["30293.4","0.00008145","0","1"],["30303.4","0","0","0"],["30644.5","0.00016417","0","1"],["30645.9","0","0","0"],["30646.6","0","0","0"]],"bids":[["30237.2","0","0","0"],["30233.1","0","0","0"],["30229.9","0.05","0","1"],["30227","0","0","0"],["30216.4","0.00661833","0","1"],["30216.2","2.21","0","1"],["30207.9","0","0","0"],["30207.6","0","0","0"],["30207.5","0.01643806","0","1"],["30195.4","0.02059858","0","1"],["30194.6","0.00062297","0","2"],["30184.6","0.01315522","0","1"],["30150","0.03481283","0","8"],["29991.7","0","0","0"],["29990.1","0","0","0"],["29990","0","0","0"],["29988.3","0","0","0"]],"ts":"1652459231556","checksum":-1299092762}]}
1652459231.6861086: {"arg":{"channel":"books","instId":"BTC-USD-220527"},"action":"update","data":[{"asks":[],"bids":[["30210.1","0","0","0"]],"ts":"1652459231478","checksum":284680148}]}
1652459231.6862874: {"arg":{"channel":"books","instId":"UNI-USD-SWAP"},"action":"update","data":[{"asks":[["5.16","157","0","2"],["5.162","11931","0","3"]],"bids":[["5.139","119","0","2"],["5.138","45","0","2"],["5.13","138","0","2"],["5.129","269","0","1"],["5.122","11915","0","2"],["5.12","150","0","3"]],"ts":"1652459231560","checksum":763702025}]}
1652459231.7933588: {"arg":{"channel":"books","instId":"BTC-USD-220527"},"action":"update","data":[{"asks":[["30229.8","0","0","0"],["30232.6","3","0","1"],["30233.1","0","0","0"],["30235.5","0","0","0"],["30243.5","0","0","0"],["30243.6","24","0","1"],["30243.7","100","0","1"],["30243.8","0","0","0"],["30257.8","0","0","0"],["30258","104","0","2"],["30273.8","0","0","0"]],"bids":[["30226.9","0","0","0"],["30226.8","0","0","0"],["30223","4","0","1"],["30222.9","3","0","1"],["30210.3","81","0","1"],["30210.2","138","0","2"],["30210.1","214","0","1"],["30210","0","0","0"],["30204.2","0","0","0"]],"ts":"1652459231666","checksum":-787371156}]}
1652459231.7939758: {"arg":{"channel":"books","instId":"BTC-USDT"},"action":"update","data":[{"asks":[["30240.4","1.26375","0","4"],["30246","0","0","0"],["30247","0.06523858","0","1"],["30253.2","0.05026727","0","1"],["30254.7","0.12","0","1"],["30254.8","0","0","0"],["30263.7","0","0","0"],["30283.2","0","0","0"],["30288","0.06615923","0","1"],["30289.5","2.44922","0","1"],["30314.8","0","0","0"],["30537","0","0","0"],["30619.9","1.95950999","0","1"],["30644.5","0.00016417","0","1"],["30645.9","0.0003738","0","1"]],"bids":[["30219.9","0.35590777","0","2"],["30207.7","0","0","0"],["30207.5","0","0","0"],["30206.8","0.01643806","0","1"],["30206.4","0","0","0"]],"ts":"1652459231661","checksum":139397697}]}
1652459231.7945287: {"arg":{"channel":"books","instId":"UNI-USD-SWAP"},"action":"update","data":[{"asks":[],"bids":[["5.126","16","0","1"]],"ts":"1652459231570","checksum":-1593810962}]}
1652459231.9013376: {"arg":{"channel":"books","instId":"BTC-USDT"},"action":"update","data":[{"asks":[["30240.4","0.001","0","1"],["30242.5","0","0","0"],["30243.7","0","0","0"],["30247","0","0","0"],["30247.1","0.00087743","0","1"],["30247.2","0.06523858","0","1"],["30249.9","0.0134","0","2"],["30253.8","0.01","0","1"],["30265.5","2.308","0","1"],["30268","1.1100615","0","3"],["30283.2","0.00798335","0","1"],["30289.8","3.183","0","1"],["30616.9","1.95970199","0","1"],["30619.9","0","0","0"],["30643.5","0","0","0"],["30644.5","0","0","0"],["30645.9","0","0","0"]],"bids":[["30231.8","5.52289644","0","1"],["30207.6","0.01643806","0","1"],["30207.2","0.037","0","1"],["30206.8","0","0","0"],["30200","16.36561501","0","58"],["29993.2","0","0","0"],["29992.7","0","0","0"]],"ts":"1652459231777","checksum":1543976531}]}
1652459231.901723: {"arg":{"channel":"books","instId":"BTC-USD-220527"},"action":"update","data":[{"asks":[["30231.9","0","0","0"],["30232.6","0","0","0"],["30235.9","0","0","0"],["30237.5","0","0","0"],["30241","3","0","1"],["30243.6","0","0","0"],["30243.7","0","0","0"],["30243.9","0","0","0"],["30258","100","0","1"],["30258.9","4","0","1"],["30261.4","0","0","0"],["30264.2","0","0","0"],["30265.6","0","0","0"],["30265.7","0","0","0"],["30273.1","11","0","1"],["30275.6","469","0","1"]],"bids":[["30234.2","3","0","1"],["30229.4","0","0","0"],["30225.4","0","0","0"],["30225.3","0","0","0"],["30223","0","0","0"],["30222.9","0","0","0"],["30210.4","4","0","1"],["30210.2","73","0","1"],["30204.2","0","0","0"],["30196.2","0","0","0"]],"ts":"1652459231779","checksum":-1901018250}]}
1652459231.9021115: {"arg":{"channel":"books","instId":"UNI-USD-SWAP"},"action":"update","data":[{"asks":[["5.157","80","0","2"],["5.162","80","0","2"]],"bids":[["5.138","122","0","3"]],"ts":"1652459231776","checksum":2048738208}]}
1652459232.0033433: {"arg":{"channel":"trades","instId":"BTC-USDT"},"data":[{"instId":"BTC-USDT","tradeId":"338476344","px":"30240.3","sz":"0.00105752","side":"sell","ts":"1652459231875"}]}
1652459232.0034642: {"arg":{"channel":"trades","instId":"BTC-USDT"},"data":[{"instId":"BTC-USDT","tradeId":"338476345","px":"30240.3","sz":"0.00019248","side":"sell","ts":"1652459231875"}]}
1652459232.0035164: {"arg":{"channel":"trades","instId":"BTC-USDT"},"data":[{"instId":"BTC-USDT","tradeId":"338476346","px":"30240.3","sz":"0.00000752","side":"sell","ts":"1652459231875"}]}
1652459232.0062084: {"arg":{"channel":"books","instId":"BTC-USDT"},"action":"update","data":[{"asks":[["30240.1","0.15238","0","3"],["30240.3","0.10929","0","2"],["30240.4","0.51505","0","5"],["30242.6","0.059","0","1"],["30243.5","0.16","0","1"],["30245","0.06523858","0","1"],["30246.1","0.00087743","0","1"],["30246.2","0","0","0"],["30246.6","0.16","0","1"],["30247.1","0","0","0"],["30247.2","0","0","0"],["30247.4","0","0","0"],["30249.9","0.0002","0","1"],["30267.9","0.40056406","0","2"],["30268","0.4","0","2"],["30274.1","0.00778663","0","1"],["30283.2","0.00798335","0","1"],["30315.9","0","0","0"],["30322.8","0.104826","0","2"],["30640","0","0","0"],["30641.6","0","0","0"],["30642.3","0","0","0"],["30642.8","0","0","0"],["30643.5","0","0","0"]],"bids":[["30240.3","0","0","0"],["30234.1","0","0","0"],["30234","0","0","0"],["30233.9","0","0","0"],["30231.9","0","0","0"],["30231.8","0","0","0"],["30231.7","0","0","0"],["30230.9","0","0","0"],["30230.8","0","0","0"],["30229.9","0","0","0"],["30229.5","0","0","0"],["30228.7","0.85286652","0","2"],["30228.1","0","0","0"],["30226.1","0.07113791","0","1"],["30223.7","0.1386","0","1"],["30222.1","0.08255","0","1"],["30219","0.15","0","2"],["30216.3","0","0","0"],["30215.4","0.15","0","1"],["30207.6","0","0","0"],["30206.8","0.01643806","0","1"],["30206.6","0.00694056","0","1"],["30148","0","0","0"],["29994.2","0.00004654","0","1"],["29993.2","0.00154236","0","1"],["29992.7","0.00007716","0","1"],["29991.7","0.00126666","0","1"],["29990.1","0.00012192","0","1"],["29990","0.01737427","0","3"],["29988.3","0.00003047","0","1"],["29988.1","0.00077825","0","1"],["29988","0.00065689","0","1"]],"ts":"1652459231892","checksum":-1384027664}]}
1652459232.0069647: {"arg":{"channel":"books","instId":"BTC-USD-220527"},"action":"update","data":[{"asks":[["30234.5","0","0","0"],["30236.4","2","0","1"],["30236.5","0","0","0"],["30240.9","2","0","1"],["30241","0","0","0"],["30261.4","100","0","1"],["30265.7","11","0","1"],["30273.1","0","0","0"]],"bids":[["30234.2","0","0","0"],["30227.2","0","0","0"],["30210.7","0","0","0"],["30210.6","77","0","2"],["30210.5","65","0","1"],["30210.4","0","0","0"],["30210.3","0","0","0"],["30210.2","0","0","0"],["30204.2","0","0","0"],["30204.1","0","0","0"]],"ts":"1652459231891","checksum":-1390829168}]}
1652459232.0083535: {"arg":{"channel":"books","instId":"UNI-USD-SWAP"},"action":"update","data":[{"asks":[["5.147","77","0","2"],["5.148","25","0","1"],["5.162","11931","0","3"]],"bids":[["5.139","20","0","1"],["5.138","45","0","2"]],"ts":"1652459231893","checksum":1221932037}]}
1652459232.0329316: {"arg":{"channel":"tickers","instId":"BTC-USDT"},"data":[{"instType":"SPOT","instId":"BTC-USDT","last":"30240.3","lastSz":"0.00000752","askPx":"30247.4","askSz":"0.00000854","bidPx":"30247.3","bidSz":"0.23185135","open24h":"29700.4","high24h":"31073","low24h":"28020.3","sodUtc0":"29028.8","sodUtc8":"30337.7","volCcy24h":"525803546.09099243","vol24h":"17602.17897338","ts":"1652459231908"}]}
1652459232.0527077: {"arg":{"channel":"trades","instId":"BTC-USDT"},"data":[{"instId":"BTC-USDT","tradeId":"338476347","px":"30240.1","sz":"0.0006591","side":"buy","ts":"1652459231933"}]}
1652459232.1181054: {"arg":{"channel":"trades","instId":"BTC-USDT"},"data":[{"instId":"BTC-USDT","tradeId":"338476348","px":"30240","sz":"0.033","side":"sell","ts":"1652459231995"}]}
1652459232.118269: {"arg":{"channel":"trades","instId":"BTC-USDT"},"data":[{"instId":"BTC-USDT","tradeId":"338476349","px":"30240","sz":"0.001","side":"sell","ts":"1652459231995"}]}
1652459232.120562: {"arg":{"channel":"books","instId":"BTC-USD-220527"},"action":"update","data":[{"asks":[["30229.9","3","0","1"],["30242.2","100","0","1"],["30242.3","30","0","1"],["30252.1","15","0","1"],["30258","0","0","0"],["30258.1","0","0","0"],["30261.4","0","0","0"],["30264.3","0","0","0"],["30275.6","0","0","0"]],"bids":[["30224.1","0","0","0"],["30221.5","0","0","0"],["30221.2","0","0","0"],["30210.8","0","0","0"],["30210.7","0","0","0"],["30210.6","4","0","1"],["30186.5","99","0","1"],["30183","99","0","1"]],"ts":"1652459232005","checksum":738930413}]}
1652459232.1209981: {"arg":{"channel":"books","instId":"BTC-USDT"},"action":"update","data":[{"asks":[["30240.1","5.48590139","0","13"],["30240.3","0.10329","0","1"],["30240.4","0.33049132","0","3"],["30242.6","0","0","0"],["30243.4","2.16","0","1"],["30243.5","0.16","0","1"],["30244.9","1.25523858","0","2"],["30245","0","0","0"],["30245.6","0","0","0"],["30246.1","0","0","0"],["30247.9","0.0002","0","1"],["30249.5","0.635","0","1"],["30249.9","0","0","0"],["30255.8","0","0","0"],["30259.4","0.03","0","1"],["30259.6","0.06","0","1"],["30260.6","0.09","0","1"],["30260.7","0.24763532","0","1"],["30261","0","0","0"],["30261.9","0.76389863","0","1"],["30262.8","0.04985104","0","1"],["30265.1","0.15","0","1"],["30266.1","0","0","0"],["30268.6","0.00892796","0","1"],["30272.6","0.037","0","1"],["30274.1","0","0","0"],["30277.9","0","0","0"],["30278.9","0","0","0"],["30283.2","0","0","0"],["30638.9","0.0019984","0","1"],["30639","0","0","0"],["30639.5","0","0","0"],["30640","0","0","0"],["30641.6","0","0","0"]],"bids":[["30240","0.0002","0","1"],["30229.3","0.0132","0","1"],["30228.3","0","0","0"],["30227.7","0","0","0"],["30227.6","0.16","0","1"],["30223.5","0.12159379","0","1"],["30223.1","0.33087274","0","1"],["30222.5","0","0","0"],["30222.1","0","0","0"],["30219.9","0","0","0"],["30213.6","0","0","0"],["30213.4","0.33097896","0","1"],["30212.3","0.24815802","0","2"],["30207.7","0.00926236","0","1"],["30207.2","0","0","0"],["30206.8","0","0","0"],["30205.2","0.00138968","0","1"],["30204.8","0.36393806","0","2"],["30201.6","0","0","0"],["30201.2","0","0","0"],["30200.2","0.037","0","1"],["30198.8","0.557","0","1"],["30198.7","0","0","0"],["30194.7","0.58799999","0","1"],["30193.5","0.48253303","0","2"],["30190.8","1","0","1"],["30182.3","0","0","0"],["30176","0.24","0","1"],["30154.7","0","0","0"],["30131.9","0.16535376","0","1"],["30096.6","0","0","0"],["30083.4","0.05128032","0","1"],["29988","0.00065689","0","1"],["29987.9","0.00012778","0","1"],["29987.6","0.00267834","0","1"],["29987.3","0","0","0"],["29986.8","0","0","0"],["29986","0","0","0"]],"ts":"1652459232006","checksum":-1762330246}]}
1652459232.122173: {"arg":{"channel":"books","instId":"UNI-USD-SWAP"},"action":"update","data":[{"asks":[["5.147","77","0","2"],["5.148","25","0","1"]],"bids":[["5.139","77","0","1"],["5.138","20","0","1"],["5.136","0","0","0"],["5.132","305","0","4"],["5.131","188","0","1"],["5.13","96","0","1"],["5.129","269","0","1"],["5.128","783","0","4"]],"ts":"1652459231994","checksum":-2043041522}]}
1652459232.1224556: {"arg":{"channel":"trades","instId":"BTC-USDT"},"data":[{"instId":"BTC-USDT","tradeId":"338476350","px":"30240","sz":"0.0002","side":"sell","ts":"1652459232005"}]}
1652459232.1428943: {"arg":{"channel":"tickers","instId":"BTC-USDT"},"data":[{"instType":"SPOT","instId":"BTC-USDT","last":"30240","lastSz":"0.0002","askPx":"30247.4","askSz":"0.00000854","bidPx":"30247.3","bidSz":"0.23185135","open24h":"29700.4","high24h":"31073","low24h":"28020.3","sodUtc0":"29028.8","sodUtc8":"30337.7","volCcy24h":"525804600.23024234","vol24h":"17602.21383248","ts":"1652459232009"}]}
1652459232.2307012: {"arg":{"channel":"books","instId":"BTC-USDT"},"action":"update","data":[{"asks":[["30230.3","0.35560972","0","4"],["30234.7","0.23273","0","1"],["30236","0","0","0"],["30236.2","0","0","0"],["30236.3","0.09739","0","2"],["30236.4","0.0132","0","1"],["30238.5","0","0","0"],["30239.4","0.16","0","1"],["30239.5","0","0","0"],["30240","0.85798335","0","2"],["30240.1","0.6852319","0","6"],["30240.3","0","0","0"],["30240.4","0.1629999","0","3"],["30240.5","0","0","0"],["30241.9","0","0","0"],["30243.4","0","0","0"],["30244.9","0","0","0"],["30245.9","0.0002","0","1"],["30247.9","0","0","0"],["30249","0.04859","0","1"],["30251.7","0.0487806","0","2"],["30251.8","0.62207612","0","4"],["30252.8","0.02476197","0","1"],["30257.9","0","0","0"],["30260.9","0.15","0","1"],["30262.8","0","0","0"],["30263.7","0.13230575","0","1"],["30265.1","0","0","0"],["30265.8","0.00269825","0","1"],["30275.1","2.45037","0","1"],["30278.4","0","0","0"],["30282.7","2.45055","0","1"],["30285","0.13232327","0","1"],["30286.6","2.45055","0","1"],["30287.2","0.25","0","1"],["30288","0","0","0"],["30289.5","0","0","0"],["30297.8","0","0","0"],["30312","1.65014767","0","1"],["30315","0","0","0"],["30317.4","0.08255","0","1"],["30322.8","0.022276","0","1"],["30326.1","0","0","0"],["30339.2","1.65861871","0","2"],["30353.3","0.00001067","0","1"],["30366.4","1.67272601","0","1"],["30380.5","0","0","0"],["30609.1","1.9603109","0","2"],["30616.9","0","0","0"],["30631.1","0.09529384","0","1"],["30633.3","0.00073181","0","2"],["30634.4","0.00066689","0","1"],["30636","0","0","0"],["30636.3","0","0","0"],["30636.7","0","0","0"],["30637.9","0","0","0"],["30638.9","0","0","0"]],"bids":[["30240","0","0","0"],["30236.3","0","0","0"],["30230.2","0.861","0","3"],["30229.3","0","0","0"],["30227.6","0","0","0"],["30227","0","0","0"],["30226.1","0","0","0"],["30225.8","0.0132","0","1"],["30224.9","0","0","0"],["30223.7","0.1386","0","1"],["30221.4","0.0711427","0","1"],["30219.6","0","0","0"],["30219.1","0","0","0"],["30219","0","0","0"],["30217.4","0","0","0"],["30216.4","0","0","0"],["30216.2","0","0","0"],["30215.4","0","0","0"],["30214.4","0.06616623","0","1"],["30214.3","0.06","0","1"],["30212","0.09","0","1"],["30211.8","0.15","0","1"],["30209.9","0","0","0"],["30208.5","0.00160826","0","1"],["30208.4","0","0","0"],["30204.9","0","0","0"],["30202.9","0.33109403","0","1"],["30197.9","0.06152773","0","1"],["30197.4","0.08","0","1"],["30193.5","0.48","0","1"],["30188","0.0255275","0","1"],["30170.5","0","0","0"],["30167.3","0","0","0"],["30160.6","0","0","0"],["30158.6","0","0","0"],["30155.7","2.44886","0","1"],["30150.7","2.44861808","0","2"],["30148.5","1.68644214","0","1"],["30143.3","2.45063","0","1"],["30131.4","0","0","0"],["30121.3","1.68719647","0","1"],["30119.9","0.19850526","0","1"],["30105.2","1.04778543","0","1"],["30104.2","0","0","0"],["30094.1","1.66422375","0","1"],["30059.9","0.66071596","0","2"],["29987.3","0.00025","0","1"],["29986.8","0.00029556","0","1"],["29986","0.00030544","0","1"],["29984","0.00005829","0","1"],["29983.6","0.00011111","0","1"],["29983.4","0","0","0"],["29983.3","0","0","0"]],"ts":"1652459232114","checksum":392041538}]}
1652459232.2316961: {"arg":{"channel":"books","instId":"BTC-USD-220527"},"action":"update","data":[{"asks":[["30226.5","0","0","0"],["30227.5","0","0","0"],["30228.1","0","0","0"],["30229.9","0","0","0"],["30236.3","0","0","0"],["30242.1","0","0","0"],["30250.3","104","0","2"],["30250.4","19","0","1"],["30252","0","0","0"],["30252.1","0","0","0"],["30255.6","11","0","1"],["30258.9","0","0","0"],["30261.4","0","0","0"],["30264.3","40","0","1"],["30265.7","0","0","0"],["30266.5","0","0","0"],["30273.8","465","0","1"],["30311.9","81","0","1"],["30324.9","0","0","0"],["30334.6","202","0","1"],["30358.8","0","0","0"],["31137.2","6","0","1"],["31147.6","0","0","0"]],"bids":[["30218.8","0","0","0"],["30218.7","3","0","1"],["30210.8","4","0","1"],["30210.7","0","0","0"],["30210.6","0","0","0"],["30186.5","0","0","0"],["30186.4","0","0","0"],["30183","99","0","1"],["30180","11","0","1"],["30171.4","0","0","0"],["30130.4","0","0","0"],["30117.7","81","0","1"],["29833.4","0","0","0"],["29825.4","202","0","1"],["29333.1","0","0","0"],["29323.3","5","0","1"]],"ts":"1652459232109","checksum":673308291}]}
1652459232.2321763: {"arg":{"channel":"books","instId":"UNI-USD-SWAP"},"action":"update","data":[{"asks":[["5.146","25","0","1"],["5.148","0","0","0"],["5.149","272","0","3"],["5.152","166","0","3"],["5.153","279","0","2"],["5.156","265","0","3"],["5.157","34","0","2"]],"bids":[["5.139","0","0","0"],["5.138","20","0","1"],["5.137","99","0","1"],["5.136","25","0","1"],["5.134","0","0","0"],["5.131","284","0","2"],["5.13","36","0","1"],["5.129","285","0","2"],["5.128","738","0","3"],["5.127","43","0","1"]],"ts":"1652459232108","checksum":296116756}]}
1652459232.3394742: {"arg":{"channel":"books","instId":"BTC-USD-220527"},"action":"update","data":[{"asks":[["30226","3","0","1"],["30227.9","2","0","1"],["30228","0","0","0"],["30236.8","0","0","0"],["30236.9","20","0","1"],["30240.8","0","0","0"],["30240.9","0","0","0"],["30242.1","4","0","1"],["30242.2","91","0","1"],["30250.2","0","0","0"],["30250.3","91","0","1"],["30255.5","91","0","1"],["30261.4","0","0","0"]],"bids":[["30221","0","0","0"],["30219.1","0","0","0"],["30218.7","0","0","0"],["30217.5","3","0","1"],["30211.3","4","0","1"],["30211.2","154","0","2"],["30211.1","0","0","0"],["30211","0","0","0"],["30210.9","65","0","1"],["30210.8","0","0","0"],["30210.6","0","0","0"],["30210.5","0","0","0"],["30210.2","0","0","0"],["30201.1","0","0","0"],["30183","100","0","1"],["30160.3","470","0","1"]],"ts":"1652459232224","checksum":1819046106}]}
1652459232.339736: {"arg":{"channel":"books","instId":"BTC-USDT"},"action":"update","data":[{"asks":[["30230.3","0.07428972","0","2"],["30234.7","0","0","0"],["30236.4","0","0","0"],["30240","0.85","0","1"],["30240.1","0.6984319","0","7"],["30244","0.01","0","1"],["30244.3","0.635","0","1"],["30247.4","0.03307","0","1"],["30249.5","0","0","0"],["30249.6","0.16563853","0","1"],["30250.6","0","0","0"],["30253.8","0","0","0"],["30257.5","0","0","0"],["30261.4","0.24845779","0","1"],["30262.5","0","0","0"],["30263.4","0.883","0","1"],["30273","0","0","0"],["30279.1","0","0","0"],["30608.9","1.96021419","0","1"],["30609.1","0.00010952","0","1"],["30636","0.00004972","0","1"],["30636.3","0.00008138","0","1"],["30636.7","0","0","0"],["30637.9","0","0","0"]],"bids":[["30230.2","0.8612","0","4"],["30221.3","0","0","0"],["30219.4","0","0","0"],["30219.2","0.000824","0","1"],["30213","0","0","0"],["30211.2","0.02098","0","1"],["30208.7","0.23037703","0","1"],["30207.4","0.00661833","0","1"],["30206.6","0","0","0"],["30205.1","2.224","0","1"],["30204.9","0","0","0"],["30195.1","0.24845779","0","1"],["30195","0.05","0","1"],["30135.3","0.01383084","0","1"],["29986.8","0","0","0"],["29986","0","0","0"],["29984","0","0","0"],["29983.6","0","0","0"]],"ts":"1652459232210","checksum":2031958849}]}
1652459232.340013: {"arg":{"channel":"books","instId":"UNI-USD-SWAP"},"action":"update","data":[{"asks":[["5.145","83","0","2"],["5.146","25","0","1"],["5.147","20","0","1"],["5.149","343","0","3"],["5.152","41","0","2"],["5.153","295","0","3"],["5.156","249","0","2"],["5.157","1","0","1"],["5.159","304","0","3"],["5.162","11915","0","2"]],"bids":[["5.138","119","0","2"],["5.137","0","0","0"],["5.127","0","0","0"],["5.126","59","0","2"],["5.125","0","0","0"],["5.122","11851","0","1"],["5.118","609","0","3"]],"ts":"1652459232220","checksum":-1065345673}]}
1652459232.463044: {"arg":{"channel":"books","instId":"BTC-USD-220527"},"action":"update","data":[{"asks":[["30226","0","0","0"],["30227","3","0","1"],["30242.2","0","0","0"],["30250.3","91","0","1"],["30407.3","506","0","1"],["30426.3","0","0","0"],["30467.7","505","0","1"],["30486.8","202","0","1"],["30528.2","507","0","1"],["30547.3","0","0","0"]],"bids":[["30217.6","4","0","1"],["30216.1","65","0","1"],["30211.3","0","0","0"],["30211.2","0","0","0"],["30210.9","0","0","0"],["30210","100","0","1"],["30201.1","100","0","1"]],"ts":"1652459232327","checksum":-410544268}]}
1652459232.4633226: {"arg":{"channel":"books","instId":"BTC-USDT"},"action":"update","data":[{"asks":[["30253.8","0.27412546","0","1"],["30305","0.08255","0","1"],["30317.4","0","0","0"],["30365.3","0.47479435","0","1"],["30636","0","0","0"],["30636.3","0","0","0"]],"bids":[["30227.7","0","0","0"],["30212.3","0.16560802","0","1"],["30209.3","0.1","0","1"],["30205.2","0.08393968","0","2"],["30193.7","0.00694355","0","1"],["29987.9","0.00012778","0","1"],["29987.6","0","0","0"],["29987.3","0","0","0"]],"ts":"1652459232322","checksum":1112318147}]}
1652459232.4634657: {"arg":{"channel":"books","instId":"UNI-USD-SWAP"},"action":"update","data":[{"asks":[["5.146","123","0","2"],["5.148","5","0","1"]],"bids":[["5.138","97","0","2"],["5.129","285","0","2"],["5.126","59","0","2"],["5.075","0","0","0"],["5.069","240","0","1"]],"ts":"1652459232334","checksum":510003847}]}
1652459232.5616384: {"arg":{"channel":"books","instId":"BTC-USD-220527"},"action":"update","data":[{"asks":[],"bids":[["30210","100","0","1"],["30154.3","19","0","1"]],"ts":"1652459232438","checksum":705907165}]}
1652459232.5618734: {"arg":{"channel":"books","instId":"BTC-USDT"},"action":"update","data":[{"asks":[["30235.9","0","0","0"],["30236.2","0.00087743","0","1"],["30240.4","0.09776132","0","2"],["30240.5","0.06523858","0","1"],["30257","6.10318499","0","1"],["30285","0.19848928","0","2"],["30631.1","0","0","0"],["30633.3","0","0","0"],["30634.4","0","0","0"]],"bids":[["30212.8","5.94198963","0","1"],["30176.4","0.04437047","0","3"],["29987.9","0","0","0"]],"ts":"1652459232448","checksum":-1314764568}]}
1652459232.5620697: {"arg":{"channel":"books","instId":"UNI-USD-SWAP"},"action":"update","data":[{"asks":[["5.146","25","0","1"]],"bids":[["5.13","79","0","2"],["5.126","16","0","1"],["5.125","0","0","0"],["5.12","86","0","2"],["5.116","64","0","1"],["5.102","0","0","0"],["5.098","3658","0","2"],["5.097","0","0","0"],["5.093","160","0","1"]],"ts":"1652459232417","checksum":2126607670}]}
1652459232.6725407: {"arg":{"channel":"books","instId":"BTC-USDT"},"action":"update","data":[{"asks":[["30240.5","0","0","0"],["30240.9","0.06523858","0","1"],["30252.5","0.00056132","0","1"],["30256.9","0.00798335","0","1"],["30271","0","0","0"],["30605.8","1.96041273","0","1"],["30608.9","0","0","0"],["30630.3","0.00001158","0","1"],["30630.6","0","0","0"]],"bids":[["30222.9","0","0","0"],["30219.4","0.09906","0","1"],["30217.7","0.15","0","2"],["30214.3","0","0","0"],["30212.9","0.00798335","0","1"],["30212","0","0","0"],["29988","0.00065689","0","1"],["29987.9","0","0","0"]],"ts":"1652459232541","checksum":-28786543}]}
1652459232.6728644: {"arg":{"channel":"books","instId":"BTC-USD-220527"},"action":"update","data":[{"asks":[],"bids":[["30156.7","19","0","1"]],"ts":"1652459232480","checksum":2088296694}]}
1652459232.6729465: {"arg":{"channel":"books","instId":"UNI-USD-SWAP"},"action":"update","data":[{"asks":[["5.145","20","0","1"],["5.149","406","0","4"]],"bids":[["5.138","20","0","1"],["5.131","188","0","1"],["5.13","36","0","1"],["5.129","381","0","3"],["5.128","778","0","4"],["5.127","0","0","0"]],"ts":"1652459232552","checksum":-945294235}]}
1652459232.7866192: {"arg":{"channel":"books","instId":"BTC-USD-220527"},"action":"update","data":[{"asks":[["30222.1","3","0","1"],["30226.9","2","0","1"],["30227","0","0","0"],["30236.4","0","0","0"],["30236.8","4","0","1"],["30242.1","0","0","0"],["30242.2","0","0","0"],["30250.2","0","0","0"],["30250.3","0","0","0"],["30254.1","214","0","1"],["30255.5","0","0","0"],["30255.6","225","0","2"],["30261.5","0","0","0"],["30264.2","91","0","1"],["30282.5","120","0","1"],["30308","0","0","0"]],"bids":[["30217.6","0","0","0"],["30217.5","0","0","0"],["30214.7","3","0","1"],["30210.2","0","0","0"],["30210.1","0","0","0"],["30210","0","0","0"],["30209.9","0","0","0"],["30205.4","0","0","0"],["30203.5","0","0","0"],["30203.4","171","0","1"],["30202.6","0","0","0"],["30201.1","4","0","1"],["30201","0","0","0"],["30193.4","100","0","1"],["30193.3","15","0","1"],["30183","0","0","0"],["30160.3","0","0","0"]],"ts":"1652459232661","checksum":1296339392}]}
