1652459232.7870326: {"arg":{"channel":"books","instId":"BTC-USDT"},"action":"update","data":[{"asks":[["30230.3","0.68522097","0","7"],["30230.5","0","0","0"],["30233.4","0.16","0","1"],["30236.2","0","0","0"],["30239.4","0.1732","0","2"],["30240.1","0.6852319","0","6"],["30240.4","0.04859","0","1"],["30240.9","0","0","0"],["30241.5","0","0","0"],["30249.6","0.2078008","0","2"],["30251.7","0.00661833","0","1"],["30251.8","0.22207612","0","3"],["30252.5","0.00439865","0","1"],["30252.7","0","0","0"],["30257","6.6715649","0","2"],["30257.6","0.15","0","1"],["30258.2","0.00263024","0","1"],["30259.8","0.33047145","0","1"],["30260.9","0","0","0"],["30264.4","0.0094517","0","1"],["30266.4","0","0","0"],["30268.6","0","0","0"],["30279.9","0.25","0","1"],["30280.1","0","0","0"],["30300","0.3821414","0","5"],["30311.8","0.1386","0","1"],["30348","0.00340081","0","1"],["30630.3","0","0","0"],["30630.6","0","0","0"],["30631.1","0","0","0"],["30633.3","0","0","0"]],"bids":[["30230.2","0.0112","0","3"],["30228.7","0","0","0"],["30225.8","0","0","0"],["30223.7","0","0","0"],["30223.5","0","0","0"],["30223.1","0","0","0"],["30222.4","0","0","0"],["30221.5","0.0132","0","1"],["30221.4","0","0","0"],["30219.5","0","0","0"],["30219.4","0","0","0"],["30219.3","0","0","0"],["30219.2","0","0","0"],["30218.4","0.07183201","0","2"],["30217.7","0","0","0"],["30215.9","0.33095158","0","1"],["30215.2","0.00011028","0","1"],["30213.4","0","0","0"],["30212.9","0.03798335","0","2"],["30212.8","0","0","0"],["30211.8","0","0","0"],["30210.5","0.00138317","0","1"],["30210","0.09366203","0","3"],["30208.4","0.09","0","1"],["30207.7","0","0","0"],["30207.2","0.15","0","1"],["30205.1","0","0","0"],["30204.8","0.01643806","0","1"],["30204.5","0.33107649","0","1"],["30203.9","0.06821614","0","1"],["30203.8","0.00727187","0","1"],["30202.8","0","0","0"],["30200.2","0","0","0"],["30195","0","0","0"],["30194.7","0","0","0"],["30192","0","0","0"],["30190.9","0.06","0","1"],["30190.6","0.037","0","1"],["30185.3","0.18067462","0","2"],["30184.6","2.3252442","0","2"],["30179.9","0.16535048","0","1"],["30179.2","0.2986","0","2"],["30174.6","0","0","0"],["30169","0.00256254","0","1"],["30149","0.3475","0","1"],["30118.7","0.5312","0","1"],["29987.9","0.00012778","0","1"],["29987.6","0.00267834","0","1"],["29987.3","0.00025","0","1"],["29986.8","0.00029556","0","1"],["29986","0.00030544","0","1"],["29984","0.00005829","0","1"],["29983.6","0.00011111","0","1"],["29983.4","0.00016309","0","1"],["29983.3","0.00106016","0","1"],["29983.1","0.00218825","0","1"],["29983","0.00046876","0","1"],["29982.5","0.00031108","0","2"],["29982.2","0","0","0"]],"ts":"1652459232668","checksum":-1784913131}]}
1652459232.7883198: {"arg":{"channel":"books","instId":"UNI-USD-SWAP"},"action":"update","data":[{"asks":[["5.145","80","0","2"],["5.147","92","0","2"],["5.149","363","0","4"],["5.151","62","0","1"],["5.155","30","0","2"]],"bids":[["5.138","0","0","0"],["5.137","0","0","0"],["5.136","0","0","0"],["5.135","30","0","2"],["5.132","232","0","2"],["5.131","0","0","0"],["5.13","36","0","1"],["5.129","269","0","3"],["5.128","723","0","3"],["5.127","0","0","0"],["5.126","112","0","2"],["5.125","266","0","1"],["5.124","298","0","3"]],"ts":"1652459232664","checksum":290970199}]}
1652459232.8937583: {"arg":{"channel":"books","instId":"BTC-USDT"},"action":"update","data":[{"asks":[["30230.3","1.92170778","0","9"],["30230.8","0.059","0","1"],["30232.3","0.0132","0","1"],["30233.3","0.00096568","0","1"],["30236.2","2.46","0","1"],["30237","0.06523858","0","1"],["30238.5","0.635","0","1"],["30239.4","0.16","0","1"],["30240.1","0.66874509","0","5"],["30244","0","0","0"],["30244.3","0","0","0"],["30248.8","0.00661833","0","1"],["30248.9","0","0","0"],["30249.5","0.04216227","0","1"],["30249.6","0.16563853","0","1"],["30251.5","0.18","0","3"],["30251.6","0.15","0","1"],["30251.7","0","0","0"],["30252.7","0.00439865","0","1"],["30254.7","0","0","0"],["30257.6","0","0","0"],["30258.3","0.0098881","0","1"],["30259.4","0","0","0"],["30259.6","0","0","0"],["30260.6","0","0","0"],["30263.9","0.037","0","1"],["30264.4","0","0","0"],["30272.6","0","0","0"],["30275.1","0","0","0"],["30282.7","0","0","0"],["30285","0.13232327","0","1"],["30286.6","0","0","0"],["30293.1","0","0","0"],["30300","0.32256758","0","4"],["30316.2","0","0","0"],["30328.3","0.0471802","0","1"],["30354.5","0","0","0"],["30630.3","0.00001158","0","1"],["30630.6","0.00105588","0","1"],["30631.1","0.09529384","0","1"],["30633.3","0","0","0"],["30634.4","0","0","0"],["30636","0","0","0"],["30636.3","0","0","0"],["30636.7","0","0","0"]],"bids":[["30225.1","0","0","0"],["30218.4","0.000682","0","1"],["30216.7","0.12162115","0","1"],["30214.4","0","0","0"],["30214.3","0.07115001","0","1"],["30213.6","0.000824","0","1"],["30212.9","0.03","0","1"],["30209.3","0","0","0"],["30206.2","0.33105786","0","1"],["30204.8","0","0","0"],["30203.9","0","0","0"],["30203.8","0","0","0"],["30203.5","0","0","0"],["30202.9","0","0","0"],["30200.1","0.00798335","0","1"],["30198.9","0.01643806","0","1"],["30198.8","0","0","0"],["30197.7","0.00758915","0","1"],["30193.5","0","0","0"],["30190.8","0","0","0"],["30190.6","0.594","0","2"],["30185.5","0.63799999","0","2"],["30185.4","0.48","0","1"],["30182.9","1","0","1"],["30178.6","0","0","0"],["30176","0","0","0"],["30173.3","0.00033166","0","1"],["30169.5","0","0","0"],["30165.5","0.649","0","1"],["30155.7","0","0","0"],["30150.7","0.00037808","0","1"],["30143.3","0","0","0"],["30119.9","0","0","0"],["30059.9","0.85922187","0","3"],["29982.2","0.00016431","0","1"],["29980","0.00339344","0","2"],["29979.9","7.12144599","0","2"],["29978.9","0.00005058","0","1"],["29975.4","0.00043973","0","1"],["29974.3","0.00001781","0","1"]],"ts":"1652459232770","checksum":-1384972759}]}
1652459232.8942714: {"arg":{"channel":"books","instId":"BTC-USD-220527"},"action":"update","data":[{"asks":[["30222","2","0","1"],["30227.8","0","0","0"],["30227.9","0","0","0"],["30236.8","95","0","2"],["30242.2","0","0","0"],["30248.1","0","0","0"],["30248.2","0","0","0"],["30250.3","91","0","1"],["30250.8","39","0","1"],["30254","91","0","1"],["30255.6","11","0","1"],["30264.2","0","0","0"],["30264.3","0","0","0"]],"bids":[["30216.1","0","0","0"],["30214.7","0","0","0"],["30212.4","3","0","1"],["30209.9","65","0","1"],["30203.5","4","0","1"],["30201.1","0","0","0"],["30193.5","0","0","0"],["30193.4","0","0","0"],["30193.3","0","0","0"],["30186.5","0","0","0"],["30186.4","100","0","1"],["30186.3","30","0","1"],["30183","100","0","1"],["30156.7","0","0","0"],["30154.3","0","0","0"]],"ts":"1652459232777","checksum":-1999233474}]}
1652459232.894517: {"arg":{"channel":"books","instId":"UNI-USD-SWAP"},"action":"update","data":[{"asks":[["5.143","20","0","1"],["5.144","25","0","1"],["5.145","20","0","1"],["5.146","6","0","1"],["5.147","0","0","0"],["5.148","25","0","2"],["5.149","379","0","4"],["5.15","6","0","1"],["5.152","5","0","1"],["5.155","0","0","0"],["5.156","57","0","1"],["5.158","193","0","3"],["5.16","122","0","1"],["5.162","0","0","0"],["5.164","0","0","0"],["5.17","0","0","0"],["5.183","0","0","0"],["5.191","160","0","1"],["5.196","0","0","0"],["5.233","0","0","0"]],"bids":[["5.136","77","0","1"],["5.135","0","0","0"],["5.134","25","0","1"],["5.133","65","0","2"],["5.129","16","0","1"],["5.128","716","0","3"],["5.127","12","0","1"],["5.126","158","0","2"],["5.124","258","0","2"],["5.123","57","0","1"],["5.122","0","0","0"],["5.121","2039","0","5"],["5.12","51","0","1"],["5.118","564","0","2"],["5.06","101","0","1"],["5.054","240","0","1"]],"ts":"1652459232773","checksum":-657205853}]}
1652459233.0163221: {"arg":{"channel":"books","instId":"BTC-USD-220527"},"action":"update","data":[{"asks":[["30219.1","3","0","1"],["30221.9","768","0","1"],["30222.1","0","0","0"],["30226.8","0","0","0"],["30236.8","0","0","0"],["30236.9","0","0","0"],["30242.2","95","0","2"],["30246.3","91","0","1"],["30246.4","0","0","0"],["30250.3","0","0","0"],["30254","0","0","0"],["30254.1","0","0","0"],["30273.8","0","0","0"],["30467.7","707","0","2"],["30486.8","0","0","0"],["30589.9","202","0","1"],["30604.6","0","0","0"]],"bids":[["30212.4","0","0","0"],["30209.9","0","0","0"],["30203.5","0","0","0"],["30203.4","0","0","0"],["30197.5","4","0","1"],["30197.4","100","0","1"],["30197.3","214","0","1"],["30194.6","171","0","1"],["30186.5","0","0","0"],["30186.4","100","0","1"],["30160.4","458","0","1"],["30132.1","20","0","1"],["30117.7","0","0","0"],["30066.3","81","0","1"],["29825.4","0","0","0"],["29816.8","202","0","1"]],"ts":"1652459232881","checksum":-1572955532}]}
1652459233.0165865: {"arg":{"channel":"books","instId":"BTC-USDT"},"action":"update","data":[{"asks":[["30230.3","1.7876975","0","9"],["30230.7","0","0","0"],["30233.3","2.42","0","1"],["30252.5","0","0","0"],["30252.8","0","0","0"],["30253","0.56837991","0","1"],["30257","6.10318499","0","1"],["30265.5","0","0","0"],["30272.2","0.02983507","0","1"],["30279","0.06617805","0","1"],["30284.5","0.66","0","2"],["30288","0.068284","0","1"],["30289.2","0","0","0"],["30289.8","0","0","0"],["30326","0.4","0","1"],["30326.7","0","0","0"],["30605.8","0","0","0"],["30608.9","1.96021419","0","1"],["30633.3","0.00073181","0","2"],["30634.4","0","0","0"],["30636","0","0","0"],["30636.3","0","0","0"],["30636.7","0","0","0"]],"bids":[["30230.2","0.4112","0","4"],["30224","0","0","0"],["30216.1","0.01144","0","1"],["30213.6","0","0","0"],["30212.3","0","0","0"],["30212.2","0","0","0"],["30208.4","0.15617827","0","2"],["30205.6","2.204","0","1"],["30198.9","0","0","0"],["30198.3","0.16566405","0","1"],["30197.1","0","0","0"],["30194.9","0","0","0"],["30193.8","0.01643806","0","1"],["30191.9","0.06189011","0","1"],["30181.4","2.959","0","1"],["30178.7","0","0","0"],["30171.4","0.00003977","0","1"],["30167.4","0.24218825","0","2"],["30164.9","0.17481553","0","2"],["30083.4","0","0","0"],["29974.3","0.00001781","0","1"],["29972.6","0.00001014","0","1"]],"ts":"1652459232887","checksum":844379259}]}
1652459233.0168102: {"arg":{"channel":"books","instId":"UNI-USD-SWAP"},"action":"update","data":[{"asks":[["5.145","92","0","2"],["5.146","120","0","2"],["5.147","80","0","2"],["5.148","5","0","1"],["5.149","304","0","4"],["5.15","286","0","3"],["5.153","215","0","2"],["5.156","73","0","2"],["5.157","36","0","2"],["5.159","288","0","2"],["5.16","167","0","2"],["5.166","256","0","2"],["5.178","579","0","7"],["5.227","240","0","1"]],"bids":[["5.136","0","0","0"],["5.133","60","0","1"],["5.131","82","0","2"],["5.129","0","0","0"],["5.127","188","0","1"],["5.126","101","0","3"],["5.124","354","0","3"],["5.123","97","0","2"],["5.122","16","0","1"],["5.121","1912","0","3"],["5.117","122","0","2"],["5.113","45","0","1"],["5.112","231","0","1"]],"ts":"1652459232885","checksum":1549068618}]}
1652459233.1126664: {"arg":{"channel":"books","instId":"BTC-USD-220527"},"action":"update","data":[{"asks":[["30217.3","3","0","1"],["30219","604","0","1"],["30219.1","0","0","0"],["30221.9","0","0","0"],["30226.8","4","0","1"],["30242.1","0","0","0"],["30242.2","91","0","1"],["30579.8","2007","0","1"],["30607.7","0","0","0"],["30670.5","2009","0","1"],["30698.4","0","0","0"],["30761.1","2003","0","1"],["30789.1","0","0","0"],["30851.7","2003","0","1"],["30879.8","0","0","0"],["30942.4","2010","0","1"],["30970.5","0","0","0"]],"bids":[["30209.8","8","0","2"],["30197.4","100","0","1"],["30197","214","0","1"],["30180.4","0","0","0"],["30165.2","40","0","1"]],"ts":"1652459232994","checksum":1913339410}]}
1652459233.1130066: {"arg":{"channel":"books","instId":"BTC-USDT"},"action":"update","data":[{"asks":[["30230.3","2.1876975","0","10"],["30249.4","0.00121867","0","1"],["30252.7","0","0","0"],["30253","0","0","0"],["30295","0","0","0"],["30297.1","0.08255","0","1"],["30305","0","0","0"],["30634.4","0.00066689","0","1"],["30636","0.00004972","0","1"]],"bids":[["30221.5","0","0","0"],["30218.4","0.013882","0","2"],["30216.7","0","0","0"],["30213","0.12163604","0","1"],["30212.9","0","0","0"],["30211.7","0.160824","0","2"],["30210","0.03366203","0","2"],["30208.4","0.06617827","0","1"],["30207.2","0","0","0"],["30205.9","0.09","0","2"],["30205.2","0.00138968","0","1"],["30202.7","0.00165574","0","1"],["30200","16.39061501","0","59"],["30193.8","0","0","0"],["30193.2","0.08255","0","1"],["30192.9","0.10999945","0","1"],["30189","0.01643806","0","1"],["30187.5","0","0","0"],["30147.9","0.51511238","0","2"],["30119.9","0.16543747","0","1"],["30081.2","0.05126406","0","1"],["29975.4","0.00043973","0","1"],["29974.3","0","0","0"],["29972.6","0","0","0"]],"ts":"1652459232995","checksum":-625041613}]}
1652459233.1135156: {"arg":{"channel":"books","instId":"UNI-USD-SWAP"},"action":"update","data":[{"asks":[["5.143","560","0","3"],["5.144","25","0","1"],["5.145","20","0","1"],["5.146","140","0","3"],["5.147","0","0","0"],["5.148","41","0","2"],["5.149","268","0","3"],["5.153","220","0","2"]],"bids":[["5.135","0","0","0"],["5.134","0","0","0"],["5.133","85","0","2"],["5.131","5","0","1"],["5.13","0","0","0"],["5.127","200","0","2"],["5.126","114","0","3"],["5.125","266","0","1"],["5.123","57","0","1"],["5.122","56","0","2"]],"ts":"1652459232987","checksum":-1384533327}]}
1652459233.2263677: {"arg":{"channel":"trades","instId":"BTC-USDT"},"data":[{"instId":"BTC-USDT","tradeId":"338476351","px":"30230.2","sz":"0.001","side":"sell","ts":"1652459233099"}]}
1652459233.2264965: {"arg":{"channel":"trades","instId":"BTC-USDT"},"data":[{"instId":"BTC-USDT","tradeId":"338476352","px":"30230.2","sz":"0.01","side":"sell","ts":"1652459233099"}]}
1652459233.2265663: {"arg":{"channel":"trades","instId":"BTC-USDT"},"data":[{"instId":"BTC-USDT","tradeId":"338476353","px":"30230.2","sz":"0.0002","side":"sell","ts":"1652459233099"}]}
1652459233.2266276: {"arg":{"channel":"trades","instId":"BTC-USDT"},"data":[{"instId":"BTC-USDT","tradeId":"338476354","px":"30230.2","sz":"0.00275031","side":"sell","ts":"1652459233099"}]}
1652459233.2266798: {"arg":{"channel":"books","instId":"BTC-USD-220527"},"action":"update","data":[{"asks":[["30226.8","4","0","1"],["30242.1","0","0","0"],["30262.6","448","0","1"],["30267.3","20","0","1"]],"bids":[["30209.8","5","0","1"],["30197.4","103","0","2"],["30182","0","0","0"],["30165.2","40","0","1"],["30160.4","0","0","0"]],"ts":"1652459233109","checksum":2080609871}]}
1652459233.2270086: {"arg":{"channel":"books","instId":"BTC-USDT"},"action":"update","data":[{"asks":[["30230.3","4.94174778","0","13"],["30235","0.06523858","0","1"],["30236.2","0","0","0"],["30237","0","0","0"],["30249.3","0.0437353","0","2"],["30249.4","2.253","0","1"],["30249.5","0","0","0"],["30253.8","0.60466245","0","2"],["30256.3","0.05","0","1"],["30257.9","0.00034593","0","1"],["30259.8","0","0","0"],["30273.6","3.107","0","1"],["30636","0","0","0"]],"bids":[["30230.2","0.39724969","0","1"],["30223.1","0","0","0"],["30207.9","0.04945046","0","1"],["30205.9","0.03","0","1"],["30204.2","0","0","0"],["30201.8","0.24532244","0","2"],["30200","16.36561501","0","58"],["30192","0","0","0"],["30191.3","0.01643806","0","1"],["30189","0","0","0"],["30184.8","0.00154236","0","1"],["30181.4","0","0","0"],["30176.7","0.00260113","0","1"],["29980","0.00339344","0","2"],["29979.9","7.12144599","0","2"],["29978.9","0.00005058","0","1"],["29975.4","0","0","0"]],"ts":"1652459233110","checksum":-1968136797}]}
1652459233.227576: {"arg":{"channel":"books","instId":"UNI-USD-SWAP"},"action":"update","data":[{"asks":[["5.145","40","0","2"],["5.146","120","0","2"],["5.153","1259","0","3"]],"bids":[["5.134","99","0","1"],["5.133","25","0","1"],["5.132","292","0","3"],["5.127","188","0","1"],["5.126","140","0","4"],["5.125","0","0","0"],["5.123","292","0","1"],["5.122","54","0","2"],["5.12","108","0","2"]],"ts":"1652459233098","checksum":1890304130}]}
1652459233.2296643: {"arg":{"channel":"trades","instId":"BTC-USDT"},"data":[{"instId":"BTC-USDT","tradeId":"338476355","px":"30230.2","sz":"0.39724969","side":"sell","ts":"1652459233109"}]}
1652459233.22981: {"arg":{"channel":"trades","instId":"BTC-USDT"},"data":[{"instId":"BTC-USDT","tradeId":"338476356","px":"30230","sz":"0.033","side":"sell","ts":"1652459233109"}]}
1652459233.312487: {"arg":{"channel":"tickers","instId":"BTC-USDT"},"data":[{"instType":"SPOT","instId":"BTC-USDT","last":"30230","lastSz":"0.033","askPx":"30230.3","askSz":"1.92174778","bidPx":"30230.2","bidSz":"0.4112","open24h":"29700.4","high24h":"31073","low24h":"28020.3","sodUtc0":"29028.8","sodUtc8":"30337.7","volCcy24h":"525818028.47848234","vol24h":"17602.65803248","ts":"1652459233193"}]}
1652459233.3330622: {"arg":{"channel":"books","instId":"BTC-USD-220527"},"action":"update","data":[{"asks":[["30215.1","2","0","1"],["30215.2","0","0","0"],["30217","2","0","1"],["30217.1","0","0","0"],["30217.2","0","0","0"],["30217.3","0","0","0"],["30219","0","0","0"],["30221.9","0","0","0"],["30222","0","0","0"],["30226.8","0","0","0"],["30226.9","0","0","0"],["30229.5","4","0","1"],["30229.6","30","0","1"],["30240.3","217","0","2"],["30240.6","214","0","1"],["30242.1","0","0","0"],["30242.2","0","0","0"],["30242.3","0","0","0"],["30245.3","91","0","1"],["30245.4","11","0","1"],["30255.6","0","0","0"],["30279.6","12","0","1"],["30325","0","0","0"],["30344.2","18","0","1"],["30371.8","0","0","0"]],"bids":[["30197.5","0","0","0"],["30197.4","103","0","2"],["30197.3","0","0","0"],["30197","0","0","0"],["30186.5","4","0","1"],["30186.3","0","0","0"],["30183","0","0","0"],["30180.2","30","0","1"],["30180","0","0","0"],["30167.1","0","0","0"],["30167","11","0","1"],["30126.8","5358","0","1"]],"ts":"1652459233212","checksum":-640554400}]}
1652459233.3334148: {"arg":{"channel":"books","instId":"BTC-USDT"},"action":"update","data":[{"asks":[["30220.1","0.12867772","0","3"],["30220.2","0.053184","0","1"],["30220.3","0.08864","0","1"],["30220.4","0.124096","0","1"],["30220.5","0.159552","0","1"],["30222.5","0","0","0"],["30222.7","0.0132","0","1"],["30224.2","0","0","0"],["30227.2","0.16","0","1"],["30227.5","0.02447016","0","2"],["30227.6","3.31975031","0","4"],["30229.3","0.06523858","0","1"],["30230.1","0.23273","0","1"],["30230.2","0.8473","0","5"],["30230.3","0.87688097","0","5"],["30230.8","0","0","0"],["30232.3","0","0","0"],["30233.3","0","0","0"],["30235","0","0","0"],["30235.5","0.01","0","1"],["30239.9","0.04154872","0","1"],["30240","0.85661833","0","2"],["30240.1","0.26874509","0","4"],["30240.9","0.03308","0","1"],["30243.4","0","0","0"],["30243.9","0.0002","0","1"],["30245.9","0","0","0"],["30246.5","0","0","0"],["30247.4","0","0","0"],["30248.8","0","0","0"],["30249.3","0","0","0"],["30250.4","0.1326122","0","2"],["30251.5","0","0","0"],["30251.6","0","0","0"],["30254.5","0.883","0","1"],["30256.9","0","0","0"],["30257.6","0.037","0","1"],["30261.4","0.30845779","0","2"],["30263.4","0","0","0"],["30263.7","0","0","0"],["30263.9","0","0","0"],["30279","0","0","0"],["30284.7","0","0","0"],["30289.7","0.08255","0","1"],["30296","0","0","0"],["30297.1","0","0","0"],["30605.8","1.96041273","0","1"],["30608.9","0","0","0"],["30629.8","0.00010625","0","1"],["30630","0.09955051","0","4"],["30630.1","0.00001013","0","1"],["30630.3","0.00001158","0","1"],["30630.6","0.00105588","0","1"],["30631.1","0.09529384","0","1"],["30633.3","0","0","0"],["30634.4","0","0","0"]],"bids":[["30230.2","0","0","0"],["30230","0","0","0"],["30220","0.034","0","2"],["30218.4","0.000682","0","1"],["30216.1","0","0","0"],["30215.9","0","0","0"],["30214.8","0","0","0"],["30212.8","0.0132","0","1"],["30211.2","0","0","0"],["30209.3","0.33102388","0","1"],["30208.4","0","0","0"],["30207.4","0","0","0"],["30206.9","0.06618134","0","1"],["30204.9","0.02099","0","1"],["30204.5","0","0","0"],["30203.1","0.22","0","2"],["30201.6","0.09","0","1"],["30199","6.0718635","0","2"],["30197.4","0","0","0"],["30197.2","0.33115653","0","1"],["30194.9","0.33118175","0","1"],["30193.2","0","0","0"],["30192.9","0","0","0"],["30190.6","0.557","0","1"],["30187.8","0.08126666","0","2"],["30187.5","0.08255","0","1"],["30186.5","0.13236573","0","1"],["30185.5","0.05","0","1"],["30184.5","0.037","0","1"],["30182.9","0","0","0"],["30178.6","0.58799999","0","1"],["30176.6","1.0010008","0","2"],["30129.1","0","0","0"],["30057.9","3.5347","0","1"],["29975.4","0.00043973","0","1"],["29974.3","0.00001781","0","1"],["29972.6","0","0","0"],["29971.2","0","0","0"],["29970","0","0","0"]],"ts":"1652459233221","checksum":905940420}]}
1652459233.3346303: {"arg":{"channel":"books","instId":"UNI-USD-SWAP"},"action":"update","data":[{"asks":[["5.143","500","0","2"],["5.144","76","0","2"]],"bids":[["5.132","256","0","3"],["5.126","125","0","4"],["5.125","38","0","1"],["5.123","292","0","1"],["5.122","16","0","1"],["5.118","12415","0","3"]],"ts":"1652459233212","checksum":1116283235}]}
1652459233.4465373: {"arg":{"channel":"books","instId":"BTC-USD-220527"},"action":"update","data":[{"asks":[["30229.5","4","0","1"],["30240.1","0","0","0"],["30240.2","91","0","1"],["30240.3","3","0","1"],["30240.5","91","0","1"],["30245.3","0","0","0"],["31126.7","6","0","1"],["31137.2","0","0","0"]],"bids":[["30197.4","0","0","0"],["30194.7","100","0","1"],["30191.9","4","0","1"],["30191.8","100","0","1"],["30191.7","214","0","1"],["30191.2","214","0","1"],["30186.5","0","0","0"],["30186.4","0","0","0"],["30183.1","0","0","0"],["30183","100","0","1"],["30165.2","0","0","0"],["30164.4","448","0","1"],["30158.6","40","0","1"],["29323.3","0","0","0"],["29313.4","5","0","1"]],"ts":"1652459233318","checksum":645485807}]}
1652459233.4468358: {"arg":{"channel":"books","instId":"BTC-USDT"},"action":"update","data":[{"asks":[["30228.8","0","0","0"],["30229.3","0.06523858","0","1"],["30235.4","0.02499523","0","1"],["30239.8","0.00040434","0","1"],["30247.7","0.33","0","4"],["30261.9","0","0","0"],["30289.7","0","0","0"],["30300.3","0.08255","0","1"],["30301.7","1.67925313","0","1"],["30312","0","0","0"],["30328.9","1.66949061","0","1"],["30339.2","0.00002071","0","1"],["30356.1","1.65765455","0","1"],["30366.4","0","0","0"],["30582.8","6.55205482","0","1"],["30607.4","0","0","0"],["30630.3","0","0","0"],["30630.6","0","0","0"],["30631.1","0","0","0"]],"bids":[["30220","0.0442","0","4"],["30211.7","0.16","0","1"],["30209.7","2.186","0","1"],["30208.7","0","0","0"],["30202","0.15","0","1"],["30201.8","0.09532244","0","1"],["30200.1","0.78311931","0","2"],["30191.3","0","0","0"],["30189.6","0","0","0"],["30188.8","0.01643806","0","1"],["30148.5","0","0","0"],["30138.4","1.68894199","0","1"],["30121.3","0","0","0"],["30111.2","1.67902674","0","1"],["30094.1","0","0","0"],["30084","1.68081994","0","3"],["29972.6","0","0","0"]],"ts":"1652459233326","checksum":841758129}]}
1652459233.4472861: {"arg":{"channel":"books","instId":"UNI-USD-SWAP"},"action":"update","data":[{"asks":[["5.141","20","0","1"],["5.142","51","0","1"],["5.144","25","0","1"],["5.145","20","0","1"],["5.153","1231","0","2"],["5.154","1824","0","1"],["5.158","12044","0","4"]],"bids":[["5.134","176","0","2"],["5.132","232","0","2"],["5.126","125","0","4"],["5.125","38","0","1"]],"ts":"1652459233316","checksum":1690684742}]}
1652459233.5555792: {"arg":{"channel":"books","instId":"BTC-USD-220527"},"action":"update","data":[{"asks":[["30250.4","0","0","0"],["30267.3","0","0","0"]],"bids":[["30209.9","0","0","0"],["30194.7","100","0","1"],["30132.1","0","0","0"]],"ts":"1652459233443","checksum":-1462744393}]}
1652459233.5557683: {"arg":{"channel":"books","instId":"BTC-USDT"},"action":"update","data":[{"asks":[["30220.1","0.36140772","0","4"],["30227.2","0","0","0"],["30228.6","0.06523858","0","1"],["30229.3","0","0","0"],["30230.1","0","0","0"],["30230.3","0.64415097","0","4"],["30231.5","0.05","0","1"],["30239.8","0","0","0"],["30252.6","0","0","0"],["30253.1","0.00962619","0","1"],["30258.3","0","0","0"],["30277.5","0.06738112","0","2"],["30297","2.47208898","0","2"],["30302.4","0","0","0"],["30360","0.2184954","0","4"],["30420","0.39651239","0","3"],["30532.4","1.96512557","0","1"],["30605.8","0","0","0"],["30630.3","0.00001158","0","1"],["30630.6","0.00105588","0","1"],["30631.1","0.09529384","0","1"],["30633.3","0.00073181","0","2"],["30634.4","0","0","0"]],"bids":[["30219.9","0.05048609","0","1"],["30210.4","0.00603281","0","1"],["30208.7","0.000824","0","1"],["30197.7","0","0","0"],["30195.1","0","0","0"],["30192.5","0.00860344","0","1"],["30190.3","0.01643806","0","1"],["30188.8","0","0","0"],["30186.9","0","0","0"],["30172.7","0.24853637","0","1"],["29975.4","0.00043973","0","1"],["29974.3","0","0","0"]],"ts":"1652459233440","checksum":1273327650}]}
1652459233.5560617: {"arg":{"channel":"books","instId":"UNI-USD-SWAP"},"action":"update","data":[{"asks":[["5.142","192","0","1"],["5.144","76","0","2"],["5.145","70","0","2"],["5.153","192","0","1"],["5.154","1859","0","2"],["5.157","1","0","1"]],"bids":[["5.128","2519","0","4"],["5.126","163","0","5"],["5.125","0","0","0"],["5.117","87","0","1"],["5.114","198","0","2"]],"ts":"1652459233438","checksum":34788614}]}
1652459233.5943475: {"arg":{"channel":"trades","instId":"BTC-USDT"},"data":[{"instId":"BTC-USDT","tradeId":"338476357","px":"30220.1","sz":"0.0001","side":"buy","ts":"1652459233476"}]}
1652459233.6713772: {"arg":{"channel":"books","instId":"BTC-USDT"},"action":"update","data":[{"asks":[["30220.1","0.36130772","0","4"],["30224.3","0.0229","0","1"],["30226.3","0.16","0","1"],["30227.8","0.06523858","0","1"],["30228.6","0","0","0"],["30231.4","0.1","0","1"],["30244.6","0.33","0","4"],["30247.7","0","0","0"],["30260.7","0","0","0"],["30277.5","0.0012","0","1"],["30291","0.93259972","0","3"],["30294","0","0","0"],["30297","2.31208898","0","1"],["30300.3","0","0","0"],["30633.3","0.00073181","0","2"],["30634.4","0","0","0"]],"bids":[["30219.9","0","0","0"],["30214.3","0","0","0"],["30210.3","0.05","0","1"],["30209.3","0.40218612","0","2"],["30206.9","0","0","0"],["30206.2","0","0","0"],["30205.9","0","0","0"],["30203.1","0.16","0","1"],["30202","0","0","0"],["30201.6","0","0","0"],["30201.3","0.03","0","1"],["30200.6","0","0","0"],["30198.8","0","0","0"],["30198.7","0.06","0","1"],["30198.4","0.24582075","0","1"],["30197.9","0","0","0"],["30197.4","0.09","0","1"],["30196.9","0.15","0","1"],["30195.4","0","0","0"],["30194.9","0.05676962","0","1"],["30190.7","0.01643806","0","1"],["30190.3","0","0","0"],["30176.4","0.00983197","0","2"],["30135.3","0","0","0"],["30105.2","0","0","0"],["29974.3","0.00001781","0","1"],["29972.6","0.00001014","0","1"],["29971.2","0.00453815","0","1"],["29970","0.00066733","0","1"],["29968","0.0143533","0","2"]],"ts":"1652459233547","checksum":1965631776}]}
1652459233.6717947: {"arg":{"channel":"books","instId":"UNI-USD-SWAP"},"action":"update","data":[{"asks":[["5.142","258","0","2"],["5.143","500","0","2"],["5.144","31","0","2"],["5.152","0","0","0"]],"bids":[["5.132","231","0","1"],["5.126","125","0","4"],["5.123","292","0","1"],["5.122","54","0","2"]],"ts":"1652459233554","checksum":-1024094545}]}
1652459233.6719148: {"arg":{"channel":"books","instId":"BTC-USD-220527"},"action":"update","data":[{"asks":[["30211.9","3","0","1"],["30213.2","2","0","1"],["30213.3","0","0","0"],["30214.9","2","0","1"],["30215","0","0","0"],["30215.1","0","0","0"],["30217","0","0","0"],["30229.5","95","0","2"],["30240.2","0","0","0"],["30240.3","0","0","0"],["30240.5","0","0","0"],["30240.6","0","0","0"],["30245.3","91","0","1"]],"bids":[["30209.8","0","0","0"],["30202.5","65","0","1"],["30202.4","3","0","1"],["30194.9","100","0","1"],["30194.8","0","0","0"],["30194.7","0","0","0"],["30191.8","0","0","0"],["30191.7","0","0","0"],["30191.2","0","0","0"],["30183.6","5","0","1"],["30183","100","0","1"]],"ts":"1652459233548","checksum":1174321362}]}
1652459233.69016: {"arg":{"channel":"tickers","instId":"BTC-USDT"},"data":[{"instType":"SPOT","instId":"BTC-USDT","last":"30220.1","lastSz":"0.0001","askPx":"30230.3","askSz":"1.92174778","bidPx":"30230.2","bidSz":"0.4112","open24h":"29700.4","high24h":"31073","low24h":"28020.3","sodUtc0":"29028.8","sodUtc8":"30337.7","volCcy24h":"525818031.50049234","vol24h":"17602.65813248","ts":"1652459233557"}]}
1652459233.7816622: {"arg":{"channel":"books","instId":"BTC-USD-220527"},"action":"update","data":[{"asks":[["30211.5","0","0","0"],["30211.9","0","0","0"],["30213.2","0","0","0"],["30214.9","0","0","0"],["30215.6","2","0","1"],["30215.7","0","0","0"],["30215.8","0","0","0"],["30217.2","0","0","0"],["30229.3","4","0","1"],["30229.4","0","0","0"],["30229.5","91","0","1"],["30239.2","214","0","1"],["30245.3","91","0","1"]],"bids":[["30210","0","0","0"],["30209.8","0","0","0"],["30204.1","3","0","1"],["30202.5","0","0","0"],["30202.4","0","0","0"],["30195","0","0","0"],["30194.9","0","0","0"],["30194.6","0","0","0"],["30191.9","0","0","0"],["30190.5","0","0","0"],["30190.3","0","0","0"],["30188.5","104","0","2"],["30188.4","171","0","1"],["30183.7","0","0","0"],["30183","100","0","1"],["30164.4","0","0","0"],["29874.1","0","0","0"],["29840.1","2000","0","1"],["29783.3","0","0","0"],["29749.4","2010","0","1"],["29692.6","0","0","0"],["29658.8","2001","0","1"],["29601.9","0","0","0"],["29568.2","2007","0","1"],["29511.2","0","0","0"],["29477.6","2008","0","1"]],"ts":"1652459233659","checksum":-1033089571}]}
1652459233.7823086: {"arg":{"channel":"books","instId":"BTC-USDT"},"action":"update","data":[{"asks":[["30237.2","0.03309","0","1"],["30238.4","0","0","0"],["30240.9","0","0","0"],["30273","0.06619054","0","1"],["30282","0.07108013","0","1"],["30291","0.85004972","0","2"],["30303.1","0.08255","0","1"],["30630.3","0.00001158","0","1"],["30630.6","0","0","0"],["30631.1","0","0","0"],["30633.3","0","0","0"]],"bids":[["30209.7","0.025","0","1"],["30209","0.09906","0","1"],["30208.7","0","0","0"],["30204.9","0","0","0"],["30202.4","0.06619076","0","1"],["30201.2","0.021","0","1"],["30199.1","0.33113569","0","1"],["30198.1","0.15","0","1"],["30196.9","0","0","0"],["30196.7","0.08255","0","1"],["30190.7","0.33122782","0","1"],["30190.2","0","0","0"],["30187.5","0","0","0"],["30187","0.01643806","0","1"],["30185.9","0.06314904","0","3"],["30182.8","0","0","0"],["30042.2","0.00034593","0","1"],["29970","0","0","0"],["29968","0","0","0"],["29966.6","0","0","0"],["29966","0","0","0"]],"ts":"1652459233664","checksum":-382848977}]}
1652459233.7827687: {"arg":{"channel":"books","instId":"UNI-USD-SWAP"},"action":"update","data":[{"asks":[["5.142","192","0","1"],["5.144","97","0","3"]],"bids":[],"ts":"1652459233605","checksum":-373698773}]}
1652459233.895482: {"arg":{"channel":"books","instId":"BTC-USD-220527"},"action":"update","data":[{"asks":[["30210.7","0","0","0"],["30213.4","0","0","0"],["30214","3","0","1"],["30215.6","0","0","0"],["30229.3","671","0","1"],["30229.4","4","0","1"],["30229.5","91","0","1"],["30239","0","0","0"],["30239.1","91","0","1"],["30245.3","91","0","1"],["30246.3","0","0","0"]],"bids":[["30206.8","0","0","0"],["30204.1","0","0","0"],["30203.3","0","0","0"],["30203.1","0","0","0"],["30201.9","65","0","1"],["30195.3","100","0","1"],["30195.2","155","0","2"],["30195.1","0","0","0"],["30195","0","0","0"],["30190.7","0","0","0"],["30190.6","0","0","0"],["30190.5","104","0","2"],["30190.4","214","0","1"],["30190.2","214","0","1"],["30188.8","100","0","1"],["30188.7","171","0","1"],["30188.6","0","0","0"],["30188.5","0","0","0"],["30188.4","0","0","0"],["30183","100","0","1"],["30155.7","461","0","1"],["30038.9","0","0","0"],["30020.7","510","0","1"],["29978.4","0","0","0"],["29960.3","505","0","1"],["29918","0","0","0"],["29899.9","504","0","1"]],"ts":"1652459233775","checksum":-1914924362}]}
1652459233.8960834: {"arg":{"channel":"books","instId":"BTC-USDT"},"action":"update","data":[{"asks":[["30224.1","0.001784","0","1"],["30224.3","0","0","0"],["30227.4","0.06523858","0","1"],["30227.8","0","0","0"],["30231.9","0.635","0","1"],["30235.5","0","0","0"],["30238.4","0","0","0"],["30238.5","0","0","0"],["30239.3","0","0","0"],["30283.3","0","0","0"],["30532.4","0","0","0"],["30605.8","1.96041273","0","1"],["30630.6","0.00105588","0","1"],["30631.1","0.09529384","0","1"],["30633.3","0","0","0"]],"bids":[["30214","0.01","0","1"],["30212.9","0.01","0","1"],["30210.4","0","0","0"],["30204.8","0.000824","0","1"],["30190.6","0","0","0"],["30187.1","0","0","0"],["30187","0.01643806","0","1"],["30184.4","0.557","0","1"],["30176.6","4.1190008","0","3"],["30125.1","0.01383552","0","1"],["30081.2","0","0","0"],["30059.3","0.05126674","0","1"],["29974.3","0","0","0"],["29972.6","0","0","0"],["29971.2","0","0","0"],["29970","0","0","0"]],"ts":"1652459233769","checksum":-558205821}]}
1652459233.8965344: {"arg":{"channel":"books","instId":"UNI-USD-SWAP"},"action":"update","data":[{"asks":[["5.142","318","0","3"],["5.143","500","0","2"],["5.144","31","0","2"],["5.149","208","0","2"]],"bids":[["5.126","169","0","5"],["5.125","0","0","0"],["5.122","16","0","1"],["5.118","12351","0","2"],["5.115","64","0","1"]],"ts":"1652459233728","checksum":599334326}]}
1652459234.0020843: {"arg":{"channel":"books","instId":"BTC-USD-220527"},"action":"update","data":[{"asks":[["30214","0","0","0"],["30217.8","0","0","0"],["30229.1","0","0","0"],["30229.2","4","0","1"],["30229.3","0","0","0"],["30229.4","0","0","0"],["30229.5","0","0","0"],["30239","0","0","0"],["30239.1","91","0","1"],["30245.3","91","0","1"],["30250.7","0","0","0"],["30262.6","0","0","0"],["30279.6","31","0","2"]],"bids":[["30208.6","0","0","0"],["30207","3","0","1"],["30202","4","0","1"],["30195.4","0","0","0"],["30195.3","0","0","0"],["30195.2","0","0","0"],["30190.6","0","0","0"],["30190.5","100","0","1"],["30188.8","0","0","0"],["30186.6","19","0","1"],["30183","100","0","1"],["30156.6","0","0","0"]],"ts":"1652459233887","checksum":1052254703}]}
1652459234.0024836: {"arg":{"channel":"books","instId":"BTC-USDT"},"action":"update","data":[{"asks":[["30225.4","0.09999997","0","1"],["30239.3","0","0","0"],["30249.4","0","0","0"],["30273.6","0","0","0"],["30287.5","0.5","0","1"],["30311.2","0","0","0"],["30631.1","0.09529384","0","1"],["30633.3","0.00073181","0","2"],["30634.4","0","0","0"]],"bids":[["30209.7","0","0","0"],["30200","16.29704924","0","57"],["30198.1","0","0","0"],["30187.9","0.01643806","0","1"],["30187","0","0","0"],["29974.3","0.00001781","0","1"],["29972.6","0.00001014","0","1"]],"ts":"1652459233884","checksum":-1969219369}]}
1652459234.0027452: {"arg":{"channel":"books","instId":"UNI-USD-SWAP"},"action":"update","data":[{"asks":[],"bids":[["5.126","114","0","3"],["5.125","113","0","2"]],"ts":"1652459233840","checksum":1367146138}]}
1652459234.11066: {"arg":{"channel":"books","instId":"BTC-USD-220527"},"action":"update","data":[{"asks":[["30212.7","0","0","0"],["30214.1","3","0","1"],["30217.9","2","0","1"],["30218","0","0","0"],["30229.1","0","0","0"],["30229.2","0","0","0"],["30229.5","95","0","2"],["30239.1","0","0","0"],["30239.2","0","0","0"],["30245.3","91","0","1"],["30250.7","0","0","0"]],"bids":[["30210.6","0","0","0"],["30207","0","0","0"],["30205","3","0","1"],["30202","0","0","0"],["30201.9","0","0","0"],["30190.6","4","0","1"],["30190.5","100","0","1"],["30190.4","0","0","0"],["30190.2","0","0","0"],["30188.8","100","0","1"],["30186.7","0","0","0"],["30183","100","0","1"]],"ts":"1652459233989","checksum":-2125100254}]}
1652459234.1111586: {"arg":{"channel":"books","instId":"BTC-USDT"},"action":"update","data":[{"asks":[["30227.4","0","0","0"],["30227.9","0","0","0"],["30228.2","0.06523858","0","1"],["30229.2","2.254","0","1"],["30244","0.33064409","0","1"],["30253.8","0.27412546","0","1"],["30272.7","0","0","0"],["30273","0.06627199","0","2"],["30293.4","0","0","0"],["30297.6","0.08255","0","1"],["30303.1","0","0","0"],["30312","0.1654621","0","1"],["30340","0.09933514","0","5"],["30633.3","0","0","0"],["30634.4","0","0","0"],["30636","0","0","0"]],"bids":[["30217.2","0.05075408","0","1"],["30214","0","0","0"],["30213","0","0","0"],["30212.9","0","0","0"],["30209","0","0","0"],["30206.7","0.1216614","0","1"],["30197.9","0","0","0"],["30197.8","0.06861746","0","1"],["30195.3","0.15","0","1"],["30194.2","0.16","0","1"],["30192.5","0","0","0"],["30190.9","0","0","0"],["30189.1","0.01643806","0","1"],["30188.7","0","0","0"],["30187.9","0","0","0"],["30186.6","0.00874049","0","1"],["30185.4","0","0","0"],["30184.6","2.31208898","0","1"],["30178.3","0.06","0","1"],["30176.5","0.48","0","1"],["30167.9","0","0","0"],["30167.4","0.00218825","0","1"],["30164.3","0.01315522","0","1"],["30159.7","0.24","0","1"],["29975.4","0.00043973","0","1"],["29974.3","0.00001781","0","1"],["29972.6","0","0","0"],["29971.2","0","0","0"],["29970","0","0","0"],["29968","0","0","0"]],"ts":"1652459233999","checksum":-999717402}]}
1652459234.1119316: {"arg":{"channel":"books","instId":"UNI-USD-SWAP"},"action":"update","data":[{"asks":[],"bids":[["5.126","158","0","4"],["5.125","69","0","1"],["5.111","3610","0","1"]],"ts":"1652459233954","checksum":2105417529}]}
1652459234.222758: {"arg":{"channel":"books","instId":"BTC-USDT"},"action":"update","data":[{"asks":[["30220.1","0.12857772","0","3"],["30227.8","0","0","0"],["30228.2","0","0","0"],["30228.9","0.06523858","0","1"],["30229.2","0","0","0"],["30239.3","0.24797347","0","1"],["30244.1","0.05026773","0","1"],["30247.2","0.00879096","0","1"],["30248.9","0.76389863","0","1"],["30253.1","0","0","0"],["30253.6","3.024","0","1"],["30263.8","0.03211724","0","1"],["30265.7","2.45112","0","1"],["30273","2.51758199","0","3"],["30274.6","2.45131","0","1"],["30629.8","0","0","0"],["30630","0","0","0"],["30630.1","0","0","0"],["30630.3","0","0","0"],["30630.6","0","0","0"],["30631.1","0","0","0"]],"bids":[["30217.2","0","0","0"],["30203.9","0.01852827","0","1"],["30195","0.03036972","0","1"],["30189.1","0","0","0"],["30188","0","0","0"],["30187","0.01643806","0","1"],["30139.2","2.44961","0","1"],["30126.3","4.90024102","0","3"],["29974.3","0","0","0"],["29972.6","0","0","0"]],"ts":"1652459234105","checksum":1412645410}]}
1652459234.223133: {"arg":{"channel":"books","instId":"BTC-USD-220527"},"action":"update","data":[{"asks":[["30214.1","0","0","0"],["30229.5","4","0","1"],["30238.5","0","0","0"],["30238.6","0","0","0"],["30245.3","0","0","0"],["30250.7","91","0","1"]],"bids":[["30205.1","4","0","1"],["30190.6","0","0","0"],["30190.5","0","0","0"],["30188.8","100","0","1"],["30186.6","0","0","0"]],"ts":"1652459234104","checksum":-913620749}]}
1652459234.2233052: {"arg":{"channel":"books","instId":"UNI-USD-SWAP"},"action":"update","data":[{"asks":[["5.142","252","0","2"],["5.143","500","0","2"],["5.144","119","0","3"]],"bids":[["5.126","114","0","3"],["5.125","126","0","2"]],"ts":"1652459234058","checksum":-1148335385}]}
1652459234.3306913: {"arg":{"channel":"books","instId":"BTC-USD-220527"},"action":"update","data":[{"asks":[["30216.5","0","0","0"],["30229.5","0","0","0"],["30241.4","4","0","1"],["30241.5","217","0","2"],["30245.2","4","0","1"],["30245.3","91","0","1"],["30250.7","94","0","1"],["30279.5","94","0","1"]],"bids":[["30209","4","0","1"],["30208.9","3","0","1"],["30205.1","0","0","0"],["30205","0","0","0"],["30192.7","214","0","1"],["30192.5","214","0","1"],["30188.9","0","0","0"]],"ts":"1652459234219","checksum":-1069344291}]}
1652459234.3310316: {"arg":{"channel":"books","instId":"BTC-USDT"},"action":"update","data":[{"asks":[["30222.7","0","0","0"],["30224.1","0.00373083","0","2"],["30225.4","0.11319997","0","2"],["30226.3","0","0","0"],["30227.3","0.01","0","1"],["30228.5","0.06523858","0","1"],["30228.9","0","0","0"],["30239.2","0.00265453","0","1"],["30247.2","0","0","0"],["30247.7","0.7100615","0","1"],["30252.7","0.00954403","0","1"],["30253.6","0","0","0"],["30265.5","0.25","0","1"],["30278.7","0","0","0"],["30629.6","0.00045906","0","1"],["30629.8","0","0","0"]],"bids":[["30213.4","0.0256717","0","2"],["30213.1","0.01145","0","1"],["30213","0.01","0","1"],["30212","0.01","0","1"],["30209.7","0.12164933","0","1"],["30192.1","0.0068079","0","1"],["30190.8","0.01643806","0","1"],["30190.7","0.33122782","0","1"],["30187","0","0","0"],["30186.6","0","0","0"],["30180.9","0.00006806","0","1"],["30176.6","1.0010008","0","2"],["30167.9","0.16546429","0","1"],["30167","0.25","0","1"],["30150","0.06781283","0","9"],["29983","0","0","0"],["29982.5","0","0","0"],["29982.2","0","0","0"],["29980","0","0","0"],["29979.9","0","0","0"],["29978.9","0","0","0"],["29975.4","0","0","0"]],"ts":"1652459234210","checksum":2005324353}]}
1652459234.3328252: {"arg":{"channel":"books","instId":"UNI-USD-SWAP"},"action":"update","data":[{"asks":[],"bids":[["5.126","114","0","3"],["5.125","126","0","2"],["5.123","292","0","1"]],"ts":"1652459234179","checksum":-1148335385}]}
1652459234.4476657: {"arg":{"channel":"books","instId":"BTC-USDT"},"action":"update","data":[{"asks":[["30220.3","0","0","0"],["30220.5","0","0","0"],["30225.4","0.0132","0","1"],["30227.3","0","0","0"],["30228.5","0","0","0"],["30229","0.06523858","0","1"],["30239.2","0.00173302","0","1"],["30241.9","2.376","0","1"],["30247.7","0","0","0"],["30248.9","0.76389863","0","1"],["30252.9","0.24984","0","2"],["30260.8","0","0","0"],["30629.8","0.00010625","0","1"],["30630","0.09955051","0","4"],["30630.1","0.00001013","0","1"],["30630.3","0.00001158","0","1"]],"bids":[["30216.9","0.16","0","1"],["30199.6","2.35004496","0","2"],["30198.8","0.15","0","1"],["30197.4","0","0","0"],["30196.4","0.1","0","1"],["30195.3","0","0","0"],["30190.8","0","0","0"],["30187.6","0.01643806","0","1"],["30187.5","0","0","0"],["30187.4","0.0006249","0","2"],["29983.1","0","0","0"],["29983","0","0","0"],["29982.5","0","0","0"]],"ts":"1652459234322","checksum":1851309015}]}
1652459234.4479935: {"arg":{"channel":"books","instId":"BTC-USD-220527"},"action":"update","data":[{"asks":[["30217.6","3","0","1"],["30217.8","695","0","1"],["30241.4","0","0","0"],["30241.5","0","0","0"],["30245.2","4","0","1"],["30245.3","0","0","0"]],"bids":[["30211.8","4","0","1"],["30211.7","0","0","0"],["30209","0","0","0"],["30208.9","0","0","0"],["30192.9","0","0","0"],["30192.8","100","0","1"],["30192.6","100","0","1"],["30188.8","0","0","0"],["30188.7","0","0","0"]],"ts":"1652459234327","checksum":-911730096}]}
1652459234.4481544: {"arg":{"channel":"books","instId":"UNI-USD-SWAP"},"action":"update","data":[{"asks":[["5.142","340","0","3"],["5.144","31","0","2"]],"bids":[["5.134","196","0","3"]],"ts":"1652459234242","checksum":1645008242}]}
1652459234.454519: {"arg":{"channel":"trades","instId":"BTC-USD-220527"},"data":[{"instId":"BTC-USD-220527","tradeId":"7850","px":"30217.7","sz":"2","side":"buy","ts":"1652459234339"}]}
1652459234.4546452: {"arg":{"channel":"trades","instId":"BTC-USD-220527"},"data":[{"instId":"BTC-USD-220527","tradeId":"7851","px":"30217.9","sz":"2","side":"buy","ts":"1652459234340"}]}
1652459234.4714751: {"arg":{"channel":"trades","instId":"BTC-USD-220527"},"data":[{"instId":"BTC-USD-220527","tradeId":"7852","px":"30229.6","sz":"30","side":"buy","ts":"1652459234354"}]}
1652459234.512934: {"arg":{"channel":"trades","instId":"BTC-USDT"},"data":[{"instId":"BTC-USDT","tradeId":"338476358","px":"30220.1","sz":"0.00185972","side":"buy","ts":"1652459234399"}]}
1652459234.5130694: {"arg":{"channel":"trades","instId":"BTC-USDT"},"data":[{"instId":"BTC-USDT","tradeId":"338476359","px":"30220.1","sz":"0.01648681","side":"buy","ts":"1652459234399"}]}
1652459234.51994: {"arg":{"channel":"tickers","instId":"BTC-USDT"},"data":[{"instType":"SPOT","instId":"BTC-USDT","last":"30220.1","lastSz":"0.00185972","askPx":"30230.3","askSz":"1.92174778","bidPx":"30230.2","bidSz":"0.4112","open24h":"29700.4","high24h":"31073","low24h":"28020.3","sodUtc0":"29028.8","sodUtc8":"30337.7","volCcy24h":"525818585.9344636","vol24h":"17602.67647901","ts":"1652459234403"}]}
1652459234.5549307: {"arg":{"channel":"trades","instId":"BTC-USDT"},"data":[{"instId":"BTC-USDT","tradeId":"338476360","px":"30224.1","sz":"0.001784","side":"buy","ts":"1652459234432"}]}
1652459234.5550776: {"arg":{"channel":"trades","instId":"BTC-USDT"},"data":[{"instId":"BTC-USDT","tradeId":"338476361","px":"30224.1","sz":"0.00194683","side":"buy","ts":"1652459234432"}]}
1652459234.5551171: {"arg":{"channel":"books","instId":"BTC-USDT"},"action":"update","data":[{"asks":[["30220.1","0","0","0"],["30220.2","0","0","0"],["30220.4","0","0","0"],["30224.1","0","0","0"],["30225.4","0","0","0"],["30226.3","0","0","0"],["30227.5","0.00798335","0","1"],["30227.6","2.91975031","0","3"],["30229","0","0","0"],["30229.4","0","0","0"],["30229.5","0.0132","0","1"],["30230.2","0.00005","0","1"],["30230.3","0","0","0"],["30231.5","0","0","0"],["30233.1","0.04843473","0","1"],["30233.4","0","0","0"],["30239.2","0","0","0"],["30239.8","0","0","0"],["30239.9","0","0","0"],["30240","0.85","0","1"],["30240.1","0.24974509","0","3"],["30241.3","0","0","0"],["30241.9","0","0","0"],["30244.6","0","0","0"],["30245.4","0.00755245","0","1"],["30250.3","0","0","0"],["30251.1","0.7100615","0","1"],["30251.9","0.03","0","1"],["30252.5","0.06","0","1"],["30252.7","0","0","0"],["30253","0.09","0","1"],["30253.7","0.15","0","1"],["30253.9","0","0","0"],["30256.3","0","0","0"],["30256.7","0.08","0","1"],["30257","0","0","0"],["30257.6","0","0","0"],["30261.1","0.197","0","2"],["30266.4","0","0","0"],["30289.6","0","0","0"],["30630.6","0.00105588","0","1"],["30631.1","0.09529384","0","1"],["30633.3","0.00073181","0","2"],["30634.4","0.00066689","0","1"],["30636","0.00004972","0","1"],["30636.3","0.00008138","0","1"],["30636.7","0.00155815","0","2"],["30637.9","0.00012767","0","1"],["30638.9","0.0019984","0","1"]],"bids":[["30224","0.21323061","0","4"],["30223.8","0.04","0","1"],["30223.4","0.16","0","1"],["30220.2","0.02358755","0","2"],["30220.1","0.14118347","0","2"],["30220","0.73999","0","6"],["30219.7","0.052","0","1"],["30217.3","0.05293126","0","1"],["30216.9","0.16","0","1"],["30214.2","0.07115978","0","1"],["30213.4","0.05452","0","1"],["30213","0","0","0"],["30212.8","0","0","0"],["30212","0","0","0"],["30209.7","0","0","0"],["30209.3","0.33102388","0","1"],["30206.7","0","0","0"],["30205.6","0","0","0"],["30204.4","0.06","0","1"],["30204.2","0.24","0","2"],["30203.3","0","0","0"],["30201.3","0","0","0"],["30201.1","0.00662203","0","1"],["30200.2","0","0","0"],["30198.8","0","0","0"],["30198.7","0","0","0"],["30192.1","0","0","0"],["30190.7","0","0","0"],["30190.1","0.49123441","0","2"],["30188.9","0.10999563","0","1"],["30187.9","0.01643806","0","1"],["30187.8","0.08126666","0","2"],["30187.6","0","0","0"],["30186.5","0","0","0"],["30184.4","0.5650794","0","2"],["30184","0.48","0","1"],["30183.4","0.58799999","0","1"],["30178.6","0","0","0"],["30176.5","0","0","0"],["30172.5","0.00025","0","1"],["30167.9","0","0","0"],["30159.7","0","0","0"],["30107.9","0.16548127","0","1"],["30053.7","1.04847887","0","1"],["29983.3","0.00106016","0","1"],["29983.1","0","0","0"],["29983","0","0","0"],["29982.5","0","0","0"],["29982.2","0","0","0"],["29980","0","0","0"],["29979.9","0","0","0"],["29978.9","0","0","0"],["29975.4","0","0","0"],["29974.3","0","0","0"],["29972.6","0","0","0"]],"ts":"1652459234437","checksum":1733853992}]}
1652459234.5557835: {"arg":{"channel":"books","instId":"BTC-USD-220527"},"action":"update","data":[{"asks":[["30217.6","0","0","0"],["30217.7","0","0","0"],["30217.8","0","0","0"],["30217.9","0","0","0"],["30219.6","0","0","0"],["30223.2","0","0","0"],["30229.6","0","0","0"],["30245","0","0","0"],["30245.1","214","0","1"],["30245.2","0","0","0"],["30245.3","94","0","1"],["30245.4","0","0","0"],["30250.7","0","0","0"],["30251.7","0","0","0"],["30252.5","11","0","1"],["30254.2","20","0","1"],["30279.4","4","0","1"],["30279.5","94","0","1"],["30279.6","19","0","1"],["30280.5","1","0","1"],["30316.1","0","0","0"],["30344.2","0","0","0"],["30407.3","0","0","0"],["30426.5","508","0","1"],["30467.7","202","0","1"],["30486.9","508","0","1"],["30528.2","0","0","0"],["30547.3","505","0","1"],["30579.8","0","0","0"],["30607.8","2003","0","1"],["30670.5","0","0","0"],["30698.4","2006","0","1"],["30761.1","0","0","0"],["30789.1","2009","0","1"],["30851.7","0","0","0"],["30879.8","2001","0","1"],["30942.4","0","0","0"],["30970.4","2006","0","1"]],"bids":[["30211.8","0","0","0"],["30195.9","2","0","1"],["30195.8","2","0","1"],["30195.7","0","0","0"],["30193.3","104","0","2"],["30193.2","192","0","3"],["30193.1","0","0","0"],["30193","0","0","0"],["30192.9","0","0","0"],["30192.8","0","0","0"],["30192.7","0","0","0"],["30192.6","0","0","0"],["30192.5","0","0","0"],["30184.1","785","0","1"],["30184","30","0","1"],["30183","0","0","0"],["30180.2","0","0","0"],["30173.9","0","0","0"],["30167.1","766","0","1"],["30158.6","0","0","0"],["30155.7","0","0","0"],["30138.2","19","0","1"],["30091.1","5629","0","1"]],"ts":"1652459234429","checksum":1397512168}]}
1652459234.5561411: {"arg":{"channel":"books","instId":"UNI-USD-SWAP"},"action":"update","data":[{"asks":[["5.142","148","0","2"],["5.145","181","0","3"],["5.146","6","0","1"],["5.148","41","0","2"]],"bids":[["5.127","189","0","2"],["5.125","157","0","2"]],"ts":"1652459234430","checksum":-1368104952}]}
1652459234.592627: {"arg":{"channel":"tickers","instId":"BTC-USD-220527"},"data":[{"instType":"FUTURES","instId":"BTC-USD-220527","last":"30229.6","lastSz":"30","askPx":"30217.8","askSz":"695","bidPx":"30211.8","bidSz":"4","open24h":"29571.4","high24h":"31003.3","low24h":"27930.8","sodUtc0":"28935.3","sodUtc8":"30320.5","volCcy24h":"2620.4014","vol24h":"779607","ts":"1652459234474"}]}
1652459234.6681972: {"arg":{"channel":"books","instId":"BTC-USD-220527"},"action":"update","data":[{"asks":[["30225.2","0","0","0"],["30225.4","3","0","1"],["30241.3","641","0","1"],["30241.4","30","0","1"],["30244.9","0","0","0"],["30245","0","0","0"],["30245.3","0","0","0"],["30250.7","4","0","1"],["30254.1","0","0","0"],["30254.2","0","0","0"],["30267.2","98","0","2"],["30267.3","0","0","0"],["30279.4","0","0","0"],["30279.5","0","0","0"],["30279.6","0","0","0"],["30300.1","15","0","1"],["30383","26","0","1"],["31126.7","0","0","0"],["31134.2","5","0","1"]],"bids":[["30218.1","0","0","0"],["30214.8","0","0","0"],["30214.7","0","0","0"],["30197.3","4","0","1"],["30197.2","0","0","0"],["30197.1","0","0","0"],["30196","0","0","0"],["30195","171","0","1"],["30193.3","100","0","1"],["30193.2","0","0","0"],["30189","30","0","1"],["30184.2","0","0","0"],["30184.1","337","0","1"],["30184","0","0","0"],["30174.2","11","0","1"],["30174","0","0","0"],["30167.1","0","0","0"],["30167","0","0","0"],["30164.8","40","0","1"],["30158.6","0","0","0"],["30138.2","0","0","0"],["30091.2","81","0","1"],["30066.4","202","0","1"],["30066.3","0","0","0"],["30066.2","0","0","0"],["29816.8","0","0","0"],["29813.5","202","0","1"]],"ts":"1652459234544","checksum":-1648428730}]}
1652459234.6686153: {"arg":{"channel":"books","instId":"BTC-USDT"},"action":"update","data":[{"asks":[["30227.5","0.00928516","0","2"],["30229.5","0","0","0"],["30231.4","0","0","0"],["30231.8","0.0132","0","1"],["30233.1","0","0","0"],["30235.4","0","0","0"],["30236.2","0.06523858","0","1"],["30236.8","0.16","0","1"],["30237.3","0","0","0"],["30239.4","0","0","0"],["30239.9","0.16","0","1"],["30244","0","0","0"],["30245.4","0","0","0"],["30246.5","0.00145748","0","1"],["30248.8","0.00439865","0","1"],["30249.6","0.20884064","0","2"],["30250.3","0.00662203","0","1"],["30250.4","0","0","0"],["30251.1","0","0","0"],["30255.1","0","0","0"],["30257","0.33050203","0","1"],["30260.4","0.00772336","0","1"],["30262.6","0.12610548","0","1"],["30263.8","0","0","0"],["30273","2.45139145","0","2"],["30274.5","0","0","0"],["30282","0","0","0"],["30288.5","0.08255","0","1"],["30292.1","0","0","0"],["30297.6","0","0","0"],["30328.3","0","0","0"],["30363.8","0.0471802","0","1"],["30639","0.00001067","0","1"],["30639.5","0.00003044","0","1"],["30640","0.97036266","0","9"]],"bids":[["30227.4","0.0012","0","2"],["30225.4","0","0","0"],["30225.3","0","0","0"],["30225.2","0","0","0"],["30224","0","0","0"],["30223.8","0","0","0"],["30223.4","0","0","0"],["30220.2","0.03578755","0","2"],["30220","0.72999","0","5"],["30218.4","0","0","0"],["30217.6","0.07115337","0","1"],["30217.3","0","0","0"],["30217","1.09","0","1"],["30215.2","0.12173747","0","2"],["30214.2","0","0","0"],["30208.3","0.06","0","1"],["30207.3","0.25","0","2"],["30206.1","0.03","0","1"],["30205.6","0.0189","0","1"],["30204.4","0","0","0"],["30204.2","0.15","0","1"],["30202.4","0","0","0"],["30201","0","0","0"],["30200.1","0.78311931","0","2"],["30198.8","0","0","0"],["30196.8","0.01643806","0","1"],["30196.7","0","0","0"],["30195.3","0.00875205","0","1"],["30194.9","0","0","0"],["30192.7","0.13233421","0","1"],["30192.1","0.037","0","1"],["30188.9","0","0","0"],["30187.9","0","0","0"],["30187","0.08255","0","1"],["30185.9","0.00039949","0","2"],["30184.5","1","0","1"],["30184.4","0.557","0","1"],["30176.6","0.0010008","0","1"],["30172.4","3.114","0","1"],["30168.5","0.24","0","1"],["30107.9","0","0","0"],["29984","0.00005829","0","1"],["29983.6","0.00011111","0","1"],["29983.4","0.00016309","0","1"],["29983.3","0.00106016","0","1"],["29983.1","0","0","0"]],"ts":"1652459234551","checksum":-1921129490}]}
1652459234.6691623: {"arg":{"channel":"books","instId":"UNI-USD-SWAP"},"action":"update","data":[{"asks":[["5.141","0","0","0"],["5.145","70","0","2"],["5.148","327","0","3"],["5.15","510","0","4"],["5.152","6","0","1"]],"bids":[["5.135","119","0","2"],["5.134","97","0","2"],["5.128","2555","0","5"],["5.127","412","0","3"],["5.126","81","0","3"],["5.125","57","0","1"],["5.121","1588","0","2"],["5.109","324","0","1"]],"ts":"1652459234546","checksum":246061034}]}
1652459234.676027: {"arg":{"channel":"tickers","instId":"BTC-USDT"},"data":[{"instType":"SPOT","instId":"BTC-USDT","last":"30224.1","lastSz":"0.00194683","askPx":"30230.3","askSz":"1.92174778","bidPx":"30230.2","bidSz":"0.4112","open24h":"29700.4","high24h":"31073","low24h":"28020.3","sodUtc0":"29028.8","sodUtc8":"30337.7","volCcy24h":"525818698.6954426","vol24h":"17602.68020984","ts":"1652459234555"}]}
1652459234.7750452: {"arg":{"channel":"books","instId":"BTC-USD-220527"},"action":"update","data":[{"asks":[["30225.4","0","0","0"],["30229.7","2","0","1"],["30229.8","0","0","0"],["30241.3","4","0","1"],["30250.7","94","0","1"],["30252.4","94","0","1"],["30258.9","0","0","0"],["30259","0","0","0"],["30260.6","94","0","1"],["30260.7","476","0","1"],["30267.2","0","0","0"],["30282.4","0","0","0"]],"bids":[["30222.4","0","0","0"],["30218.2","0","0","0"],["30197.8","74","0","1"],["30197.7","249","0","4"],["30197.6","311","0","1"],["30197.5","100","0","1"],["30197.4","806","0","3"],["30197.3","0","0","0"],["30196","0","0","0"],["30195.9","0","0","0"],["30195.8","0","0","0"],["30195.2","0","0","0"],["30195.1","0","0","0"],["30193.4","0","0","0"],["30193.3","0","0","0"],["30189.2","100","0","1"],["30189.1","619","0","1"],["30151.6","455","0","1"],["29320.6","5","0","1"],["29313.4","0","0","0"]],"ts":"1652459234659","checksum":-1116644507}]}
1652459234.7752779: {"arg":{"channel":"books","instId":"BTC-USDT"},"action":"update","data":[{"asks":[["30227.5","0.00928516","0","2"],["30230.2","0","0","0"],["30231.9","0","0","0"],["30235.3","0.06523858","0","1"],["30236.2","0","0","0"],["30236.6","0","0","0"],["30237.2","0","0","0"],["30239.1","0.635","0","1"],["30244.6","0.03309","0","1"],["30246.5","0","0","0"],["30250.9","2.261","0","1"],["30251.9","0","0","0"],["30252.5","0","0","0"],["30253","0","0","0"],["30253.7","0","0","0"],["30257.6","0.3","0","3"],["30275.4","2.973","0","1"],["30288.5","0","0","0"],["30304.8","0.08255","0","1"],["30640","0.97036266","0","9"],["30641.6","0.00065466","0","1"],["30642.3","0.00025498","0","1"],["30642.8","0.00164802","0","1"]],"bids":[["30227.4","0.0112","0","3"],["30217.6","1.31115337","0","2"],["30216.3","0","0","0"],["30208.6","0.02100159","0","2"],["30207.5","0.15","0","1"],["30204.2","0","0","0"],["30201.9","0.00662203","0","1"],["30201.2","0","0","0"],["30201.1","0","0","0"],["30199.8","0.00732697","0","1"],["30197.3","0.08255","0","1"],["30197.2","0.34759459","0","2"],["30196.9","0","0","0"],["30196.8","0","0","0"],["30195.3","0","0","0"],["30195","0","0","0"],["30191.7","0.557","0","1"],["30187","0","0","0"],["30184.4","0","0","0"],["30140","0.03303113","0","2"],["30076.3","0.05129073","0","1"],["30059.3","0","0","0"],["29983.3","0.00106016","0","1"],["29983.1","0.00218825","0","1"],["29983","0.00046876","0","1"],["29982.5","0.00031108","0","2"]],"ts":"1652459234654","checksum":1011345185}]}
1652459234.7755744: {"arg":{"channel":"books","instId":"UNI-USD-SWAP"},"action":"update","data":[{"asks":[["5.142","60","0","1"],["5.145","50","0","1"],["5.146","117","0","2"],["5.148","347","0","4"],["5.152","0","0","0"]],"bids":[["5.136","330","0","2"],["5.135","97","0","2"],["5.134","20","0","1"],["5.129","36","0","1"],["5.128","2519","0","4"],["5.127","438","0","4"],["5.126","264","0","4"],["5.125","0","0","0"],["5.123","0","0","0"]],"ts":"1652459234650","checksum":-553259634}]}
1652459234.8668263: {"arg":{"channel":"trades","instId":"BTC-USDT"},"data":[{"instId":"BTC-USDT","tradeId":"338476362","px":"30227.5","sz":"0.007903","side":"buy","ts":"1652459234752"}]}
1652459234.8854172: {"arg":{"channel":"books","instId":"BTC-USDT"},"action":"update","data":[{"asks":[["30227.5","0.23411216","0","3"],["30234.7","0","0","0"],["30235.3","0.06523858","0","1"],["30246.5","0.1","0","1"],["30256.6","0.03","0","1"],["30265.5","0","0","0"],["30277.5","0.06738287","0","2"],["30294","0.06676139","0","1"],["30312.8","2.451","0","1"],["30491.5","0","0","0"],["30640","0.97036266","0","9"],["30641.6","0.00065466","0","1"],["30642.3","0","0","0"],["30642.8","0","0","0"]],"bids":[["30224.6","0","0","0"],["30223.4","0","0","0"],["30222.2","0","0","0"],["30222","0.01","0","1"],["30221","0.01","0","1"],["30220.6","0.05452","0","1"],["30219.7","0","0","0"],["30217.8","0.07181417","0","1"],["30217.6","1.24","0","1"],["30213.4","0","0","0"],["30212.1","0.00032352","0","1"],["30211.3","0.000824","0","1"],["30209.4","0","0","0"],["30208.3","0.09","0","2"],["30206.9","0.06618309","0","1"],["30206.1","0","0","0"],["30205.6","0","0","0"],["30202.8","0.08255","0","1"],["30200.1","0.77513596","0","1"],["30197.9","0.06056453","0","1"],["30197.4","0.01643806","0","1"],["30197.3","0","0","0"],["30197.2","0.33115653","0","1"],["30192.5","0.0185","0","1"],["30151","2.44791","0","1"],["29986","0.00030544","0","1"],["29984","0.00005829","0","1"],["29983.6","0","0","0"],["29983.4","0","0","0"],["29983.3","0","0","0"],["29983.1","0","0","0"],["29983","0","0","0"],["29982.5","0","0","0"]],"ts":"1652459234769","checksum":1478966830}]}
1652459234.8856614: {"arg":{"channel":"books","instId":"BTC-USD-220527"},"action":"update","data":[{"asks":[["30222","0","0","0"],["30229.7","0","0","0"],["30229.8","3","0","1"],["30240.9","2","0","1"],["30241","677","0","1"],["30241.1","2","0","1"],["30241.2","695","0","1"],["30241.3","0","0","0"],["30241.4","0","0","0"],["30245","0","0","0"],["30249.9","4","0","1"],["30250","30","0","1"],["30250.7","0","0","0"],["30252.4","0","0","0"],["30260.6","0","0","0"],["30282.4","0","0","0"],["30403.3","508","0","1"],["30426.5","0","0","0"],["30463.7","502","0","1"],["30486.9","0","0","0"],["30524.1","508","0","1"],["30547.3","0","0","0"]],"bids":[["30220.3","3","0","1"],["30213.7","6","0","2"],["30213.6","0","0","0"],["30198","38","0","1"],["30197.9","100","0","1"],["30197.8","0","0","0"],["30197.7","100","0","1"],["30189.3","0","0","0"],["30189.2","0","0","0"],["30189.1","0","0","0"],["30091.1","5831","0","2"],["30066.4","0","0","0"],["29953.7","202","0","1"],["29940.7","1361","0","1"],["29816.2","202","0","1"],["29813.5","0","0","0"]],"ts":"1652459234764","checksum":1716981043}]}
1652459234.8858528: {"arg":{"channel":"books","instId":"UNI-USD-SWAP"},"action":"update","data":[{"asks":[["5.144","25","0","1"],["5.146","117","0","2"],["5.147","0","0","0"]],"bids":[["5.137","99","0","1"],["5.136","231","0","1"],["5.135","97","0","2"],["5.134","0","0","0"],["5.13","68","0","1"],["5.126","207","0","3"]],"ts":"1652459234723","checksum":-1482806103}]}
1652459234.9412434: {"arg":{"channel":"tickers","instId":"BTC-USDT"},"data":[{"instType":"SPOT","instId":"BTC-USDT","last":"30227.5","lastSz":"0.007903","askPx":"30230.3","askSz":"1.92174778","bidPx":"30230.2","bidSz":"0.4112","open24h":"29700.4","high24h":"31073","low24h":"28020.3","sodUtc0":"29028.8","sodUtc8":"30337.7","volCcy24h":"525818937.5833751","vol24h":"17602.68811284","ts":"1652459234813"}]}
1652459235.0019724: {"arg":{"channel":"books","instId":"BTC-USDT"},"action":"update","data":[{"asks":[["30227.5","0.23411216","0","3"],["30235.1","0.06523858","0","1"],["30235.3","0","0","0"],["30243.4","0.0248887","0","1"],["30304.8","0","0","0"],["30315.3","0.08255","0","1"],["30598.3","1.96089325","0","1"],["30605.8","0","0","0"],["30641.6","0","0","0"]],"bids":[["30227.4","0.019103","0","4"],["30224.5","0","0","0"],["30224.3","0.16","0","1"],["30222.2","0.05452","0","1"],["30220.6","0","0","0"],["30216.4","0.000824","0","1"],["30200.1","0.80811931","0","3"],["30197.9","0.06056453","0","1"],["30197.4","0","0","0"],["30196.9","0.01643806","0","1"],["29986","0","0","0"],["29984","0","0","0"]],"ts":"1652459234874","checksum":1120966791}]}
1652459235.0021431: {"arg":{"channel":"books","instId":"BTC-USD-220527"},"action":"update","data":[{"asks":[["30223.9","0","0","0"],["30224.7","3","0","1"],["30224.8","0","0","0"],["30229.6","2","0","1"],["30229.7","2","0","1"],["30229.8","0","0","0"],["30240.9","0","0","0"],["30241","0","0","0"],["30241.1","0","0","0"],["30241.2","0","0","0"],["30245","0","0","0"],["30245.1","0","0","0"],["30249.9","98","0","2"],["30251.2","0","0","0"],["30260.6","94","0","1"],["30282.4","94","0","1"]],"bids":[["30220.3","0","0","0"],["30217.5","0","0","0"],["30213.9","4","0","1"],["30213.8","2","0","1"],["30213.7","0","0","0"],["30198.3","100","0","1"],["30198.2","171","0","1"],["30198.1","0","0","0"],["30197.9","0","0","0"],["30197.7","0","0","0"],["30197.4","378","0","1"],["30195.2","100","0","1"],["30195.1","0","0","0"],["30195","0","0","0"],["30189.1","0","0","0"],["30039","500","0","1"],["30020.7","0","0","0"],["29978.5","504","0","1"],["29960.3","0","0","0"],["29918.1","505","0","1"],["29899.9","0","0","0"]],"ts":"1652459234878","checksum":-923469873}]}
1652459235.0023649: {"arg":{"channel":"books","instId":"UNI-USD-SWAP"},"action":"update","data":[{"asks":[["5.142","0","0","0"],["5.148","311","0","3"],["5.152","36","0","1"]],"bids":[],"ts":"1652459234826","checksum":-617819834}]}
1652459235.1036797: {"arg":{"channel":"books","instId":"BTC-USD-220527"},"action":"update","data":[{"asks":[["30224.7","0","0","0"],["30226.3","3","0","1"],["30260.6","0","0","0"],["30260.7","0","0","0"],["30282.4","94","0","1"]],"bids":[["30217.4","0","0","0"],["30217","0","0","0"],["30214.1","4","0","1"],["30214","2","0","1"],["30213.9","0","0","0"],["30198.4","38","0","1"],["30198","0","0","0"],["30195.2","0","0","0"],["30189.1","100","0","1"],["30156.6","20","0","1"],["30151.6","0","0","0"]],"ts":"1652459234993","checksum":2085745424}]}
1652459235.1039736: {"arg":{"channel":"books","instId":"BTC-USDT"},"action":"update","data":[{"asks":[["30227.5","0.23411216","0","3"],["30234.5","0.06523858","0","1"],["30235.1","0","0","0"],["30236.8","0.16","0","1"],["30250.9","0","0","0"],["30262.1","0.4","0","1"],["30307.2","0.08255","0","1"],["30315.3","0","0","0"],["30326","0","0","0"],["30528","1.96540881","0","1"],["30598.3","0","0","0"],["30641.6","0.00065466","0","1"],["30642.3","0","0","0"],["30642.8","0","0","0"]],"bids":[["30224.3","0","0","0"],["30223.2","0","0","0"],["30222","0","0","0"],["30218","0.07181417","0","1"],["30217.8","0","0","0"],["30213.1","0.04145","0","2"],["30211.4","0.06","0","1"],["30208.3","0","0","0"],["30199.6","0.00004496","0","1"],["30198.7","0.01643806","0","1"],["30198.4","0.24582075","0","1"],["30196.9","0","0","0"],["30172.4","0","0","0"],["30044.2","0","0","0"],["29986.8","0","0","0"],["29986","0.00030544","0","1"],["29984","0.00005829","0","1"],["29983.6","0.00011111","0","1"],["29983.4","0.00016309","0","1"],["29983.3","0.00106016","0","1"]],"ts":"1652459234979","checksum":1016734861}]}
1652459235.104306: {"arg":{"channel":"books","instId":"UNI-USD-SWAP"},"action":"update","data":[{"asks":[["5.151","98","0","2"],["5.152","0","0","0"],["5.154","1824","0","1"]],"bids":[["5.13","0","0","0"],["5.127","444","0","4"],["5.126","207","0","3"],["5.125","0","0","0"],["5.124","422","0","4"],["5.114","163","0","1"]],"ts":"1652459234989","checksum":972365419}]}
1652459235.239756: {"arg":{"channel":"books","instId":"BTC-USDT"},"action":"update","data":[{"asks":[["30251","2.245","0","1"],["30252.6","0.03","0","1"],["30254.3","5.08311375","0","1"],["30256.6","0","0","0"],["30262.1","0.45","0","2"],["30640","0","0","0"],["30641.6","0","0","0"],["30642.3","0","0","0"]],"bids":[["30218.3","0.01648681","0","1"],["30216.4","0","0","0"],["30211.5","0.10001068","0","2"],["30211.3","0","0","0"],["30204.8","0","0","0"],["30198.7","0","0","0"],["30198.3","0.18210211","0","2"],["30196.8","2.316","0","1"],["30172.5","3.05625","0","2"],["30130","0.03369896","0","3"],["29983.1","0.00218825","0","1"],["29983","0.00046876","0","1"],["29982.5","0","0","0"]],"ts":"1652459235095","checksum":-169860480}]}
1652459235.240282: {"arg":{"channel":"books","instId":"BTC-USD-220527"},"action":"update","data":[{"asks":[],"bids":[["30217.3","4","0","1"],["30217.2","3","0","1"],["30217.1","0","0","0"],["30217","0","0","0"],["30216.6","0","0","0"],["30216.5","0","0","0"],["30214.1","0","0","0"],["30198.4","38","0","1"]],"ts":"1652459235098","checksum":-1763442711}]}
1652459235.2404928: {"arg":{"channel":"books","instId":"UNI-USD-SWAP"},"action":"update","data":[{"asks":[["5.145","163","0","2"],["5.146","6","0","1"],["5.157","36","0","2"]],"bids":[["5.13","297","0","1"],["5.127","528","0","5"],["5.126","207","0","3"],["5.124","354","0","3"],["5.116","99","0","2"]],"ts":"1652459235082","checksum":-1682579873}]}
1652459235.324668: {"arg":{"channel":"books","instId":"BTC-USD-220527"},"action":"update","data":[{"asks":[["30250.1","214","0","1"],["30260.7","0","0","0"],["30260.8","479","0","1"],["30282.4","0","0","0"]],"bids":[["30217.3","0","0","0"],["30214.1","4","0","1"],["30151.6","475","0","1"],["30144.4","19","0","1"]],"ts":"1652459235209","checksum":1592593294}]}
1652459235.3250184: {"arg":{"channel":"books","instId":"BTC-USDT"},"action":"update","data":[{"asks":[["30234","0.06523858","0","1"],["30234.5","0","0","0"],["30239.2","0.1","0","1"],["30244.6","0.03308","0","1"],["30246.4","0","0","0"],["30248.8","0","0","0"],["30256.7","0","0","0"],["30271.9","0.07997935","0","1"],["30287.5","0","0","0"],["30518.5","1.96602061","0","1"],["30528","0","0","0"],["30639.5","0.00003044","0","1"],["30640","0.97036266","0","9"]],"bids":[["30227.4","0.419103","0","5"],["30212","0.000824","0","1"],["30208.8","0.02099","0","1"],["30208.6","0.00001159","0","1"],["30198.3","0.16566405","0","1"],["30196.3","0.01643806","0","1"],["30196","0.00193166","0","3"],["30191.7","1.037","0","2"],["30184","0","0","0"],["30125.1","0","0","0"],["29983","0","0","0"],["29982.5","0","0","0"]],"ts":"1652459235212","checksum":924233258}]}
1652459235.4425354: {"arg":{"channel":"books","instId":"BTC-USD-220527"},"action":"update","data":[{"asks":[["30226.3","0","0","0"],["30227.3","3","0","1"],["30250","30","0","1"],["30250.7","214","0","1"]],"bids":[["30217.7","4","0","1"],["30217.6","2","0","1"],["30217.5","2","0","1"],["30217.4","3","0","1"],["30217.3","0","0","0"],["30217.2","0","0","0"],["30214.1","0","0","0"],["30214","0","0","0"],["30213.8","0","0","0"],["30198.5","98","0","1"],["30198.3","0","0","0"]],"ts":"1652459235322","checksum":-1372076676}]}
1652459235.4430335: {"arg":{"channel":"books","instId":"BTC-USDT"},"action":"update","data":[{"asks":[["30227.5","0.00138216","0","2"],["30234","0","0","0"],["30234.4","0","0","0"],["30234.9","0.06523858","0","1"],["30236.8","0","0","0"],["30248.7","0.00244474","0","1"],["30248.8","0.06227862","0","1"],["30261.1","0.16","0","1"],["30640","0","0","0"],["30641.6","0","0","0"]],"bids":[["30224.3","0.16","0","1"],["30218.5","0.12161391","0","1"],["30217","1.09603201","0","2"],["30210.4","0.09","0","1"],["30207.3","0.16","0","1"],["30203.2","0.00662203","0","1"],["30201.9","0","0","0"],["30196.9","0.01643806","0","1"],["30196.3","0","0","0"],["30196.2","0","0","0"],["30167.9","0.16542214","0","1"],["29983.6","0","0","0"],["29983.4","0","0","0"],["29983.3","0","0","0"],["29983.1","0","0","0"]],"ts":"1652459235324","checksum":1730228298}]}
1652459235.4437244: {"arg":{"channel":"books","instId":"UNI-USD-SWAP"},"action":"update","data":[{"asks":[["5.15","546","0","5"],["5.151","62","0","1"]],"bids":[["5.137","0","0","0"],["5.136","427","0","4"],["5.135","20","0","1"],["5.128","2522","0","5"],["5.127","412","0","3"],["5.126","291","0","4"]],"ts":"1652459235323","checksum":891800411}]}
1652459235.5460875: {"arg":{"channel":"books","instId":"BTC-USDT"},"action":"update","data":[{"asks":[["30234.9","0","0","0"],["30235.4","0.06523858","0","1"],["30240.8","0.05","0","1"],["30248.7","0","0","0"],["30252.6","0","0","0"],["30267","0.037","0","1"],["30639","0.00001067","0","1"],["30639.5","0.00003044","0","1"]],"bids":[["30200.1","0.80013596","0","2"],["30196.9","0","0","0"],["30196.7","0.01643806","0","1"],["30196.6","0","0","0"],["30191.3","0.58799999","0","1"],["30184.6","0","0","0"],["30183.4","0","0","0"],["30181.4","2.31208898","0","1"],["30119.7","0.013838","0","1"],["29984","0","0","0"]],"ts":"1652459235421","checksum":390566643}]}
1652459235.5516598: {"arg":{"channel":"books","instId":"BTC-USD-220527"},"action":"update","data":[{"asks":[["30227.3","0","0","0"],["30227.6","3","0","1"]],"bids":[["30220.1","3","0","1"],["30217.7","0","0","0"],["30217.4","0","0","0"],["30201.8","98","0","1"],["30201.7","42","0","2"],["30201.6","214","0","1"],["30201.5","214","0","1"],["30198.5","0","0","0"],["30198.4","0","0","0"],["30197.5","0","0","0"],["30144.4","0","0","0"],["30091.1","202","0","1"]],"ts":"1652459235427","checksum":-1611202943}]}
1652459235.5519533: {"arg":{"channel":"books","instId":"UNI-USD-SWAP"},"action":"update","data":[{"asks":[["5.145","50","0","1"],["5.146","6","0","1"],["5.147","113","0","1"]],"bids":[["5.128","2619","0","5"],["5.127","496","0","4"],["5.126","207","0","3"],["5.125","1220","0","1"]],"ts":"1652459235385","checksum":-1654731936}]}
1652459235.6296623: {"arg":{"channel":"trades","instId":"BTC-USDT"},"data":[{"instId":"BTC-USDT","tradeId":"338476363","px":"30227.5","sz":"0.00008035","side":"buy","ts":"1652459235515"}]}
1652459235.6298473: {"arg":{"channel":"trades","instId":"BTC-USDT"},"data":[{"instId":"BTC-USDT","tradeId":"338476364","px":"30227.5","sz":"0.00009459","side":"buy","ts":"1652459235515"}]}
1652459235.6568558: {"arg":{"channel":"trades","instId":"BTC-USDT"},"data":[{"instId":"BTC-USDT","tradeId":"338476365","px":"30227.5","sz":"0.0012","side":"buy","ts":"1652459235538"}]}
1652459235.657034: {"arg":{"channel":"trades","instId":"BTC-USDT"},"data":[{"instId":"BTC-USDT","tradeId":"338476366","px":"30227.5","sz":"0.00000722","side":"buy","ts":"1652459235539"}]}
1652459235.6571438: {"arg":{"channel":"trades","instId":"BTC-USDT"},"data":[{"instId":"BTC-USDT","tradeId":"338476367","px":"30227.5","sz":"0.00119278","side":"buy","ts":"1652459235539"}]}
1652459235.6572428: {"arg":{"channel":"tickers","instId":"BTC-USDT"},"data":[{"instType":"SPOT","instId":"BTC-USDT","last":"30227.5","lastSz":"0.00008035","askPx":"30230.3","askSz":"1.92174778","bidPx":"30230.2","bidSz":"0.4112","open24h":"29700.4","high24h":"31073","low24h":"28020.3","sodUtc0":"29028.8","sodUtc8":"30337.7","volCcy24h":"525818942.87137395","vol24h":"17602.68828778","ts":"1652459235519"}]}
1652459235.6576173: {"arg":{"channel":"books","instId":"BTC-USD-220527"},"action":"update","data":[{"asks":[["30225.3","0","0","0"],["30227.5","0","0","0"],["30227.6","0","0","0"],["30229.6","0","0","0"],["30229.7","0","0","0"],["30231.4","0","0","0"],["30249.8","131","0","2"],["30249.9","104","0","2"],["30250.1","0","0","0"],["30250.7","214","0","1"],["30251","214","0","1"],["30252.4","0","0","0"],["30260.8","0","0","0"],["30282.4","0","0","0"],["30463.7","704","0","2"],["30467.7","0","0","0"],["30589.9","0","0","0"],["30607.8","2205","0","2"]],"bids":[["30226","0","0","0"],["30220.1","0","0","0"],["30218","4","0","1"],["30217.9","0","0","0"],["30217.7","0","0","0"],["30202.3","171","0","1"],["30202","0","0","0"],["30201.9","38","0","1"],["30201.7","0","0","0"],["30201.6","0","0","0"],["30201.5","0","0","0"],["30198.3","0","0","0"],["30198.2","0","0","0"],["30197.7","98","0","1"],["30189.1","98","0","1"],["30156.6","0","0","0"],["30151.6","0","0","0"],["30117.7","81","0","1"],["30091.3","202","0","1"],["30091.2","0","0","0"],["30091.1","0","0","0"],["29957.2","202","0","1"],["29953.7","0","0","0"],["29819.7","202","0","1"],["29816.2","0","0","0"]],"ts":"1652459235542","checksum":-2086407731}]}
1652459235.6586792: {"arg":{"channel":"books","instId":"BTC-USDT"},"action":"update","data":[{"asks":[["30227.5","0.00679057","0","1"],["30235.2","0","0","0"],["30235.4","0","0","0"],["30235.5","0","0","0"],["30236.3","0.0488","0","1"],["30237.1","0.06523858","0","1"],["30240.8","0","0","0"],["30248.7","0","0","0"],["30248.8","0","0","0"],["30251","0","0","0"],["30254.3","0","0","0"],["30256.1","0.03","0","1"],["30257.6","0.15","0","2"],["30259.3","0.15","0","1"],["30262.1","0.4","0","1"],["30275.4","0","0","0"],["30296.9","0.5","0","1"],["30360","0.05304972","0","3"],["30420","0.56192523","0","4"],["30639.5","0.00003044","0","1"],["30640","0.97036266","0","9"],["30641.6","0.00065466","0","1"]],"bids":[["30227.4","1.06109365","0","9"],["30221.3","0.07181417","0","1"],["30220.6","0.05055668","0","1"],["30220.2","0.07258755","0","2"],["30218","0","0","0"],["30215.3","0.000824","0","1"],["30210.3","0","0","0"],["30200.1","0.80811931","0","3"],["30172.5","0.00025","0","1"],["30164.9","0.00938518","0","1"],["29986","0","0","0"],["29984","0","0","0"]],"ts":"1652459235545","checksum":1781913732}]}
1652459235.6595042: {"arg":{"channel":"books","instId":"UNI-USD-SWAP"},"action":"update","data":[{"asks":[["5.144","0","0","0"],["5.146","119","0","2"],["5.147","0","0","0"]],"bids":[],"ts":"1652459235512","checksum":-2121541487}]}
1652459235.6684432: {"arg":{"channel":"trades","instId":"BTC-USDT"},"data":[{"instId":"BTC-USDT","tradeId":"338476368","px":"30227.5","sz":"0.00679057","side":"buy","ts":"1652459235555"}]}
1652459235.6686027: {"arg":{"channel":"trades","instId":"BTC-USDT"},"data":[{"instId":"BTC-USDT","tradeId":"338476369","px":"30227.6","sz":"0.28289943","side":"buy","ts":"1652459235555"}]}
1652459235.6686857: {"arg":{"channel":"trades","instId":"BTC-USDT"},"data":[{"instId":"BTC-USDT","tradeId":"338476370","px":"30227.6","sz":"0.0444","side":"buy","ts":"1652459235555"}]}
1652459235.6687477: {"arg":{"channel":"trades","instId":"BTC-USDT"},"data":[{"instId":"BTC-USDT","tradeId":"338476371","px":"30227.6","sz":"0.0303","side":"buy","ts":"1652459235555"}]}
1652459235.69066: {"arg":{"channel":"trades","instId":"BTC-USDT"},"data":[{"instId":"BTC-USDT","tradeId":"338476372","px":"30227.6","sz":"0.31215088","side":"buy","ts":"1652459235575"}]}
1652459235.6908195: {"arg":{"channel":"trades","instId":"BTC-USDT"},"data":[{"instId":"BTC-USDT","tradeId":"338476373","px":"30227.6","sz":"1.21","side":"buy","ts":"1652459235575"}]}
1652459235.6909115: {"arg":{"channel":"trades","instId":"BTC-USDT"},"data":[{"instId":"BTC-USDT","tradeId":"338476374","px":"30227.6","sz":"1.03999912","side":"buy","ts":"1652459235575"}]}
1652459235.6909842: {"arg":{"channel":"trades","instId":"BTC-USDT"},"data":[{"instId":"BTC-USDT","tradeId":"338476375","px":"30227.6","sz":"0.00000088","side":"buy","ts":"1652459235576"}]}
1652459235.7606227: {"arg":{"channel":"tickers","instId":"BTC-USDT"},"data":[{"instType":"SPOT","instId":"BTC-USDT","last":"30227.6","lastSz":"0.00000088","askPx":"30230.3","askSz":"1.92174778","bidPx":"30230.2","bidSz":"0.4112","open24h":"29700.4","high24h":"31073","low24h":"28020.3","sodUtc0":"29028.8","sodUtc8":"30337.7","volCcy24h":"525907477.72379918","vol24h":"17605.61722866","ts":"1652459235637"}]}
1652459235.7703292: {"arg":{"channel":"books","instId":"BTC-USD-220527"},"action":"update","data":[{"asks":[["30234.2","0","0","0"],["30237.2","0","0","0"],["30237.3","0","0","0"],["30238.6","677","0","1"],["30238.7","0","0","0"],["30241.5","0","0","0"],["30249.5","605","0","1"],["30249.6","0","0","0"],["30249.7","0","0","0"],["30249.8","0","0","0"],["30249.9","100","0","1"],["30250.6","0","0","0"],["30250.7","0","0","0"],["30250.8","0","0","0"],["30251","0","0","0"],["30252.4","0","0","0"],["30252.5","0","0","0"],["30255.3","0","0","0"],["30255.4","0","0","0"],["30256.8","100","0","1"],["30256.9","15","0","1"],["30263.2","11","0","1"],["30280.4","4","0","1"],["30280.5","0","0","0"],["30282.4","0","0","0"],["30290.2","0","0","0"],["30296.6","1","0","1"],["30304.2","20","0","1"],["30316.4","20","0","1"],["30403.3","0","0","0"],["30431.2","509","0","1"],["30463.7","202","0","1"],["30491.7","502","0","1"],["30524.1","0","0","0"],["30552.1","508","0","1"],["31134.2","0","0","0"],["31143.2","6","0","1"]],"bids":[["30230.9","0","0","0"],["30228.5","0","0","0"],["30227.3","0","0","0"],["30227.2","0","0","0"],["30218","0","0","0"],["30217.9","4","0","1"],["30217.8","76","0","2"],["30217.7","0","0","0"],["30217.5","65","0","1"],["30216.6","0","0","0"],["30216.5","0","0","0"],["30208.8","214","0","1"],["30208.3","214","0","1"],["30207.4","5","0","1"],["30202.4","38","0","1"],["30202","0","0","0"],["30201.9","0","0","0"],["30201.8","0","0","0"],["30201.5","27","0","1"],["30197.7","0","0","0"],["30197.5","0","0","0"],["30189.1","99","0","1"],["30189","0","0","0"],["30183.6","0","0","0"],["30183.5","27","0","1"],["30174.2","0","0","0"],["30168.9","19","0","1"],["30164.8","0","0","0"],["29868.1","2004","0","1"],["29840.1","0","0","0"],["29777.4","2006","0","1"],["29749.4","0","0","0"],["29686.7","2008","0","1"],["29658.8","0","0","0"],["29596","2007","0","1"],["29568.2","0","0","0"],["29505.3","2009","0","1"],["29477.6","0","0","0"]],"ts":"1652459235657","checksum":-1453265927}]}
1652459235.7713697: {"arg":{"channel":"books","instId":"BTC-USDT"},"action":"update","data":[{"asks":[["30227.5","0","0","0"],["30227.6","0","0","0"],["30231.8","0","0","0"],["30236.2","0.001","0","1"],["30236.3","0","0","0"],["30237","0.00003","0","1"],["30237.1","0","0","0"],["30237.9","0","0","0"],["30238.7","0","0","0"],["30239.1","0","0","0"],["30239.2","0","0","0"],["30239.3","0","0","0"],["30239.9","0","0","0"],["30240","0","0","0"],["30240.1","0","0","0"],["30240.4","0","0","0"],["30240.7","0.00138424","0","1"],["30241","0.06523858","0","1"],["30241.9","0.0132","0","1"],["30243.1","0.16","0","1"],["30243.4","0","0","0"],["30243.5","0","0","0"],["30244.6","0","0","0"],["30246.1","0.635","0","1"],["30248.9","0","0","0"],["30249.6","0.16563853","0","1"],["30250.3","0","0","0"],["30251.6","0.03308","0","1"],["30252.8","0.00041076","0","1"],["30253.7","0","0","0"],["30254.5","0","0","0"],["30256.1","0","0","0"],["30257.6","0","0","0"],["30258.2","0","0","0"],["30259.3","0.222771","0","3"],["30260.4","0","0","0"],["30261","0.00662203","0","1"],["30261.4","0.24845779","0","1"],["30261.5","0.15","0","2"],["30262.1","0","0","0"],["30265.1","0.883","0","1"],["30265.6","0","0","0"],["30268.5","0.00890659","0","1"],["30272.2","0","0","0"],["30273.5","0.06","0","1"],["30277.5","0.0012","0","1"],["30279","0.06617805","0","1"],["30301.7","0","0","0"],["30307.2","0","0","0"],["30318","1.66491279","0","1"],["30319.6","0.08255","0","1"],["30328.9","0","0","0"],["30345.2","1.64912198","0","1"],["30356.1","0","0","0"],["30363.8","0","0","0"],["30372.4","1.67659345","0","1"],["30376.5","0.0471802","0","1"],["30518.5","0","0","0"],["30598.3","1.96089325","0","1"],["30642.3","0.00025498","0","1"],["30642.8","0.00164802","0","1"],["30643.2","6.53852334","0","1"],["30643.5","0.00265198","0","1"],["30644.5","0.00016417","0","1"],["30645.9","0.0003738","0","1"],["30646.6","0.00023887","0","1"],["30650","0.10083281","0","7"],["30650.2","0.00102749","0","1"],["30650.3","0","0","0"],["30651","0","0","0"],["30651.4","0","0","0"],["30652.2","0","0","0"]],"bids":[["30232.9","0.00899172","0","2"],["30232.8","0","0","0"],["30232.2","0.04","0","1"],["30230.9","0.05927887","0","1"],["30230.8","0.04859","0","1"],["30230.2","0","0","0"],["30230.1","0.04859","0","1"],["30229.6","0.44859","0","2"],["30227.7","0.16","0","1"],["30227.6","0.24771","0","3"],["30227.5","1.57844554","0","6"],["30227.4","0.4180637","0","5"],["30226.6","0.052","0","1"],["30225.9","0.0718055","0","1"],["30224.1","0","0","0"],["30222.3","0.3308815","0","1"],["30222.2","0","0","0"],["30221.6","0.12160143","0","1"],["30221.3","0","0","0"],["30220.6","0.14961668","0","2"],["30220","0.2814","0","3"],["30217.7","0.09","0","2"],["30216.4","0.09","0","1"],["30216","0.02099","0","1"],["30215.8","0.15","0","1"],["30215.2","0.00011028","0","1"],["30213.4","0.00662203","0","1"],["30213.3","0.00015039","0","1"],["30213.1","0.01145","0","1"],["30212.3","0.33099102","0","1"],["30212.1","0.00032352","0","1"],["30211.4","0","0","0"],["30210.6","0.33100964","0","1"],["30210.4","0","0","0"],["30209.3","0","0","0"],["30208.8","0","0","0"],["30208.3","0.020374","0","1"],["30207.5","0","0","0"],["30207.4","2.374","0","1"],["30206.9","0.09000074","0","1"],["30205.6","0.01643806","0","1"],["30204.1","0.00844715","0","1"],["30203.2","0","0","0"],["30202.8","0.41364513","0","2"],["30202.5","0","0","0"],["30201.7","0.00004205","0","1"],["30200.1","0.80013596","0","2"],["30199.8","0","0","0"],["30199.1","0","0","0"],["30198.1","0.557","0","1"],["30197.2","0","0","0"],["30196.7","0","0","0"],["30196.4","0","0","0"],["30194.9","0.16540627","0","1"],["30192.7","0","0","0"],["30192.1","0","0","0"],["30192","0.00256975","0","1"],["30191.7","0.48","0","1"],["30190.8","1","0","1"],["30190.1","0.16","0","1"],["30184.5","0","0","0"],["30184.3","0.00250808","0","1"],["30179.9","0.33074909","0","2"],["30177.2","0.24","0","1"],["30168.5","0","0","0"],["30151.1","1.68807278","0","2"],["30138.4","0","0","0"],["30123.9","1.68268465","0","1"],["30119.9","0","0","0"],["30111.2","0","0","0"],["30096.7","1.66900484","0","1"],["30084","0.00006523","0","2"],["29994.2","0","0","0"],["29993.2","0","0","0"],["29992.7","0","0","0"],["29991.7","0","0","0"],["29990.1","0","0","0"],["29990","0","0","0"],["29988.3","0","0","0"],["29988.1","0","0","0"],["29988","0","0","0"],["29987.9","0","0","0"],["29987.6","0","0","0"],["29987.3","0","0","0"],["29986","0","0","0"],["29984","0","0","0"],["29983.6","0","0","0"],["29983.4","0","0","0"],["29983.3","0","0","0"],["29983.1","0","0","0"],["29983","0","0","0"]],"ts":"1652459235647","checksum":2106982873}]}
1652459235.774141: {"arg":{"channel":"books","instId":"UNI-USD-SWAP"},"action":"update","data":[{"asks":[["5.145","50","0","1"],["5.146","120","0","2"],["5.147","114","0","1"],["5.151","62","0","1"]],"bids":[["5.136","427","0","4"]],"ts":"1652459235655","checksum":-1573425198}]}
1652459235.8793344: {"arg":{"channel":"books","instId":"BTC-USDT"},"action":"update","data":[{"asks":[["30237","0","0","0"],["30240.7","0.01","0","1"],["30241","0.01","0","1"],["30241.8","0","0","0"],["30241.9","0","0","0"],["30242","0.01","0","1"],["30243.1","0","0","0"],["30243.9","0.0134","0","2"],["30244.1","0","0","0"],["30244.6","0.06523858","0","1"],["30246","0.00087743","0","1"],["30246.5","0","0","0"],["30246.6","0.16","0","1"],["30252.8","0.24797347","0","1"],["30252.9","0.19984","0","1"],["30254.4","0","0","0"],["30256.1","0.00090626","0","1"],["30257","0","0","0"],["30258.9","0","0","0"],["30259.3","0","0","0"],["30261","0.83773784","0","3"],["30262.5","0.03","0","1"],["30262.6","0","0","0"],["30264.3","0.15","0","1"],["30265.3","0.05","0","1"],["30267","0","0","0"],["30267.9","0.73094707","0","3"],["30268.5","0","0","0"],["30270.7","0.0599994","0","1"],["30272.9","0.00914864","0","1"],["30273","0.00008145","0","1"],["30274.9","0.037","0","1"],["30279","0","0","0"],["30281.4","0.0251312","0","1"],["30283.3","0","0","0"],["30598.3","0","0","0"],["30601.6","1.96068179","0","1"],["30646.6","0.00023887","0","1"],["30650","0.10083281","0","7"],["30650.2","0.00102749","0","1"],["30650.3","0","0","0"],["30651","0","0","0"],["30651.4","0","0","0"],["30652.2","0","0","0"],["30653.8","0","0","0"]],"bids":[["30236.1","0.11423923","0","5"],["30233.2","0","0","0"],["30233.1","0.04859","0","1"],["30233","0","0","0"],["30232.9","0.04859","0","1"],["30232.2","0","0","0"],["30231.5","0.0077","0","1"],["30230.9","0.05927887","0","1"],["30230.1","0","0","0"],["30229.6","0.4","0","1"],["30229.1","0.07180355","0","1"],["30228","0.01","0","1"],["30227.6","0.24001","0","2"],["30227.5","1.57844554","0","6"],["30227.4","0.41","0","2"],["30227","0.01","0","1"],["30226.6","0","0","0"],["30225.9","0","0","0"],["30225.6","0.12158534","0","1"],["30221.1","0","0","0"],["30221","0","0","0"],["30220.3","0.00044642","0","1"],["30220.1","0.09259347","0","1"],["30219.5","0.000824","0","1"],["30218.5","0","0","0"],["30218.3","0","0","0"],["30217.8","0","0","0"],["30217.7","0.2397","0","3"],["30210.5","0.03008317","0","2"],["30209.4","0.00684979","0","1"],["30205.6","0.01643806","0","1"],["30204.1","0","0","0"],["30202.7","0.00165574","0","1"],["30202.6","0","0","0"],["30201.9","0.037","0","1"],["30200.1","0.025","0","1"],["30199.8","0.48","0","1"],["30198.4","0.83382074","0","2"],["30191.9","0","0","0"],["30191.7","0","0","0"],["30191.3","0","0","0"],["30190.8","0","0","0"],["30181.7","0.25","0","1"],["30177.2","0","0","0"],["30139.2","0","0","0"],["29999.6","0.04507001","0","1"],["29999.4","0.00270878","0","1"],["29999","0.01500049","0","2"],["29998","0.00400028","0","1"],["29996.6","0.00166685","0","1"],["29995.7","0.00087403","0","1"],["29995","0.0284951","0","1"],["29994.2","0.00004654","0","1"]],"ts":"1652459235761","checksum":1749097243}]}
1652459235.8820043: {"arg":{"channel":"books","instId":"UNI-USD-SWAP"},"action":"update","data":[{"asks":[["5.143","0","0","0"],["5.146","120","0","2"],["5.147","0","0","0"],["5.148","25","0","2"],["5.15","707","0","5"],["5.151","62","0","1"],["5.152","87","0","1"],["5.167","0","0","0"]],"bids":[["5.136","350","0","3"],["5.131","67","0","2"],["5.13","383","0","2"],["5.129","39","0","2"],["5.128","2519","0","4"],["5.127","412","0","3"],["5.126","145","0","2"]],"ts":"1652459235760","checksum":-2056355617}]}
1652459235.882435: {"arg":{"channel":"books","instId":"BTC-USD-220527"},"action":"update","data":[{"asks":[["30235.7","0","0","0"],["30238.6","0","0","0"],["30242.6","3","0","1"],["30249.3","738","0","1"],["30249.4","0","0","0"],["30249.5","0","0","0"],["30249.9","0","0","0"],["30250","0","0","0"],["30256.8","0","0","0"],["30256.9","0","0","0"],["30259.2","100","0","1"],["30259.3","12","0","1"],["30260.9","0","0","0"],["30261","215","0","1"],["30263","4","0","1"],["30263.1","100","0","1"],["30263.2","0","0","0"],["30267.8","0","0","0"],["30267.9","33","0","1"],["30268.6","462","0","1"],["30270","11","0","1"],["30280.4","0","0","0"],["30300.1","0","0","0"],["30304.2","0","0","0"],["30344.3","27","0","1"],["30383","0","0","0"],["30416.5","21","0","1"]],"bids":[["30234.7","2","0","1"],["30232","0","0","0"],["30230.6","0","0","0"],["30225.6","0","0","0"],["30225.5","0","0","0"],["30218.3","4","0","1"],["30218.2","157","0","3"],["30218.1","0","0","0"],["30218","2","0","1"],["30217.9","0","0","0"],["30217.8","0","0","0"],["30217.6","0","0","0"],["30217.5","0","0","0"],["30217.4","0","0","0"],["30217.3","0","0","0"],["30209.7","171","0","1"],["30208.9","99","0","1"],["30202.4","137","0","2"],["30202.3","0","0","0"],["30197.7","99","0","1"],["30189.1","0","0","0"],["30181.3","11","0","1"],["30168.9","0","0","0"],["30162.2","463","0","1"],["29329.1","5","0","1"],["29320.6","0","0","0"]],"ts":"1652459235762","checksum":-552629045}]}
1652459235.9872365: {"arg":{"channel":"books","instId":"BTC-USDT"},"action":"update","data":[{"asks":[["30240.7","0","0","0"],["30241","0","0","0"],["30242","0","0","0"],["30243.9","0.0002","0","1"],["30244.6","0","0","0"],["30245.9","0","0","0"],["30246","0","0","0"],["30249","0.06179","0","2"],["30256.1","0","0","0"],["30260.9","0.00439865","0","1"],["30265.7","0","0","0"],["30270.7","0","0","0"],["30274.6","0","0","0"],["30278.4","0.10322003","0","1"],["30282","0.06617039","0","1"],["30285","0","0","0"],["30312.2","0.08255","0","1"],["30319.6","0","0","0"],["30558.9","0.37759236","0","1"],["30650.3","0.00230626","0","1"],["30651","0.00007125","0","1"],["30651.4","0.00010958","0","1"],["30652.2","0.00894205","0","1"],["30653.8","0.0000131","0","1"],["30654.8","0.00044899","0","1"],["30655.4","0","0","0"],["30655.5","0","0","0"]],"bids":[["30236.1","0.15611766","0","6"],["30233.1","0","0","0"],["30232.9","0","0","0"],["30230.9","0","0","0"],["30229.1","0.19337482","0","2"],["30224.7","0.03","0","1"],["30220.2","0.05","0","1"],["30219","0.24","0","2"],["30218.4","0.000682","0","1"],["30217.7","0","0","0"],["30217.2","0.0292137","0","1"],["30216.4","0","0","0"],["30215.8","0","0","0"],["30212.4","0.7838375","0","1"],["30211.4","0.06617061","0","1"],["30208.3","0.102924","0","2"],["30207.9","0.06588852","0","2"],["30207.4","0","0","0"],["30207.2","0","0","0"],["30205.6","0","0","0"],["30203.9","0.08326207","0","2"],["30202.8","0.33109513","0","1"],["30200.1","0","0","0"],["30196.8","0","0","0"],["30195.4","1","0","1"],["30182.5","0.24","0","1"],["30126.3","0.00001102","0","1"],["29995","0.0284951","0","1"],["29994.2","0.00004654","0","1"],["29993.2","0.00154236","0","1"],["29992.7","0.00007716","0","1"]],"ts":"1652459235852","checksum":-1814121561}]}
1652459235.9943526: {"arg":{"channel":"books","instId":"BTC-USD-220527"},"action":"update","data":[{"asks":[["30236.4","0","0","0"],["30239.4","0","0","0"],["30239.7","0","0","0"],["30240.7","3","0","1"],["30242.4","0","0","0"],["30242.5","2","0","1"],["30242.6","0","0","0"],["30249.2","0","0","0"],["30249.3","0","0","0"],["30259.1","0","0","0"],["30259.2","104","0","2"],["30263","0","0","0"]],"bids":[["30234.7","0","0","0"],["30231.7","2","0","1"],["30228.1","2","0","1"],["30228","0","0","0"],["30218.5","4","0","1"],["30218.4","0","0","0"],["30218.3","0","0","0"],["30218.2","0","0","0"],["30218","0","0","0"],["30217.9","0","0","0"],["30208.9","0","0","0"],["30207.3","1578","0","1"],["30202.4","0","0","0"],["30197.7","99","0","1"],["30184.2","99","0","1"],["30162.2","0","0","0"]],"ts":"1652459235868","checksum":-806475951}]}
1652459235.994795: {"arg":{"channel":"books","instId":"UNI-USD-SWAP"},"action":"update","data":[{"asks":[["5.146","6","0","1"],["5.147","284","0","3"],["5.149","192","0","1"],["5.15","514","0","4"],["5.151","0","0","0"],["5.152","269","0","2"],["5.153","254","0","2"],["5.155","7","0","1"],["5.161","500","0","1"]],"bids":[["5.136","375","0","4"],["5.134","77","0","1"],["5.133","6","0","1"],["5.13","333","0","2"],["5.129","99","0","2"],["5.128","2519","0","4"],["5.127","498","0","4"],["5.124","258","0","2"]],"ts":"1652459235875","checksum":1120617028}]}
1652459236.1035037: {"arg":{"channel":"books","instId":"BTC-USD-220527"},"action":"update","data":[{"asks":[["30239.5","3","0","1"],["30240.1","2","0","1"],["30240.2","0","0","0"],["30240.3","0","0","0"],["30259.2","104","0","2"],["30268.6","0","0","0"]],"bids":[["30231.7","0","0","0"],["30231.3","0","0","0"],["30228.2","0","0","0"],["30218.5","0","0","0"],["30209.8","4","0","1"],["30197.7","0","0","0"],["30184.2","0","0","0"],["30170.5","484","0","1"]],"ts":"1652459235981","checksum":305908623}]}
1652459236.1037369: {"arg":{"channel":"books","instId":"BTC-USDT"},"action":"update","data":[{"asks":[["30246.1","0","0","0"],["30247.2","0.06523858","0","1"],["30249.6","0","0","0"],["30253.2","0","0","0"],["30253.5","0.635","0","1"],["30261.4","2.289","0","1"],["30261.5","0","0","0"],["30264.3","0","0","0"],["30264.7","0.06","0","1"],["30264.8","0.09","0","1"],["30266.1","0.16559088","0","1"],["30268.5","0.15","0","1"],["30274.9","0","0","0"],["30280.3","0.037","0","1"],["30283.3","0.24836597","0","1"],["30285.9","3.091","0","1"],["30315","0.13232064","0","1"],["30651.4","0","0","0"],["30652.2","0","0","0"],["30653.8","0","0","0"],["30654.8","0","0","0"],["30655.4","0","0","0"]],"bids":[["30236.1","0.16402066","0","7"],["30233","0.16","0","1"],["30227.1","0.01648681","0","1"],["30224.7","0.09","0","2"],["30224.3","0.1832","0","2"],["30222.7","0.000824","0","1"],["30221.6","0","0","0"],["30220.8","0.00477786","0","1"],["30220.7","0","0","0"],["30220.3","0","0","0"],["30215.7","2.278","0","1"],["30213.4","0.0152954","0","2"],["30210","0.11366203","0","3"],["30209.4","0","0","0"],["30209","0","0","0"],["30207.9","0.04945046","0","1"],["30207","0.01643806","0","1"],["30206.9","0.09000074","0","1"],["30195.1","0.24836597","0","1"],["30191.2","3.125","0","1"],["30187.8","0.00126666","0","1"],["30178.3","0.709","0","2"],["30172.7","0","0","0"],["30165.5","0","0","0"],["30104.3","3.5","0","1"],["29995","0","0","0"],["29994.2","0","0","0"],["29993.2","0","0","0"],["29992.7","0","0","0"]],"ts":"1652459235968","checksum":121203805}]}
1652459236.104072: {"arg":{"channel":"books","instId":"UNI-USD-SWAP"},"action":"update","data":[{"asks":[["5.147","170","0","2"],["5.148","139","0","3"],["5.153","270","0","3"],["5.158","193","0","3"]],"bids":[["5.131","153","0","3"],["5.13","333","0","2"],["5.129","99","0","2"],["5.127","412","0","3"],["5.118","500","0","1"],["5.115","0","0","0"]],"ts":"1652459235959","checksum":1774657022}]}
1652459236.21229: {"arg":{"channel":"books","instId":"BTC-USD-220527"},"action":"update","data":[{"asks":[["30238.6","0","0","0"],["30239.5","0","0","0"],["30259.2","104","0","2"],["30268.8","483","0","1"]],"bids":[["30229.4","2","0","1"],["30209.9","38","0","1"],["30208.8","214","0","1"]],"ts":"1652459236097","checksum":418221819}]}
1652459236.2125025: {"arg":{"channel":"books","instId":"BTC-USDT"},"action":"update","data":[{"asks":[["30246.5","0.00087743","0","1"],["30246.8","0","0","0"],["30247.2","0","0","0"],["30247.5","0","0","0"],["30258","0.61","0","2"],["30262.5","0","0","0"],["30264.7","0","0","0"],["30264.8","0","0","0"],["30268.5","0.33","0","4"],["30271.9","0","0","0"],["30273.5","5.3487643","0","2"],["30284.5","0.74","0","3"],["30312.2","0","0","0"],["30319.4","0.08255","0","1"],["30601.6","0","0","0"],["30609.1","1.9603109","0","2"],["30651.4","0.00010958","0","1"],["30652.2","0.00894205","0","1"],["30653.8","0.0000131","0","1"],["30654.8","0.00044899","0","1"],["30655.4","0.000068","0","1"]],"bids":[["30236.1","0.18050747","0","8"],["30234","0.052","0","1"],["30233.2","0.07180355","0","1"],["30233","0.28155591","0","2"],["30229.1","0.12157127","0","1"],["30228.1","0.00798335","0","1"],["30228","5.21314678","0","2"],["30227.1","0","0","0"],["30225.8","0.000824","0","1"],["30222.4","0.0005692","0","1"],["30222.1","0.09","0","1"],["30220.8","0","0","0"],["30220.7","0.00457765","0","1"],["30219","0.15","0","1"],["30214.9","0.08255","0","1"],["30209.1","0.01643806","0","1"],["30208.3","0.020374","0","1"],["30207","0","0","0"],["30193","0.02758644","0","1"],["29999.7","0","0","0"],["29999.6","0","0","0"],["29999.4","0","0","0"],["29999","0","0","0"],["29998","0","0","0"],["29996.6","0","0","0"],["29995.7","0","0","0"],["29995","0","0","0"]],"ts":"1652459236096","checksum":-308733687}]}
1652459236.2128143: {"arg":{"channel":"books","instId":"UNI-USD-SWAP"},"action":"update","data":[{"asks":[["5.146","0","0","0"],["5.147","211","0","2"],["5.148","5","0","1"],["5.15","534","0","5"],["5.151","0","0","0"],["5.156","57","0","1"],["5.159","304","0","3"]],"bids":[["5.137","20","0","1"],["5.136","452","0","5"],["5.135","0","0","0"],["5.134","0","0","0"],["5.131","67","0","2"],["5.13","356","0","3"],["5.129","183","0","2"],["5.127","498","0","4"],["5.118","564","0","2"]],"ts":"1652459236094","checksum":1552772605}]}
1652459236.3416445: {"arg":{"channel":"books","instId":"BTC-USD-220527"},"action":"update","data":[{"asks":[["30238.8","3","0","1"],["30240.7","0","0","0"]],"bids":[],"ts":"1652459236119","checksum":664471393}]}
